Workbook

Sheet 说明
A1: 西藏高质量发展「安全—发展—生态」三元协调评价 · 可复现计算底稿
A3: 本底稿与论文现行方法严格一致，全部为活公式：修改「1_基础数据」蓝色单元格后，所有下游结果自动重算。
A5: 计算链路
A6: 1_基础数据 原始统计值与三条辅助序列（常住人口、全国城乡居民人均可支配收入）
A7: 2_指标值 按表1口径换算出13项指标（人均化、相对化、比值化）
A8: 3_标准化 固定基准标准化，式(1)正向/式(2)逆向，超出[0,1]截断；式(3)平移压缩至[0.01,0.99]
A9: 4_子系统指数 子系统内等权平均，得 US / UD / UE
A10: 5_MPI协调指数 D = M − S²/M，M为三子系统均值，S²为总体方差
A11: 6_组合权重 熵值权重 × CRITIC权重后归一（仅用于诊断与稳健性对照，不参与子系统合成）
A12: 7_结构性贡献缺口 O(i,j) = w(j)·I(i,j) / Σ w·I，逐年计算后取样本期均值（论文表4）
A13: 8_局部敏感性 ε = (D⁺−D⁻)/(0.02·D)，±1%相对扰动双侧数值微分（论文表5）
A14: 9_留一法 逐一剔除13项指标重算，检验方向性判断稳健性（论文表6）
... A33: 历年《居民收入和消费支出情况》。其中2016—2018年西藏常住人口未经原件直接确证，但US三年均精确吻合。

Sheet 1_基础数据
A1: 基础数据（蓝色为原始输入，可直接修改）
A2: 项目 | B2: 单位 | C2: 2016 | D2: 2017 | E2: 2018 | F2: 2019 | G2: 2020 | H2: 2021 | I2: 2022 | J2: 2023 | K2: 2024 | L2: 2025
A3: 地方一般公共预算收入 | B3: 亿元 | C3: 155.99 | D3: 185.83 | E3: 230.35 | F3: 221.99 | G3: 220.99 | H3: 215.62 | I3: 179.63 | J3: 236.63 | K3: 277.19 | L3: 317.9
A4: 城乡居民人均可支配收入比 | B4: 倍 | C4: 3.05718 | D4: 2.96912 | E4: 2.9517 | F4: 2.88858 | G4: 2.81929 | H4: 2.74597 | I4: 2.67741 | J4: 2.6049 | K4: 2.56947 | L4: 2.53597
A5: 居民医保人均财政补助标准 | B5: 元/人年 | C5: 420 | D5: 450 | E5: 515 | F5: 515 | G5: 550 | H5: 580 | I5: 615 | J5: 675 | K5: 705 | L5: 735
A6: 基本养老保险参保率 | B6: % | C6: 85.5 | D6: 89.3 | E6: 91.15 | F6: 92.6 | G6: 94.1 | H6: 95.2 | I6: 95.5 | J6: 95.8 | K6: 96.31 | L6: 96.5
A7: 人均GDP相对全国水平 | B7: % | C7: 65.4184 | D7: 65.8931 | E7: 66.2221 | F7: 69.7822 | G7: 72.8755 | H7: 68.3805 | I7: 68.5 | J7: 73.44 | K7: 78.58 | L7: 81.77
A8: 地区生产总值 | B8: 亿元 | C8: 1197.38 | D8: 1380.97 | E8: 1583.48 | F8: 1750.34 | G8: 1956.54 | H8: 2145.08 | I8: 2235.39 | J8: 2532.86 | K8: 2789.07 | L8: 3031.89
A9: 农村居民人均可支配收入 | B9: 元 | C9: 9094 | D9: 10330 | E9: 11450 | F9: 12951 | G9: 14598 | H9: 16935 | I9: 18209 | J9: 19924 | K9: 21578 | L9: 23184
A10: 货物进出口总额 | B10: 亿元 | C10: 51.67 | D10: 59.19 | E10: 47.52 | F10: 48.76 | G10: 21.33 | H10: 40.16 | I10: 46.01 | J10: 109.78 | K10: 126.72 | L10: 84.79
A11: 接待游客总人数 | B11: 万人次 | C11: 2315.94 | D11: 2561.43 | E11: 3368.73 | F11: 4012.15 | G11: 3505.01 | H11: 4153.44 | I11: 3002.76 | J11: 5516.98 | K11: 6389.1 | L11: 7073.37
A12: 发电量 | B12: 亿千瓦时 | C12: 50.78 | D12: 52.06 | E12: 63.14 | F12: 66.3 | G12: 67.1 | H12: 80.8 | I12: 111.1 | J12: 133.5 | K12: 140.41 | L12: 162.42
A13: 单位GDP能耗指数 | B13: 指数 | C13: 96.8 | D13: 93.41 | E13: 90.51 | F13: 87.98 | G13: 86.66 | H13: 84.06 | I13: 81.2 | J13: 78.85 | K13: 76.41 | L13: 73.89
A14: 森林覆盖率 | B14: % | C14: 11.98 | D14: 12.14 | E14: 12.14 | F14: 12.14 | G14: 12.31 | H14: 12.31 | I14: 12.31 | J14: 12.31 | K14: 12.31 | L14: 12.54
... A16: 草原综合植被盖度 | B16: % | C16: 42.3 | D16: 44.2 | E16: 45.9 | F16: 46.7 | G16: 46.9 | H16: 47.14 | I16: 47.5 | J16: 47.78 | K16: 48.02 | L16: 48.07
A18: 辅助序列
A19: 西藏年末常住人口 | B19: 万人 | C19: 330.54 | D19: 337.15 | E19: 343.82 | F19: 350.56 | G19: 364.81 | H19: 366 | I19: 364 | J19: 365 | K19: 370 | L19: 374
A20: 全国农村居民人均可支配收入 | B20: 元 | C20: 12363 | D20: 13432 | E20: 14617 | F20: 16021 | G20: 17131 | H20: 18931 | I20: 20133 | J20: 21691 | K20: 23119 | L20: 24456
A21: 全国城镇居民人均可支配收入 | B21: 元 | C21: 33616 | D21: 36396 | E21: 39251 | F21: 42359 | G21: 43834 | H21: 47412 | I21: 49283 | J21: 51821 | K21: 54188 | L21: 56502
A22: 全国城乡居民收入比 | B22: 倍 | C22: =C21/C20 | D22: =D21/D20 | E22: =E21/E20 | F22: =F21/F20 | G22: =G21/G20 | H22: =H21/H20 | I22: =I21/I20 | J22: =J21/J20 | ... L22: =L21/L20

Sheet 2_指标值
A1: 13项指标（表1口径）—— 由 1_基础数据 换算
A2: 子系统 | B2: 编码 | C2: 三级指标 | D2: 方向 | E2: 下限 | F2: 上限 | G2: 2016 | H2: 2017 | I2: 2018 | J2: 2019 | K2: 2020 | L2: 2021 | M2: 2022 | N2: 2023 | O2: 2024 | P2: 2025
A3: 安全 S | B3: S1 | C3: 人均一般公共预算收入（元/人） | D3: 正向 | E3: 0 | F3: ='10_稳健性检验'!D54 | G3: ='1_基础数据'!C3*10000/'1_基础数据'!C19 | H3: ='1_基础数据'!D3*10000/'1_基础数据'!D19 | I3: ='1_基础数据'!E3*10000/'1_基础数据'!E19 | J3: ='1_基础数据'!F3*10000/'1_基础数据'!F19 | K3: ='1_基础数据'!G3*10000/'1_基础数据'!G19 | L3: ='1_基础数据'!H3*10000/'1_基础数据'!H19 | M3: ='1_基础数据'!I3*10000/'1_基础数据'!I19 | N3: ='1_基础数据'!J3*10000/'1_基础数据'!J19 | ... P3: ='1_基础数据'!L3*10000/'1_基础数据'!L19
A4: 安全 S | B4: S2 | C4: 城乡居民收入比与全国差距（倍） | D4: 逆向 | E4: -1 | F4: 2 | G4: ='1_基础数据'!C4-'1_基础数据'!C22 | H4: ='1_基础数据'!D4-'1_基础数据'!D22 | I4: ='1_基础数据'!E4-'1_基础数据'!E22 | J4: ='1_基础数据'!F4-'1_基础数据'!F22 | K4: ='1_基础数据'!G4-'1_基础数据'!G22 | L4: ='1_基础数据'!H4-'1_基础数据'!H22 | M4: ='1_基础数据'!I4-'1_基础数据'!I22 | N4: ='1_基础数据'!J4-'1_基础数据'!J22 | ... P4: ='1_基础数据'!L4-'1_基础数据'!L22
A5: 安全 S | B5: S3 | C5: 居民医保人均财政补助标准（元/人年） | D5: 正向 | E5: 0 | F5: ='10_稳健性检验'!D55 | G5: ='1_基础数据'!C5 | H5: ='1_基础数据'!D5 | I5: ='1_基础数据'!E5 | J5: ='1_基础数据'!F5 | K5: ='1_基础数据'!G5 | L5: ='1_基础数据'!H5 | M5: ='1_基础数据'!I5 | N5: ='1_基础数据'!J5 | ... P5: ='1_基础数据'!L5
A6: 安全 S | B6: S4 | C6: 基本养老保险参保率（%） | D6: 正向 | E6: 0 | F6: 100 | G6: ='1_基础数据'!C6 | H6: ='1_基础数据'!D6 | I6: ='1_基础数据'!E6 | J6: ='1_基础数据'!F6 | K6: ='1_基础数据'!G6 | L6: ='1_基础数据'!H6 | M6: ='1_基础数据'!I6 | N6: ='1_基础数据'!J6 | ... P6: ='1_基础数据'!L6
A7: 发展 D | B7: D1 | C7: 人均GDP相对全国水平（%） | D7: 正向 | E7: 0 | F7: 100 | G7: ='1_基础数据'!C7 | H7: ='1_基础数据'!D7 | I7: ='1_基础数据'!E7 | J7: ='1_基础数据'!F7 | K7: ='1_基础数据'!G7 | L7: ='1_基础数据'!H7 | M7: ='1_基础数据'!I7 | N7: ='1_基础数据'!J7 | ... P7: ='1_基础数据'!L7
A8: 发展 D | B8: D2 | C8: 农村居民人均收入相对全国水平（%） | D8: 正向 | E8: 0 | F8: 100 | G8: ='1_基础数据'!C9/'1_基础数据'!C20*100 | H8: ='1_基础数据'!D9/'1_基础数据'!D20*100 | I8: ='1_基础数据'!E9/'1_基础数据'!E20*100 | J8: ='1_基础数据'!F9/'1_基础数据'!F20*100 | K8: ='1_基础数据'!G9/'1_基础数据'!G20*100 | L8: ='1_基础数据'!H9/'1_基础数据'!H20*100 | M8: ='1_基础数据'!I9/'1_基础数据'!I20*100 | N8: ='1_基础数据'!J9/'1_基础数据'!J20*100 | ... P8: ='1_基础数据'!L9/'1_基础数据'!L20*100
A9: 发展 D | B9: D3 | C9: 外向度（进出口总额/GDP，%） | D9: 正向 | E9: 0 | F9: ='10_稳健性检验'!D56 | G9: ='1_基础数据'!C10/'1_基础数据'!C8*100 | H9: ='1_基础数据'!D10/'1_基础数据'!D8*100 | I9: ='1_基础数据'!E10/'1_基础数据'!E8*100 | J9: ='1_基础数据'!F10/'1_基础数据'!F8*100 | K9: ='1_基础数据'!G10/'1_基础数据'!G8*100 | L9: ='1_基础数据'!H10/'1_基础数据'!H8*100 | M9: ='1_基础数据'!I10/'1_基础数据'!I8*100 | N9: ='1_基础数据'!J10/'1_基础数据'!J8*100 | ... P9: ='1_基础数据'!L10/'1_基础数据'!L8*100
A10: 发展 D | B10: D4 | C10: 人均接待游客（万人次/万人） | D10: 正向 | E10: 0 | F10: ='10_稳健性检验'!D57 | G10: ='1_基础数据'!C11/'1_基础数据'!C19 | H10: ='1_基础数据'!D11/'1_基础数据'!D19 | I10: ='1_基础数据'!E11/'1_基础数据'!E19 | J10: ='1_基础数据'!F11/'1_基础数据'!F19 | K10: ='1_基础数据'!G11/'1_基础数据'!G19 | L10: ='1_基础数据'!H11/'1_基础数据'!H19 | M10: ='1_基础数据'!I11/'1_基础数据'!I19 | N10: ='1_基础数据'!J11/'1_基础数据'!J19 | ... P10: ='1_基础数据'!L11/'1_基础数据'!L19
A11: 发展 D | B11: D5 | C11: 发电量（亿千瓦时） | D11: 正向 | E11: 0 | F11: ='10_稳健性检验'!D58 | G11: ='1_基础数据'!C12 | H11: ='1_基础数据'!D12 | I11: ='1_基础数据'!E12 | J11: ='1_基础数据'!F12 | K11: ='1_基础数据'!G12 | L11: ='1_基础数据'!H12 | M11: ='1_基础数据'!I12 | N11: ='1_基础数据'!J12 | ... P11: ='1_基础数据'!L12
A12: 生态 E | B12: E1 | C12: 单位GDP能耗指数 | D12: 逆向 | E12: 60 | F12: 100 | G12: ='1_基础数据'!C13 | H12: ='1_基础数据'!D13 | I12: ='1_基础数据'!E13 | J12: ='1_基础数据'!F13 | K12: ='1_基础数据'!G13 | L12: ='1_基础数据'!H13 | M12: ='1_基础数据'!I13 | N12: ='1_基础数据'!J13 | ... P12: ='1_基础数据'!L13
A13: 生态 E | B13: E2 | C13: 森林覆盖率（%） | D13: 正向 | E13: 11.98 | F13: 12.51 | G13: ='1_基础数据'!C14 | H13: ='1_基础数据'!D14 | I13: ='1_基础数据'!E14 | J13: ='1_基础数据'!F14 | K13: ='1_基础数据'!G14 | L13: ='1_基础数据'!H14 | M13: ='1_基础数据'!I14 | N13: ='1_基础数据'!J14 | ... P13: ='1_基础数据'!L14
A14: 生态 E | B14: E3 | C14: 空气质量优良天数比例（%） | D14: 正向 | E14: 0 | F14: 100 | G14: ='1_基础数据'!C15 | H14: ='1_基础数据'!D15 | I14: ='1_基础数据'!E15 | J14: ='1_基础数据'!F15 | K14: ='1_基础数据'!G15 | L14: ='1_基础数据'!H15 | M14: ='1_基础数据'!I15 | N14: ='1_基础数据'!J15 | ... P14: ='1_基础数据'!L15
A15: 生态 E | B15: E4 | C15: 草原综合植被盖度（%） | D15: 正向 | E15: 42.3 | F15: 50 | G15: ='1_基础数据'!C16 | H15: ='1_基础数据'!D16 | I15: ='1_基础数据'!E16 | J15: ='1_基础数据'!F16 | K15: ='1_基础数据'!G16 | L15: ='1_基础数据'!H16 | M15: ='1_基础数据'!I16 | N15: ='1_基础数据'!J16 | ... P15: ='1_基础数据'!L16

Sheet 3_标准化
A1: 固定基准标准化：式(1)正向 / 式(2)逆向，超出[0,1]截断；式(3) x' = 0.98·x* + 0.01
A2: 子系统 | B2: 编码 | C2: 三级指标 | D2: 方向 | E2: 2016 | F2: 2017 | G2: 2018 | H2: 2019 | I2: 2020 | J2: 2021 | K2: 2022 | L2: 2023 | M2: 2024 | N2: 2025
A3: 安全 S | B3: S1 | C3: =0.98*MIN(1,MAX(0,('2_指标值'!G3-'2_指标值'!$E3)/('2_指标值'!$F3-'2_指标值'!$E3)))+0.01 | D3: =0.98*MIN(1,MAX(0,('2_指标值'!H3-'2_指标值'!$E3)/('2_指标值'!$F3-'2_指标值'!$E3)))+0.01 | E3: =0.98*MIN(1,MAX(0,('2_指标值'!I3-'2_指标值'!$E3)/('2_指标值'!$F3-'2_指标值'!$E3)))+0.01 | F3: =0.98*MIN(1,MAX(0,('2_指标值'!J3-'2_指标值'!$E3)/('2_指标值'!$F3-'2_指标值'!$E3)))+0.01 | G3: =0.98*MIN(1,MAX(0,('2_指标值'!K3-'2_指标值'!$E3)/('2_指标值'!$F3-'2_指标值'!$E3)))+0.01 | H3: =0.98*MIN(1,MAX(0,('2_指标值'!L3-'2_指标值'!$E3)/('2_指标值'!$F3-'2_指标值'!$E3)))+0.01 | I3: =0.98*MIN(1,MAX(0,('2_指标值'!M3-'2_指标值'!$E3)/('2_指标值'!$F3-'2_指标值'!$E3)))+0.01 | J3: =0.98*MIN(1,MAX(0,('2_指标值'!N3-'2_指标值'!$E3)/('2_指标值'!$F3-'2_指标值'!$E3)))+0.01 | ... L3: =0.98*MIN(1,MAX(0,('2_指标值'!P3-'2_指标值'!$E3)/('2_指标值'!$F3-'2_指标值'!$E3)))+0.01
A4: 安全 S | B4: S2 | C4: =0.98*MIN(1,MAX(0,('2_指标值'!$F4-'2_指标值'!G4)/('2_指标值'!$F4-'2_指标值'!$E4)))+0.01 | D4: =0.98*MIN(1,MAX(0,('2_指标值'!$F4-'2_指标值'!H4)/('2_指标值'!$F4-'2_指标值'!$E4)))+0.01 | E4: =0.98*MIN(1,MAX(0,('2_指标值'!$F4-'2_指标值'!I4)/('2_指标值'!$F4-'2_指标值'!$E4)))+0.01 | F4: =0.98*MIN(1,MAX(0,('2_指标值'!$F4-'2_指标值'!J4)/('2_指标值'!$F4-'2_指标值'!$E4)))+0.01 | G4: =0.98*MIN(1,MAX(0,('2_指标值'!$F4-'2_指标值'!K4)/('2_指标值'!$F4-'2_指标值'!$E4)))+0.01 | H4: =0.98*MIN(1,MAX(0,('2_指标值'!$F4-'2_指标值'!L4)/('2_指标值'!$F4-'2_指标值'!$E4)))+0.01 | I4: =0.98*MIN(1,MAX(0,('2_指标值'!$F4-'2_指标值'!M4)/('2_指标值'!$F4-'2_指标值'!$E4)))+0.01 | J4: =0.98*MIN(1,MAX(0,('2_指标值'!$F4-'2_指标值'!N4)/('2_指标值'!$F4-'2_指标值'!$E4)))+0.01 | ... L4: =0.98*MIN(1,MAX(0,('2_指标值'!$F4-'2_指标值'!P4)/('2_指标值'!$F4-'2_指标值'!$E4)))+0.01
A5: 安全 S | B5: S3 | C5: =0.98*MIN(1,MAX(0,('2_指标值'!G5-'2_指标值'!$E5)/('2_指标值'!$F5-'2_指标值'!$E5)))+0.01 | D5: =0.98*MIN(1,MAX(0,('2_指标值'!H5-'2_指标值'!$E5)/('2_指标值'!$F5-'2_指标值'!$E5)))+0.01 | E5: =0.98*MIN(1,MAX(0,('2_指标值'!I5-'2_指标值'!$E5)/('2_指标值'!$F5-'2_指标值'!$E5)))+0.01 | F5: =0.98*MIN(1,MAX(0,('2_指标值'!J5-'2_指标值'!$E5)/('2_指标值'!$F5-'2_指标值'!$E5)))+0.01 | G5: =0.98*MIN(1,MAX(0,('2_指标值'!K5-'2_指标值'!$E5)/('2_指标值'!$F5-'2_指标值'!$E5)))+0.01 | H5: =0.98*MIN(1,MAX(0,('2_指标值'!L5-'2_指标值'!$E5)/('2_指标值'!$F5-'2_指标值'!$E5)))+0.01 | I5: =0.98*MIN(1,MAX(0,('2_指标值'!M5-'2_指标值'!$E5)/('2_指标值'!$F5-'2_指标值'!$E5)))+0.01 | J5: =0.98*MIN(1,MAX(0,('2_指标值'!N5-'2_指标值'!$E5)/('2_指标值'!$F5-'2_指标值'!$E5)))+0.01 | ... L5: =0.98*MIN(1,MAX(0,('2_指标值'!P5-'2_指标值'!$E5)/('2_指标值'!$F5-'2_指标值'!$E5)))+0.01
A6: 安全 S | B6: S4 | C6: =0.98*MIN(1,MAX(0,('2_指标值'!G6-'2_指标值'!$E6)/('2_指标值'!$F6-'2_指标值'!$E6)))+0.01 | D6: =0.98*MIN(1,MAX(0,('2_指标值'!H6-'2_指标值'!$E6)/('2_指标值'!$F6-'2_指标值'!$E6)))+0.01 | E6: =0.98*MIN(1,MAX(0,('2_指标值'!I6-'2_指标值'!$E6)/('2_指标值'!$F6-'2_指标值'!$E6)))+0.01 | F6: =0.98*MIN(1,MAX(0,('2_指标值'!J6-'2_指标值'!$E6)/('2_指标值'!$F6-'2_指标值'!$E6)))+0.01 | G6: =0.98*MIN(1,MAX(0,('2_指标值'!K6-'2_指标值'!$E6)/('2_指标值'!$F6-'2_指标值'!$E6)))+0.01 | H6: =0.98*MIN(1,MAX(0,('2_指标值'!L6-'2_指标值'!$E6)/('2_指标值'!$F6-'2_指标值'!$E6)))+0.01 | I6: =0.98*MIN(1,MAX(0,('2_指标值'!M6-'2_指标值'!$E6)/('2_指标值'!$F6-'2_指标值'!$E6)))+0.01 | J6: =0.98*MIN(1,MAX(0,('2_指标值'!N6-'2_指标值'!$E6)/('2_指标值'!$F6-'2_指标值'!$E6)))+0.01 | ... L6: =0.98*MIN(1,MAX(0,('2_指标值'!P6-'2_指标值'!$E6)/('2_指标值'!$F6-'2_指标值'!$E6)))+0.01
A7: 发展 D | B7: D1 | C7: =0.98*MIN(1,MAX(0,('2_指标值'!G7-'2_指标值'!$E7)/('2_指标值'!$F7-'2_指标值'!$E7)))+0.01 | D7: =0.98*MIN(1,MAX(0,('2_指标值'!H7-'2_指标值'!$E7)/('2_指标值'!$F7-'2_指标值'!$E7)))+0.01 | E7: =0.98*MIN(1,MAX(0,('2_指标值'!I7-'2_指标值'!$E7)/('2_指标值'!$F7-'2_指标值'!$E7)))+0.01 | F7: =0.98*MIN(1,MAX(0,('2_指标值'!J7-'2_指标值'!$E7)/('2_指标值'!$F7-'2_指标值'!$E7)))+0.01 | G7: =0.98*MIN(1,MAX(0,('2_指标值'!K7-'2_指标值'!$E7)/('2_指标值'!$F7-'2_指标值'!$E7)))+0.01 | H7: =0.98*MIN(1,MAX(0,('2_指标值'!L7-'2_指标值'!$E7)/('2_指标值'!$F7-'2_指标值'!$E7)))+0.01 | I7: =0.98*MIN(1,MAX(0,('2_指标值'!M7-'2_指标值'!$E7)/('2_指标值'!$F7-'2_指标值'!$E7)))+0.01 | J7: =0.98*MIN(1,MAX(0,('2_指标值'!N7-'2_指标值'!$E7)/('2_指标值'!$F7-'2_指标值'!$E7)))+0.01 | ... L7: =0.98*MIN(1,MAX(0,('2_指标值'!P7-'2_指标值'!$E7)/('2_指标值'!$F7-'2_指标值'!$E7)))+0.01
A8: 发展 D | B8: D2 | C8: =0.98*MIN(1,MAX(0,('2_指标值'!G8-'2_指标值'!$E8)/('2_指标值'!$F8-'2_指标值'!$E8)))+0.01 | D8: =0.98*MIN(1,MAX(0,('2_指标值'!H8-'2_指标值'!$E8)/('2_指标值'!$F8-'2_指标值'!$E8)))+0.01 | E8: =0.98*MIN(1,MAX(0,('2_指标值'!I8-'2_指标值'!$E8)/('2_指标值'!$F8-'2_指标值'!$E8)))+0.01 | F8: =0.98*MIN(1,MAX(0,('2_指标值'!J8-'2_指标值'!$E8)/('2_指标值'!$F8-'2_指标值'!$E8)))+0.01 | G8: =0.98*MIN(1,MAX(0,('2_指标值'!K8-'2_指标值'!$E8)/('2_指标值'!$F8-'2_指标值'!$E8)))+0.01 | H8: =0.98*MIN(1,MAX(0,('2_指标值'!L8-'2_指标值'!$E8)/('2_指标值'!$F8-'2_指标值'!$E8)))+0.01 | I8: =0.98*MIN(1,MAX(0,('2_指标值'!M8-'2_指标值'!$E8)/('2_指标值'!$F8-'2_指标值'!$E8)))+0.01 | J8: =0.98*MIN(1,MAX(0,('2_指标值'!N8-'2_指标值'!$E8)/('2_指标值'!$F8-'2_指标值'!$E8)))+0.01 | ... L8: =0.98*MIN(1,MAX(0,('2_指标值'!P8-'2_指标值'!$E8)/('2_指标值'!$F8-'2_指标值'!$E8)))+0.01
A9: 发展 D | B9: D3 | C9: =0.98*MIN(1,MAX(0,('2_指标值'!G9-'2_指标值'!$E9)/('2_指标值'!$F9-'2_指标值'!$E9)))+0.01 | D9: =0.98*MIN(1,MAX(0,('2_指标值'!H9-'2_指标值'!$E9)/('2_指标值'!$F9-'2_指标值'!$E9)))+0.01 | E9: =0.98*MIN(1,MAX(0,('2_指标值'!I9-'2_指标值'!$E9)/('2_指标值'!$F9-'2_指标值'!$E9)))+0.01 | F9: =0.98*MIN(1,MAX(0,('2_指标值'!J9-'2_指标值'!$E9)/('2_指标值'!$F9-'2_指标值'!$E9)))+0.01 | G9: =0.98*MIN(1,MAX(0,('2_指标值'!K9-'2_指标值'!$E9)/('2_指标值'!$F9-'2_指标值'!$E9)))+0.01 | H9: =0.98*MIN(1,MAX(0,('2_指标值'!L9-'2_指标值'!$E9)/('2_指标值'!$F9-'2_指标值'!$E9)))+0.01 | I9: =0.98*MIN(1,MAX(0,('2_指标值'!M9-'2_指标值'!$E9)/('2_指标值'!$F9-'2_指标值'!$E9)))+0.01 | J9: =0.98*MIN(1,MAX(0,('2_指标值'!N9-'2_指标值'!$E9)/('2_指标值'!$F9-'2_指标值'!$E9)))+0.01 | ... L9: =0.98*MIN(1,MAX(0,('2_指标值'!P9-'2_指标值'!$E9)/('2_指标值'!$F9-'2_指标值'!$E9)))+0.01
A10: 发展 D | B10: D4 | C10: =0.98*MIN(1,MAX(0,('2_指标值'!G10-'2_指标值'!$E10)/('2_指标值'!$F10-'2_指标值'!$E10)))+0.01 | D10: =0.98*MIN(1,MAX(0,('2_指标值'!H10-'2_指标值'!$E10)/('2_指标值'!$F10-'2_指标值'!$E10)))+0.01 | E10: =0.98*MIN(1,MAX(0,('2_指标值'!I10-'2_指标值'!$E10)/('2_指标值'!$F10-'2_指标值'!$E10)))+0.01 | F10: =0.98*MIN(1,MAX(0,('2_指标值'!J10-'2_指标值'!$E10)/('2_指标值'!$F10-'2_指标值'!$E10)))+0.01 | G10: =0.98*MIN(1,MAX(0,('2_指标值'!K10-'2_指标值'!$E10)/('2_指标值'!$F10-'2_指标值'!$E10)))+0.01 | H10: =0.98*MIN(1,MAX(0,('2_指标值'!L10-'2_指标值'!$E10)/('2_指标值'!$F10-'2_指标值'!$E10)))+0.01 | I10: =0.98*MIN(1,MAX(0,('2_指标值'!M10-'2_指标值'!$E10)/('2_指标值'!$F10-'2_指标值'!$E10)))+0.01 | J10: =0.98*MIN(1,MAX(0,('2_指标值'!N10-'2_指标值'!$E10)/('2_指标值'!$F10-'2_指标值'!$E10)))+0.01 | ... L10: =0.98*MIN(1,MAX(0,('2_指标值'!P10-'2_指标值'!$E10)/('2_指标值'!$F10-'2_指标值'!$E10)))+0.01
A11: 发展 D | B11: D5 | C11: =0.98*MIN(1,MAX(0,('2_指标值'!G11-'2_指标值'!$E11)/('2_指标值'!$F11-'2_指标值'!$E11)))+0.01 | D11: =0.98*MIN(1,MAX(0,('2_指标值'!H11-'2_指标值'!$E11)/('2_指标值'!$F11-'2_指标值'!$E11)))+0.01 | E11: =0.98*MIN(1,MAX(0,('2_指标值'!I11-'2_指标值'!$E11)/('2_指标值'!$F11-'2_指标值'!$E11)))+0.01 | F11: =0.98*MIN(1,MAX(0,('2_指标值'!J11-'2_指标值'!$E11)/('2_指标值'!$F11-'2_指标值'!$E11)))+0.01 | G11: =0.98*MIN(1,MAX(0,('2_指标值'!K11-'2_指标值'!$E11)/('2_指标值'!$F11-'2_指标值'!$E11)))+0.01 | H11: =0.98*MIN(1,MAX(0,('2_指标值'!L11-'2_指标值'!$E11)/('2_指标值'!$F11-'2_指标值'!$E11)))+0.01 | I11: =0.98*MIN(1,MAX(0,('2_指标值'!M11-'2_指标值'!$E11)/('2_指标值'!$F11-'2_指标值'!$E11)))+0.01 | J11: =0.98*MIN(1,MAX(0,('2_指标值'!N11-'2_指标值'!$E11)/('2_指标值'!$F11-'2_指标值'!$E11)))+0.01 | ... L11: =0.98*MIN(1,MAX(0,('2_指标值'!P11-'2_指标值'!$E11)/('2_指标值'!$F11-'2_指标值'!$E11)))+0.01
A12: 生态 E | B12: E1 | C12: =0.98*MIN(1,MAX(0,('2_指标值'!$F12-'2_指标值'!G12)/('2_指标值'!$F12-'2_指标值'!$E12)))+0.01 | D12: =0.98*MIN(1,MAX(0,('2_指标值'!$F12-'2_指标值'!H12)/('2_指标值'!$F12-'2_指标值'!$E12)))+0.01 | E12: =0.98*MIN(1,MAX(0,('2_指标值'!$F12-'2_指标值'!I12)/('2_指标值'!$F12-'2_指标值'!$E12)))+0.01 | F12: =0.98*MIN(1,MAX(0,('2_指标值'!$F12-'2_指标值'!J12)/('2_指标值'!$F12-'2_指标值'!$E12)))+0.01 | G12: =0.98*MIN(1,MAX(0,('2_指标值'!$F12-'2_指标值'!K12)/('2_指标值'!$F12-'2_指标值'!$E12)))+0.01 | H12: =0.98*MIN(1,MAX(0,('2_指标值'!$F12-'2_指标值'!L12)/('2_指标值'!$F12-'2_指标值'!$E12)))+0.01 | I12: =0.98*MIN(1,MAX(0,('2_指标值'!$F12-'2_指标值'!M12)/('2_指标值'!$F12-'2_指标值'!$E12)))+0.01 | J12: =0.98*MIN(1,MAX(0,('2_指标值'!$F12-'2_指标值'!N12)/('2_指标值'!$F12-'2_指标值'!$E12)))+0.01 | ... L12: =0.98*MIN(1,MAX(0,('2_指标值'!$F12-'2_指标值'!P12)/('2_指标值'!$F12-'2_指标值'!$E12)))+0.01
A13: 生态 E | B13: E2 | C13: =0.98*MIN(1,MAX(0,('2_指标值'!G13-'2_指标值'!$E13)/('2_指标值'!$F13-'2_指标值'!$E13)))+0.01 | D13: =0.98*MIN(1,MAX(0,('2_指标值'!H13-'2_指标值'!$E13)/('2_指标值'!$F13-'2_指标值'!$E13)))+0.01 | E13: =0.98*MIN(1,MAX(0,('2_指标值'!I13-'2_指标值'!$E13)/('2_指标值'!$F13-'2_指标值'!$E13)))+0.01 | F13: =0.98*MIN(1,MAX(0,('2_指标值'!J13-'2_指标值'!$E13)/('2_指标值'!$F13-'2_指标值'!$E13)))+0.01 | G13: =0.98*MIN(1,MAX(0,('2_指标值'!K13-'2_指标值'!$E13)/('2_指标值'!$F13-'2_指标值'!$E13)))+0.01 | H13: =0.98*MIN(1,MAX(0,('2_指标值'!L13-'2_指标值'!$E13)/('2_指标值'!$F13-'2_指标值'!$E13)))+0.01 | I13: =0.98*MIN(1,MAX(0,('2_指标值'!M13-'2_指标值'!$E13)/('2_指标值'!$F13-'2_指标值'!$E13)))+0.01 | J13: =0.98*MIN(1,MAX(0,('2_指标值'!N13-'2_指标值'!$E13)/('2_指标值'!$F13-'2_指标值'!$E13)))+0.01 | ... L13: =0.98*MIN(1,MAX(0,('2_指标值'!P13-'2_指标值'!$E13)/('2_指标值'!$F13-'2_指标值'!$E13)))+0.01
A14: 生态 E | B14: E3 | C14: =0.98*MIN(1,MAX(0,('2_指标值'!G14-'2_指标值'!$E14)/('2_指标值'!$F14-'2_指标值'!$E14)))+0.01 | D14: =0.98*MIN(1,MAX(0,('2_指标值'!H14-'2_指标值'!$E14)/('2_指标值'!$F14-'2_指标值'!$E14)))+0.01 | E14: =0.98*MIN(1,MAX(0,('2_指标值'!I14-'2_指标值'!$E14)/('2_指标值'!$F14-'2_指标值'!$E14)))+0.01 | F14: =0.98*MIN(1,MAX(0,('2_指标值'!J14-'2_指标值'!$E14)/('2_指标值'!$F14-'2_指标值'!$E14)))+0.01 | G14: =0.98*MIN(1,MAX(0,('2_指标值'!K14-'2_指标值'!$E14)/('2_指标值'!$F14-'2_指标值'!$E14)))+0.01 | H14: =0.98*MIN(1,MAX(0,('2_指标值'!L14-'2_指标值'!$E14)/('2_指标值'!$F14-'2_指标值'!$E14)))+0.01 | I14: =0.98*MIN(1,MAX(0,('2_指标值'!M14-'2_指标值'!$E14)/('2_指标值'!$F14-'2_指标值'!$E14)))+0.01 | J14: =0.98*MIN(1,MAX(0,('2_指标值'!N14-'2_指标值'!$E14)/('2_指标值'!$F14-'2_指标值'!$E14)))+0.01 | ... L14: =0.98*MIN(1,MAX(0,('2_指标值'!P14-'2_指标值'!$E14)/('2_指标值'!$F14-'2_指标值'!$E14)))+0.01
A15: 生态 E | B15: E4 | C15: =0.98*MIN(1,MAX(0,('2_指标值'!G15-'2_指标值'!$E15)/('2_指标值'!$F15-'2_指标值'!$E15)))+0.01 | D15: =0.98*MIN(1,MAX(0,('2_指标值'!H15-'2_指标值'!$E15)/('2_指标值'!$F15-'2_指标值'!$E15)))+0.01 | E15: =0.98*MIN(1,MAX(0,('2_指标值'!I15-'2_指标值'!$E15)/('2_指标值'!$F15-'2_指标值'!$E15)))+0.01 | F15: =0.98*MIN(1,MAX(0,('2_指标值'!J15-'2_指标值'!$E15)/('2_指标值'!$F15-'2_指标值'!$E15)))+0.01 | G15: =0.98*MIN(1,MAX(0,('2_指标值'!K15-'2_指标值'!$E15)/('2_指标值'!$F15-'2_指标值'!$E15)))+0.01 | H15: =0.98*MIN(1,MAX(0,('2_指标值'!L15-'2_指标值'!$E15)/('2_指标值'!$F15-'2_指标值'!$E15)))+0.01 | I15: =0.98*MIN(1,MAX(0,('2_指标值'!M15-'2_指标值'!$E15)/('2_指标值'!$F15-'2_指标值'!$E15)))+0.01 | J15: =0.98*MIN(1,MAX(0,('2_指标值'!N15-'2_指标值'!$E15)/('2_指标值'!$F15-'2_指标值'!$E15)))+0.01 | ... L15: =0.98*MIN(1,MAX(0,('2_指标值'!P15-'2_指标值'!$E15)/('2_指标值'!$F15-'2_指标值'!$E15)))+0.01

Sheet 4_子系统指数
A1: 子系统指数：子系统内等权平均（论文§3(四) 主设定）
A2: 年份 | B2: US 安全 | C2: UD 发展 | D2: UE 生态 | F2: US 论文 | G2: UD 论文 | H2: UE 论文 | J2: US 差 | K2: UD 差 | L2: UE 差
A3: 2016 | B3: =AVERAGE('3_标准化'!C3,'3_标准化'!C4,'3_标准化'!C5,'3_标准化'!C6) | C3: =AVERAGE('3_标准化'!C7,'3_标准化'!C8,'3_标准化'!C9,'3_标准化'!C10,'3_标准化'!C11) | D3: =AVERAGE('3_标准化'!C12,'3_标准化'!C13,'3_标准化'!C14,'3_标准化'!C15) | F3: 0.537 | G3: 0.467 | H3: 0.267 | J3: =B3-F3 | K3: =C3-G3 | L3: =D3-H3
A4: 2017 | B4: =AVERAGE('3_标准化'!D3,'3_标准化'!D4,'3_标准化'!D5,'3_标准化'!D6) | C4: =AVERAGE('3_标准化'!D7,'3_标准化'!D8,'3_标准化'!D9,'3_标准化'!D10,'3_标准化'!D11) | D4: =AVERAGE('3_标准化'!D12,'3_标准化'!D13,'3_标准化'!D14,'3_标准化'!D15) | F4: 0.575 | G4: 0.483 | H4: 0.423 | J4: =B4-F4 | K4: =C4-G4 | L4: =D4-H4
A5: 2018 | B5: =AVERAGE('3_标准化'!E3,'3_标准化'!E4,'3_标准化'!E5,'3_标准化'!E6) | C5: =AVERAGE('3_标准化'!E7,'3_标准化'!E8,'3_标准化'!E9,'3_标准化'!E10,'3_标准化'!E11) | D5: =AVERAGE('3_标准化'!E12,'3_标准化'!E13,'3_标准化'!E14,'3_标准化'!E15) | F5: 0.617 | G5: 0.489 | H5: 0.499 | J5: =B5-F5 | K5: =C5-G5 | L5: =D5-H5
A6: 2019 | B6: =AVERAGE('3_标准化'!F3,'3_标准化'!F4,'3_标准化'!F5,'3_标准化'!F6) | C6: =AVERAGE('3_标准化'!F7,'3_标准化'!F8,'3_标准化'!F9,'3_标准化'!F10,'3_标准化'!F11) | D6: =AVERAGE('3_标准化'!F12,'3_标准化'!F13,'3_标准化'!F14,'3_标准化'!F15) | F6: 0.615 | G6: 0.519 | H6: 0.542 | J6: =B6-F6 | K6: =C6-G6 | L6: =D6-H6
A7: 2020 | B7: =AVERAGE('3_标准化'!G3,'3_标准化'!G4,'3_标准化'!G5,'3_标准化'!G6) | C7: =AVERAGE('3_标准化'!G7,'3_标准化'!G8,'3_标准化'!G9,'3_标准化'!G10,'3_标准化'!G11) | D7: =AVERAGE('3_标准化'!G12,'3_标准化'!G13,'3_标准化'!G14,'3_标准化'!G15) | F7: 0.619 | G7: 0.484 | H7: 0.634 | J7: =B7-F7 | K7: =C7-G7 | L7: =D7-H7
A8: 2021 | B8: =AVERAGE('3_标准化'!H3,'3_标准化'!H4,'3_标准化'!H5,'3_标准化'!H6) | C8: =AVERAGE('3_标准化'!H7,'3_标准化'!H8,'3_标准化'!H9,'3_标准化'!H10,'3_标准化'!H11) | D8: =AVERAGE('3_标准化'!H12,'3_标准化'!H13,'3_标准化'!H14,'3_标准化'!H15) | F8: 0.626 | G8: 0.528 | H8: 0.657 | J8: =B8-F8 | K8: =C8-G8 | L8: =D8-H8
A9: 2022 | B9: =AVERAGE('3_标准化'!I3,'3_标准化'!I4,'3_标准化'!I5,'3_标准化'!I6) | C9: =AVERAGE('3_标准化'!I7,'3_标准化'!I8,'3_标准化'!I9,'3_标准化'!I10,'3_标准化'!I11) | D9: =AVERAGE('3_标准化'!I12,'3_标准化'!I13,'3_标准化'!I14,'3_标准化'!I15) | F9: 0.615 | G9: 0.539 | H9: 0.686 | J9: =B9-F9 | K9: =C9-G9 | L9: =D9-H9
A10: 2023 | B10: =AVERAGE('3_标准化'!J3,'3_标准化'!J4,'3_标准化'!J5,'3_标准化'!J6) | C10: =AVERAGE('3_标准化'!J7,'3_标准化'!J8,'3_标准化'!J9,'3_标准化'!J10,'3_标准化'!J11) | D10: =AVERAGE('3_标准化'!J12,'3_标准化'!J13,'3_标准化'!J14,'3_标准化'!J15) | F10: 0.661 | G10: 0.672 | H10: 0.71 | J10: =B10-F10 | K10: =C10-G10 | L10: =D10-H10
A11: 2024 | B11: =AVERAGE('3_标准化'!K3,'3_标准化'!K4,'3_标准化'!K5,'3_标准化'!K6) | C11: =AVERAGE('3_标准化'!K7,'3_标准化'!K8,'3_标准化'!K9,'3_标准化'!K10,'3_标准化'!K11) | D11: =AVERAGE('3_标准化'!K12,'3_标准化'!K13,'3_标准化'!K14,'3_标准化'!K15) | F11: 0.688 | G11: 0.713 | H11: 0.733 | J11: =B11-F11 | K11: =C11-G11 | L11: =D11-H11
A12: 2025 | B12: =AVERAGE('3_标准化'!L3,'3_标准化'!L4,'3_标准化'!L5,'3_标准化'!L6) | C12: =AVERAGE('3_标准化'!L7,'3_标准化'!L8,'3_标准化'!L9,'3_标准化'!L10,'3_标准化'!L11) | D12: =AVERAGE('3_标准化'!L12,'3_标准化'!L13,'3_标准化'!L14,'3_标准化'!L15) | F12: 0.715 | G12: 0.718 | H12: 0.843 | J12: =B12-F12 | K12: =C12-G12 | L12: =D12-H12

Sheet 5_MPI协调指数
A1: MPI 失衡惩罚型协调指数：D = M − S²/M（M为三子系统均值，S²为总体方差）
A2: 年份 | B2: US | C2: UD | D2: UE | E2: M 均值 | F2: S 标准差 | G2: S² 方差 | H2: CV | I2: D MPI | K2: D 论文 | L2: D 差 | N2: 最弱子系统
A3: 2016 | B3: ='4_子系统指数'!B3 | C3: ='4_子系统指数'!C3 | D3: ='4_子系统指数'!D3 | E3: =AVERAGE(B3:D3) | F3: =STDEV.P(B3:D3) | G3: =VAR.P(B3:D3) | H3: =F3/E3 | I3: =E3-G3/E3 | K3: 0.393 | L3: =I3-K3 | N3: =INDEX({"安全","发展","生态"},MATCH(MIN(B3:D3),B3:D3,0))
A4: 2017 | B4: ='4_子系统指数'!B4 | C4: ='4_子系统指数'!C4 | D4: ='4_子系统指数'!D4 | E4: =AVERAGE(B4:D4) | F4: =STDEV.P(B4:D4) | G4: =VAR.P(B4:D4) | H4: =F4/E4 | I4: =E4-G4/E4 | K4: 0.486 | L4: =I4-K4 | N4: =INDEX({"安全","发展","生态"},MATCH(MIN(B4:D4),B4:D4,0))
A5: 2018 | B5: ='4_子系统指数'!B5 | C5: ='4_子系统指数'!C5 | D5: ='4_子系统指数'!D5 | E5: =AVERAGE(B5:D5) | F5: =STDEV.P(B5:D5) | G5: =VAR.P(B5:D5) | H5: =F5/E5 | I5: =E5-G5/E5 | K5: 0.528 | L5: =I5-K5 | N5: =INDEX({"安全","发展","生态"},MATCH(MIN(B5:D5),B5:D5,0))
A6: 2019 | B6: ='4_子系统指数'!B6 | C6: ='4_子系统指数'!C6 | D6: ='4_子系统指数'!D6 | E6: =AVERAGE(B6:D6) | F6: =STDEV.P(B6:D6) | G6: =VAR.P(B6:D6) | H6: =F6/E6 | I6: =E6-G6/E6 | K6: 0.556 | L6: =I6-K6 | N6: =INDEX({"安全","发展","生态"},MATCH(MIN(B6:D6),B6:D6,0))
A7: 2020 | B7: ='4_子系统指数'!B7 | C7: ='4_子系统指数'!C7 | D7: ='4_子系统指数'!D7 | E7: =AVERAGE(B7:D7) | F7: =STDEV.P(B7:D7) | G7: =VAR.P(B7:D7) | H7: =F7/E7 | I7: =E7-G7/E7 | K7: 0.571 | L7: =I7-K7 | N7: =INDEX({"安全","发展","生态"},MATCH(MIN(B7:D7),B7:D7,0))
A8: 2021 | B8: ='4_子系统指数'!B8 | C8: ='4_子系统指数'!C8 | D8: ='4_子系统指数'!D8 | E8: =AVERAGE(B8:D8) | F8: =STDEV.P(B8:D8) | G8: =VAR.P(B8:D8) | H8: =F8/E8 | I8: =E8-G8/E8 | K8: 0.598 | L8: =I8-K8 | N8: =INDEX({"安全","发展","生态"},MATCH(MIN(B8:D8),B8:D8,0))
A9: 2022 | B9: ='4_子系统指数'!B9 | C9: ='4_子系统指数'!C9 | D9: ='4_子系统指数'!D9 | E9: =AVERAGE(B9:D9) | F9: =STDEV.P(B9:D9) | G9: =VAR.P(B9:D9) | H9: =F9/E9 | I9: =E9-G9/E9 | K9: 0.607 | L9: =I9-K9 | N9: =INDEX({"安全","发展","生态"},MATCH(MIN(B9:D9),B9:D9,0))
A10: 2023 | B10: ='4_子系统指数'!B10 | C10: ='4_子系统指数'!C10 | D10: ='4_子系统指数'!D10 | E10: =AVERAGE(B10:D10) | F10: =STDEV.P(B10:D10) | G10: =VAR.P(B10:D10) | H10: =F10/E10 | I10: =E10-G10/E10 | K10: 0.68 | L10: =I10-K10 | N10: =INDEX({"安全","发展","生态"},MATCH(MIN(B10:D10),B10:D10,0))
A11: 2024 | B11: ='4_子系统指数'!B11 | C11: ='4_子系统指数'!C11 | D11: ='4_子系统指数'!D11 | E11: =AVERAGE(B11:D11) | F11: =STDEV.P(B11:D11) | G11: =VAR.P(B11:D11) | H11: =F11/E11 | I11: =E11-G11/E11 | K11: 0.711 | L11: =I11-K11 | N11: =INDEX({"安全","发展","生态"},MATCH(MIN(B11:D11),B11:D11,0))
A12: 2025 | B12: ='4_子系统指数'!B12 | C12: ='4_子系统指数'!C12 | D12: ='4_子系统指数'!D12 | E12: =AVERAGE(B12:D12) | F12: =STDEV.P(B12:D12) | G12: =VAR.P(B12:D12) | H12: =F12/E12 | I12: =E12-G12/E12 | K12: 0.754 | L12: =I12-K12 | N12: =INDEX({"安全","发展","生态"},MATCH(MIN(B12:D12),B12:D12,0))

Sheet 6_组合权重
A1: 熵值法 × CRITIC 组合权重（仅用于诊断与稳健性对照，不参与子系统合成）
A2: 注：论文子系统合成采用等权。本表权重用于「7_结构性贡献缺口」与权重集中度检验。
A4: 编码 | B4: 指标 | C4: Σx' | D4: 熵值 e | E4: 差异 d=1-e | F4: 熵值权重 | G4: 标准差 σ | H4: 冲突性 Σ(1-r) | I4: CRITIC量 C | J4: CRITIC权重 | K4: 组合(积) | L4: 组合权重
A5: S1 | B5: 人均一般公共预算收入（元/人） | C5: =SUM('3_标准化'!$C$3:$L$3) | D5: =-1/LN(10)*(IF('3_标准化'!C3=0,0,('3_标准化'!C3/$C5)*LN('3_标准化'!C3/$C5))+IF('3_标准化'!D3=0,0,('3_标准化'!D3/$C5)*LN('3_标准化'!D3/$C5))+IF('3_标准化'!E3=0,0,('3_标准化'!E3/$C5)*LN('3_标准化'!E3/$C5))+IF('3_标准化'!F3=0,0,('3_标准化'!F3/$C5)*LN('3_标准化'!F3/$C5))+IF('3_标准化'!G3=0,0,('3_标准化'!G3/$C5)*LN('3_标准化'!G3/$C5))+IF('3_标准化'!H3=0,0,('3_标准化'!H3/$C5)*LN('3_标准化'!H3/$C5))+IF('3_标准化'!I3=0,0,('3_标准化'!I3/$C5)*LN('3_标准化'!I3/$C5))+IF('3_标准化'!J3=0,0,('3_标准化'!J3/$C5)*LN('3_标准化'!J3/$C5))+IF('3_标准化'!K3=0,0,('3_标准化'!K3/$C5)*LN('3_标准化'!K3/$C5))+IF('3_标准化'!L3=0,0,('3_标准化'!L3/$C5)*LN('3_标准化'!L3/$C5))) | E5: =1-D5 | F5: =E5/SUM($E$5:$E$17) | G5: =STDEV.S('3_标准化'!$C$3:$L$3) | H5: =(1-CORREL('3_标准化'!$C$3:$L$3,'3_标准化'!$C$4:$L$4))+(1-CORREL('3_标准化'!$C$3:$L$3,'3_标准化'!$C$5:$L$5))+(1-CORREL('3_标准化'!$C$3:$L$3,'3_标准化'!$C$6:$L$6))+(1-CORREL('3_标准化'!$C$3:$L$3,'3_标准化'!$C$7:$L$7))+(1-CORREL('3_标准化'!$C$3:$L$3,'3_标准化'!$C$8:$L$8))+(1-CORREL('3_标准化'!$C$3:$L$3,'3_标准化'!$C$9:$L$9))+(1-CORREL('3_标准化'!$C$3:$L$3,'3_标准化'!$C$10:$L$10))+(1-CORREL('3_标准化'!$C$3:$L$3,'3_标准化'!$C$11:$L$11))+(1-CORREL('3_标准化'!$C$3:$L$3,'3_标准化'!$C$12:$L$12))+(1-CORREL('3_标准化'!$C$3:$L$3,'3_标准化'!$C$13:$L$13))+(1-CORREL('3_标准化'!$C$3:$L$3,'3_标准化'!$C$14:$L$14))+(1-CORREL('3_标准化'!$C$3:$L$3,'3_标准化'!$C$15:$L$15)) | I5: =G5*H5 | J5: =I5/SUM($I$5:$I$17) | K5: =F5*J5 | L5: =K5/SUM($K$5:$K$17)
A6: S2 | B6: 城乡居民收入比与全国差距（倍） | C6: =SUM('3_标准化'!$C$4:$L$4) | D6: =-1/LN(10)*(IF('3_标准化'!C4=0,0,('3_标准化'!C4/$C6)*LN('3_标准化'!C4/$C6))+IF('3_标准化'!D4=0,0,('3_标准化'!D4/$C6)*LN('3_标准化'!D4/$C6))+IF('3_标准化'!E4=0,0,('3_标准化'!E4/$C6)*LN('3_标准化'!E4/$C6))+IF('3_标准化'!F4=0,0,('3_标准化'!F4/$C6)*LN('3_标准化'!F4/$C6))+IF('3_标准化'!G4=0,0,('3_标准化'!G4/$C6)*LN('3_标准化'!G4/$C6))+IF('3_标准化'!H4=0,0,('3_标准化'!H4/$C6)*LN('3_标准化'!H4/$C6))+IF('3_标准化'!I4=0,0,('3_标准化'!I4/$C6)*LN('3_标准化'!I4/$C6))+IF('3_标准化'!J4=0,0,('3_标准化'!J4/$C6)*LN('3_标准化'!J4/$C6))+IF('3_标准化'!K4=0,0,('3_标准化'!K4/$C6)*LN('3_标准化'!K4/$C6))+IF('3_标准化'!L4=0,0,('3_标准化'!L4/$C6)*LN('3_标准化'!L4/$C6))) | E6: =1-D6 | F6: =E6/SUM($E$5:$E$17) | G6: =STDEV.S('3_标准化'!$C$4:$L$4) | H6: =(1-CORREL('3_标准化'!$C$4:$L$4,'3_标准化'!$C$3:$L$3))+(1-CORREL('3_标准化'!$C$4:$L$4,'3_标准化'!$C$5:$L$5))+(1-CORREL('3_标准化'!$C$4:$L$4,'3_标准化'!$C$6:$L$6))+(1-CORREL('3_标准化'!$C$4:$L$4,'3_标准化'!$C$7:$L$7))+(1-CORREL('3_标准化'!$C$4:$L$4,'3_标准化'!$C$8:$L$8))+(1-CORREL('3_标准化'!$C$4:$L$4,'3_标准化'!$C$9:$L$9))+(1-CORREL('3_标准化'!$C$4:$L$4,'3_标准化'!$C$10:$L$10))+(1-CORREL('3_标准化'!$C$4:$L$4,'3_标准化'!$C$11:$L$11))+(1-CORREL('3_标准化'!$C$4:$L$4,'3_标准化'!$C$12:$L$12))+(1-CORREL('3_标准化'!$C$4:$L$4,'3_标准化'!$C$13:$L$13))+(1-CORREL('3_标准化'!$C$4:$L$4,'3_标准化'!$C$14:$L$14))+(1-CORREL('3_标准化'!$C$4:$L$4,'3_标准化'!$C$15:$L$15)) | I6: =G6*H6 | J6: =I6/SUM($I$5:$I$17) | K6: =F6*J6 | L6: =K6/SUM($K$5:$K$17)
A7: S3 | B7: 居民医保人均财政补助标准（元/人年） | C7: =SUM('3_标准化'!$C$5:$L$5) | D7: =-1/LN(10)*(IF('3_标准化'!C5=0,0,('3_标准化'!C5/$C7)*LN('3_标准化'!C5/$C7))+IF('3_标准化'!D5=0,0,('3_标准化'!D5/$C7)*LN('3_标准化'!D5/$C7))+IF('3_标准化'!E5=0,0,('3_标准化'!E5/$C7)*LN('3_标准化'!E5/$C7))+IF('3_标准化'!F5=0,0,('3_标准化'!F5/$C7)*LN('3_标准化'!F5/$C7))+IF('3_标准化'!G5=0,0,('3_标准化'!G5/$C7)*LN('3_标准化'!G5/$C7))+IF('3_标准化'!H5=0,0,('3_标准化'!H5/$C7)*LN('3_标准化'!H5/$C7))+IF('3_标准化'!I5=0,0,('3_标准化'!I5/$C7)*LN('3_标准化'!I5/$C7))+IF('3_标准化'!J5=0,0,('3_标准化'!J5/$C7)*LN('3_标准化'!J5/$C7))+IF('3_标准化'!K5=0,0,('3_标准化'!K5/$C7)*LN('3_标准化'!K5/$C7))+IF('3_标准化'!L5=0,0,('3_标准化'!L5/$C7)*LN('3_标准化'!L5/$C7))) | E7: =1-D7 | F7: =E7/SUM($E$5:$E$17) | G7: =STDEV.S('3_标准化'!$C$5:$L$5) | H7: =(1-CORREL('3_标准化'!$C$5:$L$5,'3_标准化'!$C$3:$L$3))+(1-CORREL('3_标准化'!$C$5:$L$5,'3_标准化'!$C$4:$L$4))+(1-CORREL('3_标准化'!$C$5:$L$5,'3_标准化'!$C$6:$L$6))+(1-CORREL('3_标准化'!$C$5:$L$5,'3_标准化'!$C$7:$L$7))+(1-CORREL('3_标准化'!$C$5:$L$5,'3_标准化'!$C$8:$L$8))+(1-CORREL('3_标准化'!$C$5:$L$5,'3_标准化'!$C$9:$L$9))+(1-CORREL('3_标准化'!$C$5:$L$5,'3_标准化'!$C$10:$L$10))+(1-CORREL('3_标准化'!$C$5:$L$5,'3_标准化'!$C$11:$L$11))+(1-CORREL('3_标准化'!$C$5:$L$5,'3_标准化'!$C$12:$L$12))+(1-CORREL('3_标准化'!$C$5:$L$5,'3_标准化'!$C$13:$L$13))+(1-CORREL('3_标准化'!$C$5:$L$5,'3_标准化'!$C$14:$L$14))+(1-CORREL('3_标准化'!$C$5:$L$5,'3_标准化'!$C$15:$L$15)) | I7: =G7*H7 | J7: =I7/SUM($I$5:$I$17) | K7: =F7*J7 | L7: =K7/SUM($K$5:$K$17)
A8: S4 | B8: 基本养老保险参保率（%） | C8: =SUM('3_标准化'!$C$6:$L$6) | D8: =-1/LN(10)*(IF('3_标准化'!C6=0,0,('3_标准化'!C6/$C8)*LN('3_标准化'!C6/$C8))+IF('3_标准化'!D6=0,0,('3_标准化'!D6/$C8)*LN('3_标准化'!D6/$C8))+IF('3_标准化'!E6=0,0,('3_标准化'!E6/$C8)*LN('3_标准化'!E6/$C8))+IF('3_标准化'!F6=0,0,('3_标准化'!F6/$C8)*LN('3_标准化'!F6/$C8))+IF('3_标准化'!G6=0,0,('3_标准化'!G6/$C8)*LN('3_标准化'!G6/$C8))+IF('3_标准化'!H6=0,0,('3_标准化'!H6/$C8)*LN('3_标准化'!H6/$C8))+IF('3_标准化'!I6=0,0,('3_标准化'!I6/$C8)*LN('3_标准化'!I6/$C8))+IF('3_标准化'!J6=0,0,('3_标准化'!J6/$C8)*LN('3_标准化'!J6/$C8))+IF('3_标准化'!K6=0,0,('3_标准化'!K6/$C8)*LN('3_标准化'!K6/$C8))+IF('3_标准化'!L6=0,0,('3_标准化'!L6/$C8)*LN('3_标准化'!L6/$C8))) | E8: =1-D8 | F8: =E8/SUM($E$5:$E$17) | G8: =STDEV.S('3_标准化'!$C$6:$L$6) | H8: =(1-CORREL('3_标准化'!$C$6:$L$6,'3_标准化'!$C$3:$L$3))+(1-CORREL('3_标准化'!$C$6:$L$6,'3_标准化'!$C$4:$L$4))+(1-CORREL('3_标准化'!$C$6:$L$6,'3_标准化'!$C$5:$L$5))+(1-CORREL('3_标准化'!$C$6:$L$6,'3_标准化'!$C$7:$L$7))+(1-CORREL('3_标准化'!$C$6:$L$6,'3_标准化'!$C$8:$L$8))+(1-CORREL('3_标准化'!$C$6:$L$6,'3_标准化'!$C$9:$L$9))+(1-CORREL('3_标准化'!$C$6:$L$6,'3_标准化'!$C$10:$L$10))+(1-CORREL('3_标准化'!$C$6:$L$6,'3_标准化'!$C$11:$L$11))+(1-CORREL('3_标准化'!$C$6:$L$6,'3_标准化'!$C$12:$L$12))+(1-CORREL('3_标准化'!$C$6:$L$6,'3_标准化'!$C$13:$L$13))+(1-CORREL('3_标准化'!$C$6:$L$6,'3_标准化'!$C$14:$L$14))+(1-CORREL('3_标准化'!$C$6:$L$6,'3_标准化'!$C$15:$L$15)) | I8: =G8*H8 | J8: =I8/SUM($I$5:$I$17) | K8: =F8*J8 | L8: =K8/SUM($K$5:$K$17)
A9: D1 | B9: 人均GDP相对全国水平（%） | C9: =SUM('3_标准化'!$C$7:$L$7) | D9: =-1/LN(10)*(IF('3_标准化'!C7=0,0,('3_标准化'!C7/$C9)*LN('3_标准化'!C7/$C9))+IF('3_标准化'!D7=0,0,('3_标准化'!D7/$C9)*LN('3_标准化'!D7/$C9))+IF('3_标准化'!E7=0,0,('3_标准化'!E7/$C9)*LN('3_标准化'!E7/$C9))+IF('3_标准化'!F7=0,0,('3_标准化'!F7/$C9)*LN('3_标准化'!F7/$C9))+IF('3_标准化'!G7=0,0,('3_标准化'!G7/$C9)*LN('3_标准化'!G7/$C9))+IF('3_标准化'!H7=0,0,('3_标准化'!H7/$C9)*LN('3_标准化'!H7/$C9))+IF('3_标准化'!I7=0,0,('3_标准化'!I7/$C9)*LN('3_标准化'!I7/$C9))+IF('3_标准化'!J7=0,0,('3_标准化'!J7/$C9)*LN('3_标准化'!J7/$C9))+IF('3_标准化'!K7=0,0,('3_标准化'!K7/$C9)*LN('3_标准化'!K7/$C9))+IF('3_标准化'!L7=0,0,('3_标准化'!L7/$C9)*LN('3_标准化'!L7/$C9))) | E9: =1-D9 | F9: =E9/SUM($E$5:$E$17) | G9: =STDEV.S('3_标准化'!$C$7:$L$7) | H9: =(1-CORREL('3_标准化'!$C$7:$L$7,'3_标准化'!$C$3:$L$3))+(1-CORREL('3_标准化'!$C$7:$L$7,'3_标准化'!$C$4:$L$4))+(1-CORREL('3_标准化'!$C$7:$L$7,'3_标准化'!$C$5:$L$5))+(1-CORREL('3_标准化'!$C$7:$L$7,'3_标准化'!$C$6:$L$6))+(1-CORREL('3_标准化'!$C$7:$L$7,'3_标准化'!$C$8:$L$8))+(1-CORREL('3_标准化'!$C$7:$L$7,'3_标准化'!$C$9:$L$9))+(1-CORREL('3_标准化'!$C$7:$L$7,'3_标准化'!$C$10:$L$10))+(1-CORREL('3_标准化'!$C$7:$L$7,'3_标准化'!$C$11:$L$11))+(1-CORREL('3_标准化'!$C$7:$L$7,'3_标准化'!$C$12:$L$12))+(1-CORREL('3_标准化'!$C$7:$L$7,'3_标准化'!$C$13:$L$13))+(1-CORREL('3_标准化'!$C$7:$L$7,'3_标准化'!$C$14:$L$14))+(1-CORREL('3_标准化'!$C$7:$L$7,'3_标准化'!$C$15:$L$15)) | I9: =G9*H9 | J9: =I9/SUM($I$5:$I$17) | K9: =F9*J9 | L9: =K9/SUM($K$5:$K$17)
A10: D2 | B10: 农村居民人均收入相对全国水平（%） | C10: =SUM('3_标准化'!$C$8:$L$8) | D10: =-1/LN(10)*(IF('3_标准化'!C8=0,0,('3_标准化'!C8/$C10)*LN('3_标准化'!C8/$C10))+IF('3_标准化'!D8=0,0,('3_标准化'!D8/$C10)*LN('3_标准化'!D8/$C10))+IF('3_标准化'!E8=0,0,('3_标准化'!E8/$C10)*LN('3_标准化'!E8/$C10))+IF('3_标准化'!F8=0,0,('3_标准化'!F8/$C10)*LN('3_标准化'!F8/$C10))+IF('3_标准化'!G8=0,0,('3_标准化'!G8/$C10)*LN('3_标准化'!G8/$C10))+IF('3_标准化'!H8=0,0,('3_标准化'!H8/$C10)*LN('3_标准化'!H8/$C10))+IF('3_标准化'!I8=0,0,('3_标准化'!I8/$C10)*LN('3_标准化'!I8/$C10))+IF('3_标准化'!J8=0,0,('3_标准化'!J8/$C10)*LN('3_标准化'!J8/$C10))+IF('3_标准化'!K8=0,0,('3_标准化'!K8/$C10)*LN('3_标准化'!K8/$C10))+IF('3_标准化'!L8=0,0,('3_标准化'!L8/$C10)*LN('3_标准化'!L8/$C10))) | E10: =1-D10 | F10: =E10/SUM($E$5:$E$17) | G10: =STDEV.S('3_标准化'!$C$8:$L$8) | H10: =(1-CORREL('3_标准化'!$C$8:$L$8,'3_标准化'!$C$3:$L$3))+(1-CORREL('3_标准化'!$C$8:$L$8,'3_标准化'!$C$4:$L$4))+(1-CORREL('3_标准化'!$C$8:$L$8,'3_标准化'!$C$5:$L$5))+(1-CORREL('3_标准化'!$C$8:$L$8,'3_标准化'!$C$6:$L$6))+(1-CORREL('3_标准化'!$C$8:$L$8,'3_标准化'!$C$7:$L$7))+(1-CORREL('3_标准化'!$C$8:$L$8,'3_标准化'!$C$9:$L$9))+(1-CORREL('3_标准化'!$C$8:$L$8,'3_标准化'!$C$10:$L$10))+(1-CORREL('3_标准化'!$C$8:$L$8,'3_标准化'!$C$11:$L$11))+(1-CORREL('3_标准化'!$C$8:$L$8,'3_标准化'!$C$12:$L$12))+(1-CORREL('3_标准化'!$C$8:$L$8,'3_标准化'!$C$13:$L$13))+(1-CORREL('3_标准化'!$C$8:$L$8,'3_标准化'!$C$14:$L$14))+(1-CORREL('3_标准化'!$C$8:$L$8,'3_标准化'!$C$15:$L$15)) | I10: =G10*H10 | J10: =I10/SUM($I$5:$I$17) | K10: =F10*J10 | L10: =K10/SUM($K$5:$K$17)
A11: D3 | B11: 外向度（进出口总额/GDP，%） | C11: =SUM('3_标准化'!$C$9:$L$9) | D11: =-1/LN(10)*(IF('3_标准化'!C9=0,0,('3_标准化'!C9/$C11)*LN('3_标准化'!C9/$C11))+IF('3_标准化'!D9=0,0,('3_标准化'!D9/$C11)*LN('3_标准化'!D9/$C11))+IF('3_标准化'!E9=0,0,('3_标准化'!E9/$C11)*LN('3_标准化'!E9/$C11))+IF('3_标准化'!F9=0,0,('3_标准化'!F9/$C11)*LN('3_标准化'!F9/$C11))+IF('3_标准化'!G9=0,0,('3_标准化'!G9/$C11)*LN('3_标准化'!G9/$C11))+IF('3_标准化'!H9=0,0,('3_标准化'!H9/$C11)*LN('3_标准化'!H9/$C11))+IF('3_标准化'!I9=0,0,('3_标准化'!I9/$C11)*LN('3_标准化'!I9/$C11))+IF('3_标准化'!J9=0,0,('3_标准化'!J9/$C11)*LN('3_标准化'!J9/$C11))+IF('3_标准化'!K9=0,0,('3_标准化'!K9/$C11)*LN('3_标准化'!K9/$C11))+IF('3_标准化'!L9=0,0,('3_标准化'!L9/$C11)*LN('3_标准化'!L9/$C11))) | E11: =1-D11 | F11: =E11/SUM($E$5:$E$17) | G11: =STDEV.S('3_标准化'!$C$9:$L$9) | H11: =(1-CORREL('3_标准化'!$C$9:$L$9,'3_标准化'!$C$3:$L$3))+(1-CORREL('3_标准化'!$C$9:$L$9,'3_标准化'!$C$4:$L$4))+(1-CORREL('3_标准化'!$C$9:$L$9,'3_标准化'!$C$5:$L$5))+(1-CORREL('3_标准化'!$C$9:$L$9,'3_标准化'!$C$6:$L$6))+(1-CORREL('3_标准化'!$C$9:$L$9,'3_标准化'!$C$7:$L$7))+(1-CORREL('3_标准化'!$C$9:$L$9,'3_标准化'!$C$8:$L$8))+(1-CORREL('3_标准化'!$C$9:$L$9,'3_标准化'!$C$10:$L$10))+(1-CORREL('3_标准化'!$C$9:$L$9,'3_标准化'!$C$11:$L$11))+(1-CORREL('3_标准化'!$C$9:$L$9,'3_标准化'!$C$12:$L$12))+(1-CORREL('3_标准化'!$C$9:$L$9,'3_标准化'!$C$13:$L$13))+(1-CORREL('3_标准化'!$C$9:$L$9,'3_标准化'!$C$14:$L$14))+(1-CORREL('3_标准化'!$C$9:$L$9,'3_标准化'!$C$15:$L$15)) | I11: =G11*H11 | J11: =I11/SUM($I$5:$I$17) | K11: =F11*J11 | L11: =K11/SUM($K$5:$K$17)
A12: D4 | B12: 人均接待游客（万人次/万人） | C12: =SUM('3_标准化'!$C$10:$L$10) | D12: =-1/LN(10)*(IF('3_标准化'!C10=0,0,('3_标准化'!C10/$C12)*LN('3_标准化'!C10/$C12))+IF('3_标准化'!D10=0,0,('3_标准化'!D10/$C12)*LN('3_标准化'!D10/$C12))+IF('3_标准化'!E10=0,0,('3_标准化'!E10/$C12)*LN('3_标准化'!E10/$C12))+IF('3_标准化'!F10=0,0,('3_标准化'!F10/$C12)*LN('3_标准化'!F10/$C12))+IF('3_标准化'!G10=0,0,('3_标准化'!G10/$C12)*LN('3_标准化'!G10/$C12))+IF('3_标准化'!H10=0,0,('3_标准化'!H10/$C12)*LN('3_标准化'!H10/$C12))+IF('3_标准化'!I10=0,0,('3_标准化'!I10/$C12)*LN('3_标准化'!I10/$C12))+IF('3_标准化'!J10=0,0,('3_标准化'!J10/$C12)*LN('3_标准化'!J10/$C12))+IF('3_标准化'!K10=0,0,('3_标准化'!K10/$C12)*LN('3_标准化'!K10/$C12))+IF('3_标准化'!L10=0,0,('3_标准化'!L10/$C12)*LN('3_标准化'!L10/$C12))) | E12: =1-D12 | F12: =E12/SUM($E$5:$E$17) | G12: =STDEV.S('3_标准化'!$C$10:$L$10) | H12: =(1-CORREL('3_标准化'!$C$10:$L$10,'3_标准化'!$C$3:$L$3))+(1-CORREL('3_标准化'!$C$10:$L$10,'3_标准化'!$C$4:$L$4))+(1-CORREL('3_标准化'!$C$10:$L$10,'3_标准化'!$C$5:$L$5))+(1-CORREL('3_标准化'!$C$10:$L$10,'3_标准化'!$C$6:$L$6))+(1-CORREL('3_标准化'!$C$10:$L$10,'3_标准化'!$C$7:$L$7))+(1-CORREL('3_标准化'!$C$10:$L$10,'3_标准化'!$C$8:$L$8))+(1-CORREL('3_标准化'!$C$10:$L$10,'3_标准化'!$C$9:$L$9))+(1-CORREL('3_标准化'!$C$10:$L$10,'3_标准化'!$C$11:$L$11))+(1-CORREL('3_标准化'!$C$10:$L$10,'3_标准化'!$C$12:$L$12))+(1-CORREL('3_标准化'!$C$10:$L$10,'3_标准化'!$C$13:$L$13))+(1-CORREL('3_标准化'!$C$10:$L$10,'3_标准化'!$C$14:$L$14))+(1-CORREL('3_标准化'!$C$10:$L$10,'3_标准化'!$C$15:$L$15)) | I12: =G12*H12 | J12: =I12/SUM($I$5:$I$17) | K12: =F12*J12 | L12: =K12/SUM($K$5:$K$17)
A13: D5 | B13: 发电量（亿千瓦时） | C13: =SUM('3_标准化'!$C$11:$L$11) | D13: =-1/LN(10)*(IF('3_标准化'!C11=0,0,('3_标准化'!C11/$C13)*LN('3_标准化'!C11/$C13))+IF('3_标准化'!D11=0,0,('3_标准化'!D11/$C13)*LN('3_标准化'!D11/$C13))+IF('3_标准化'!E11=0,0,('3_标准化'!E11/$C13)*LN('3_标准化'!E11/$C13))+IF('3_标准化'!F11=0,0,('3_标准化'!F11/$C13)*LN('3_标准化'!F11/$C13))+IF('3_标准化'!G11=0,0,('3_标准化'!G11/$C13)*LN('3_标准化'!G11/$C13))+IF('3_标准化'!H11=0,0,('3_标准化'!H11/$C13)*LN('3_标准化'!H11/$C13))+IF('3_标准化'!I11=0,0,('3_标准化'!I11/$C13)*LN('3_标准化'!I11/$C13))+IF('3_标准化'!J11=0,0,('3_标准化'!J11/$C13)*LN('3_标准化'!J11/$C13))+IF('3_标准化'!K11=0,0,('3_标准化'!K11/$C13)*LN('3_标准化'!K11/$C13))+IF('3_标准化'!L11=0,0,('3_标准化'!L11/$C13)*LN('3_标准化'!L11/$C13))) | E13: =1-D13 | F13: =E13/SUM($E$5:$E$17) | G13: =STDEV.S('3_标准化'!$C$11:$L$11) | H13: =(1-CORREL('3_标准化'!$C$11:$L$11,'3_标准化'!$C$3:$L$3))+(1-CORREL('3_标准化'!$C$11:$L$11,'3_标准化'!$C$4:$L$4))+(1-CORREL('3_标准化'!$C$11:$L$11,'3_标准化'!$C$5:$L$5))+(1-CORREL('3_标准化'!$C$11:$L$11,'3_标准化'!$C$6:$L$6))+(1-CORREL('3_标准化'!$C$11:$L$11,'3_标准化'!$C$7:$L$7))+(1-CORREL('3_标准化'!$C$11:$L$11,'3_标准化'!$C$8:$L$8))+(1-CORREL('3_标准化'!$C$11:$L$11,'3_标准化'!$C$9:$L$9))+(1-CORREL('3_标准化'!$C$11:$L$11,'3_标准化'!$C$10:$L$10))+(1-CORREL('3_标准化'!$C$11:$L$11,'3_标准化'!$C$12:$L$12))+(1-CORREL('3_标准化'!$C$11:$L$11,'3_标准化'!$C$13:$L$13))+(1-CORREL('3_标准化'!$C$11:$L$11,'3_标准化'!$C$14:$L$14))+(1-CORREL('3_标准化'!$C$11:$L$11,'3_标准化'!$C$15:$L$15)) | I13: =G13*H13 | J13: =I13/SUM($I$5:$I$17) | K13: =F13*J13 | L13: =K13/SUM($K$5:$K$17)
A14: E1 | B14: 单位GDP能耗指数 | C14: =SUM('3_标准化'!$C$12:$L$12) | D14: =-1/LN(10)*(IF('3_标准化'!C12=0,0,('3_标准化'!C12/$C14)*LN('3_标准化'!C12/$C14))+IF('3_标准化'!D12=0,0,('3_标准化'!D12/$C14)*LN('3_标准化'!D12/$C14))+IF('3_标准化'!E12=0,0,('3_标准化'!E12/$C14)*LN('3_标准化'!E12/$C14))+IF('3_标准化'!F12=0,0,('3_标准化'!F12/$C14)*LN('3_标准化'!F12/$C14))+IF('3_标准化'!G12=0,0,('3_标准化'!G12/$C14)*LN('3_标准化'!G12/$C14))+IF('3_标准化'!H12=0,0,('3_标准化'!H12/$C14)*LN('3_标准化'!H12/$C14))+IF('3_标准化'!I12=0,0,('3_标准化'!I12/$C14)*LN('3_标准化'!I12/$C14))+IF('3_标准化'!J12=0,0,('3_标准化'!J12/$C14)*LN('3_标准化'!J12/$C14))+IF('3_标准化'!K12=0,0,('3_标准化'!K12/$C14)*LN('3_标准化'!K12/$C14))+IF('3_标准化'!L12=0,0,('3_标准化'!L12/$C14)*LN('3_标准化'!L12/$C14))) | E14: =1-D14 | F14: =E14/SUM($E$5:$E$17) | G14: =STDEV.S('3_标准化'!$C$12:$L$12) | H14: =(1-CORREL('3_标准化'!$C$12:$L$12,'3_标准化'!$C$3:$L$3))+(1-CORREL('3_标准化'!$C$12:$L$12,'3_标准化'!$C$4:$L$4))+(1-CORREL('3_标准化'!$C$12:$L$12,'3_标准化'!$C$5:$L$5))+(1-CORREL('3_标准化'!$C$12:$L$12,'3_标准化'!$C$6:$L$6))+(1-CORREL('3_标准化'!$C$12:$L$12,'3_标准化'!$C$7:$L$7))+(1-CORREL('3_标准化'!$C$12:$L$12,'3_标准化'!$C$8:$L$8))+(1-CORREL('3_标准化'!$C$12:$L$12,'3_标准化'!$C$9:$L$9))+(1-CORREL('3_标准化'!$C$12:$L$12,'3_标准化'!$C$10:$L$10))+(1-CORREL('3_标准化'!$C$12:$L$12,'3_标准化'!$C$11:$L$11))+(1-CORREL('3_标准化'!$C$12:$L$12,'3_标准化'!$C$13:$L$13))+(1-CORREL('3_标准化'!$C$12:$L$12,'3_标准化'!$C$14:$L$14))+(1-CORREL('3_标准化'!$C$12:$L$12,'3_标准化'!$C$15:$L$15)) | I14: =G14*H14 | J14: =I14/SUM($I$5:$I$17) | K14: =F14*J14 | L14: =K14/SUM($K$5:$K$17)
A15: E2 | B15: 森林覆盖率（%） | C15: =SUM('3_标准化'!$C$13:$L$13) | D15: =-1/LN(10)*(IF('3_标准化'!C13=0,0,('3_标准化'!C13/$C15)*LN('3_标准化'!C13/$C15))+IF('3_标准化'!D13=0,0,('3_标准化'!D13/$C15)*LN('3_标准化'!D13/$C15))+IF('3_标准化'!E13=0,0,('3_标准化'!E13/$C15)*LN('3_标准化'!E13/$C15))+IF('3_标准化'!F13=0,0,('3_标准化'!F13/$C15)*LN('3_标准化'!F13/$C15))+IF('3_标准化'!G13=0,0,('3_标准化'!G13/$C15)*LN('3_标准化'!G13/$C15))+IF('3_标准化'!H13=0,0,('3_标准化'!H13/$C15)*LN('3_标准化'!H13/$C15))+IF('3_标准化'!I13=0,0,('3_标准化'!I13/$C15)*LN('3_标准化'!I13/$C15))+IF('3_标准化'!J13=0,0,('3_标准化'!J13/$C15)*LN('3_标准化'!J13/$C15))+IF('3_标准化'!K13=0,0,('3_标准化'!K13/$C15)*LN('3_标准化'!K13/$C15))+IF('3_标准化'!L13=0,0,('3_标准化'!L13/$C15)*LN('3_标准化'!L13/$C15))) | E15: =1-D15 | F15: =E15/SUM($E$5:$E$17) | G15: =STDEV.S('3_标准化'!$C$13:$L$13) | H15: =(1-CORREL('3_标准化'!$C$13:$L$13,'3_标准化'!$C$3:$L$3))+(1-CORREL('3_标准化'!$C$13:$L$13,'3_标准化'!$C$4:$L$4))+(1-CORREL('3_标准化'!$C$13:$L$13,'3_标准化'!$C$5:$L$5))+(1-CORREL('3_标准化'!$C$13:$L$13,'3_标准化'!$C$6:$L$6))+(1-CORREL('3_标准化'!$C$13:$L$13,'3_标准化'!$C$7:$L$7))+(1-CORREL('3_标准化'!$C$13:$L$13,'3_标准化'!$C$8:$L$8))+(1-CORREL('3_标准化'!$C$13:$L$13,'3_标准化'!$C$9:$L$9))+(1-CORREL('3_标准化'!$C$13:$L$13,'3_标准化'!$C$10:$L$10))+(1-CORREL('3_标准化'!$C$13:$L$13,'3_标准化'!$C$11:$L$11))+(1-CORREL('3_标准化'!$C$13:$L$13,'3_标准化'!$C$12:$L$12))+(1-CORREL('3_标准化'!$C$13:$L$13,'3_标准化'!$C$14:$L$14))+(1-CORREL('3_标准化'!$C$13:$L$13,'3_标准化'!$C$15:$L$15)) | I15: =G15*H15 | J15: =I15/SUM($I$5:$I$17) | K15: =F15*J15 | L15: =K15/SUM($K$5:$K$17)
A16: E3 | B16: 空气质量优良天数比例（%） | C16: =SUM('3_标准化'!$C$14:$L$14) | D16: =-1/LN(10)*(IF('3_标准化'!C14=0,0,('3_标准化'!C14/$C16)*LN('3_标准化'!C14/$C16))+IF('3_标准化'!D14=0,0,('3_标准化'!D14/$C16)*LN('3_标准化'!D14/$C16))+IF('3_标准化'!E14=0,0,('3_标准化'!E14/$C16)*LN('3_标准化'!E14/$C16))+IF('3_标准化'!F14=0,0,('3_标准化'!F14/$C16)*LN('3_标准化'!F14/$C16))+IF('3_标准化'!G14=0,0,('3_标准化'!G14/$C16)*LN('3_标准化'!G14/$C16))+IF('3_标准化'!H14=0,0,('3_标准化'!H14/$C16)*LN('3_标准化'!H14/$C16))+IF('3_标准化'!I14=0,0,('3_标准化'!I14/$C16)*LN('3_标准化'!I14/$C16))+IF('3_标准化'!J14=0,0,('3_标准化'!J14/$C16)*LN('3_标准化'!J14/$C16))+IF('3_标准化'!K14=0,0,('3_标准化'!K14/$C16)*LN('3_标准化'!K14/$C16))+IF('3_标准化'!L14=0,0,('3_标准化'!L14/$C16)*LN('3_标准化'!L14/$C16))) | E16: =1-D16 | F16: =E16/SUM($E$5:$E$17) | G16: =STDEV.S('3_标准化'!$C$14:$L$14) | H16: =(1-CORREL('3_标准化'!$C$14:$L$14,'3_标准化'!$C$3:$L$3))+(1-CORREL('3_标准化'!$C$14:$L$14,'3_标准化'!$C$4:$L$4))+(1-CORREL('3_标准化'!$C$14:$L$14,'3_标准化'!$C$5:$L$5))+(1-CORREL('3_标准化'!$C$14:$L$14,'3_标准化'!$C$6:$L$6))+(1-CORREL('3_标准化'!$C$14:$L$14,'3_标准化'!$C$7:$L$7))+(1-CORREL('3_标准化'!$C$14:$L$14,'3_标准化'!$C$8:$L$8))+(1-CORREL('3_标准化'!$C$14:$L$14,'3_标准化'!$C$9:$L$9))+(1-CORREL('3_标准化'!$C$14:$L$14,'3_标准化'!$C$10:$L$10))+(1-CORREL('3_标准化'!$C$14:$L$14,'3_标准化'!$C$11:$L$11))+(1-CORREL('3_标准化'!$C$14:$L$14,'3_标准化'!$C$12:$L$12))+(1-CORREL('3_标准化'!$C$14:$L$14,'3_标准化'!$C$13:$L$13))+(1-CORREL('3_标准化'!$C$14:$L$14,'3_标准化'!$C$15:$L$15)) | I16: =G16*H16 | J16: =I16/SUM($I$5:$I$17) | K16: =F16*J16 | L16: =K16/SUM($K$5:$K$17)
A17: E4 | B17: 草原综合植被盖度（%） | C17: =SUM('3_标准化'!$C$15:$L$15) | D17: =-1/LN(10)*(IF('3_标准化'!C15=0,0,('3_标准化'!C15/$C17)*LN('3_标准化'!C15/$C17))+IF('3_标准化'!D15=0,0,('3_标准化'!D15/$C17)*LN('3_标准化'!D15/$C17))+IF('3_标准化'!E15=0,0,('3_标准化'!E15/$C17)*LN('3_标准化'!E15/$C17))+IF('3_标准化'!F15=0,0,('3_标准化'!F15/$C17)*LN('3_标准化'!F15/$C17))+IF('3_标准化'!G15=0,0,('3_标准化'!G15/$C17)*LN('3_标准化'!G15/$C17))+IF('3_标准化'!H15=0,0,('3_标准化'!H15/$C17)*LN('3_标准化'!H15/$C17))+IF('3_标准化'!I15=0,0,('3_标准化'!I15/$C17)*LN('3_标准化'!I15/$C17))+IF('3_标准化'!J15=0,0,('3_标准化'!J15/$C17)*LN('3_标准化'!J15/$C17))+IF('3_标准化'!K15=0,0,('3_标准化'!K15/$C17)*LN('3_标准化'!K15/$C17))+IF('3_标准化'!L15=0,0,('3_标准化'!L15/$C17)*LN('3_标准化'!L15/$C17))) | E17: =1-D17 | F17: =E17/SUM($E$5:$E$17) | G17: =STDEV.S('3_标准化'!$C$15:$L$15) | H17: =(1-CORREL('3_标准化'!$C$15:$L$15,'3_标准化'!$C$3:$L$3))+(1-CORREL('3_标准化'!$C$15:$L$15,'3_标准化'!$C$4:$L$4))+(1-CORREL('3_标准化'!$C$15:$L$15,'3_标准化'!$C$5:$L$5))+(1-CORREL('3_标准化'!$C$15:$L$15,'3_标准化'!$C$6:$L$6))+(1-CORREL('3_标准化'!$C$15:$L$15,'3_标准化'!$C$7:$L$7))+(1-CORREL('3_标准化'!$C$15:$L$15,'3_标准化'!$C$8:$L$8))+(1-CORREL('3_标准化'!$C$15:$L$15,'3_标准化'!$C$9:$L$9))+(1-CORREL('3_标准化'!$C$15:$L$15,'3_标准化'!$C$10:$L$10))+(1-CORREL('3_标准化'!$C$15:$L$15,'3_标准化'!$C$11:$L$11))+(1-CORREL('3_标准化'!$C$15:$L$15,'3_标准化'!$C$12:$L$12))+(1-CORREL('3_标准化'!$C$15:$L$15,'3_标准化'!$C$13:$L$13))+(1-CORREL('3_标准化'!$C$15:$L$15,'3_标准化'!$C$14:$L$14)) | I17: =G17*H17 | J17: =I17/SUM($I$5:$I$17) | K17: =F17*J17 | L17: =K17/SUM($K$5:$K$17)
B18: 合计 | F18: =SUM(F5:F17) | J18: =SUM(J5:J17) | L18: =SUM(L5:L17)

Sheet 7_结构性贡献缺口
A1: 结构性贡献缺口 O(i,j) = w(j)·I(i,j) / Σ w·I，I=1-x'，逐年计算后取样本期均值（论文表4）
A2: 编码 | B2: 指标 | C2: 2016 | D2: 2017 | E2: 2018 | F2: 2019 | G2: 2020 | H2: 2021 | I2: 2022 | J2: 2023 | K2: 2024 | L2: 2025 | M2: 样本期均值 | N2: 论文表4
A3: S1 | B3: 人均一般公共预算收入（元/人） | C3: ='6_组合权重'!$L$5*(1-'3_标准化'!C3)/C$17 | D3: ='6_组合权重'!$L$5*(1-'3_标准化'!D3)/D$17 | E3: ='6_组合权重'!$L$5*(1-'3_标准化'!E3)/E$17 | F3: ='6_组合权重'!$L$5*(1-'3_标准化'!F3)/F$17 | G3: ='6_组合权重'!$L$5*(1-'3_标准化'!G3)/G$17 | H3: ='6_组合权重'!$L$5*(1-'3_标准化'!H3)/H$17 | I3: ='6_组合权重'!$L$5*(1-'3_标准化'!I3)/I$17 | J3: ='6_组合权重'!$L$5*(1-'3_标准化'!J3)/J$17 | ... L3: ='6_组合权重'!$L$5*(1-'3_标准化'!L3)/L$17 | M3: =AVERAGE(C3:L3)
A4: S2 | B4: 城乡居民收入比与全国差距（倍） | C4: ='6_组合权重'!$L$6*(1-'3_标准化'!C4)/C$17 | D4: ='6_组合权重'!$L$6*(1-'3_标准化'!D4)/D$17 | E4: ='6_组合权重'!$L$6*(1-'3_标准化'!E4)/E$17 | F4: ='6_组合权重'!$L$6*(1-'3_标准化'!F4)/F$17 | G4: ='6_组合权重'!$L$6*(1-'3_标准化'!G4)/G$17 | H4: ='6_组合权重'!$L$6*(1-'3_标准化'!H4)/H$17 | I4: ='6_组合权重'!$L$6*(1-'3_标准化'!I4)/I$17 | J4: ='6_组合权重'!$L$6*(1-'3_标准化'!J4)/J$17 | ... L4: ='6_组合权重'!$L$6*(1-'3_标准化'!L4)/L$17 | M4: =AVERAGE(C4:L4)
A5: S3 | B5: 居民医保人均财政补助标准（元/人年） | C5: ='6_组合权重'!$L$7*(1-'3_标准化'!C5)/C$17 | D5: ='6_组合权重'!$L$7*(1-'3_标准化'!D5)/D$17 | E5: ='6_组合权重'!$L$7*(1-'3_标准化'!E5)/E$17 | F5: ='6_组合权重'!$L$7*(1-'3_标准化'!F5)/F$17 | G5: ='6_组合权重'!$L$7*(1-'3_标准化'!G5)/G$17 | H5: ='6_组合权重'!$L$7*(1-'3_标准化'!H5)/H$17 | I5: ='6_组合权重'!$L$7*(1-'3_标准化'!I5)/I$17 | J5: ='6_组合权重'!$L$7*(1-'3_标准化'!J5)/J$17 | ... L5: ='6_组合权重'!$L$7*(1-'3_标准化'!L5)/L$17 | M5: =AVERAGE(C5:L5)
A6: S4 | B6: 基本养老保险参保率（%） | C6: ='6_组合权重'!$L$8*(1-'3_标准化'!C6)/C$17 | D6: ='6_组合权重'!$L$8*(1-'3_标准化'!D6)/D$17 | E6: ='6_组合权重'!$L$8*(1-'3_标准化'!E6)/E$17 | F6: ='6_组合权重'!$L$8*(1-'3_标准化'!F6)/F$17 | G6: ='6_组合权重'!$L$8*(1-'3_标准化'!G6)/G$17 | H6: ='6_组合权重'!$L$8*(1-'3_标准化'!H6)/H$17 | I6: ='6_组合权重'!$L$8*(1-'3_标准化'!I6)/I$17 | J6: ='6_组合权重'!$L$8*(1-'3_标准化'!J6)/J$17 | ... L6: ='6_组合权重'!$L$8*(1-'3_标准化'!L6)/L$17 | M6: =AVERAGE(C6:L6)
A7: D1 | B7: 人均GDP相对全国水平（%） | C7: ='6_组合权重'!$L$9*(1-'3_标准化'!C7)/C$17 | D7: ='6_组合权重'!$L$9*(1-'3_标准化'!D7)/D$17 | E7: ='6_组合权重'!$L$9*(1-'3_标准化'!E7)/E$17 | F7: ='6_组合权重'!$L$9*(1-'3_标准化'!F7)/F$17 | G7: ='6_组合权重'!$L$9*(1-'3_标准化'!G7)/G$17 | H7: ='6_组合权重'!$L$9*(1-'3_标准化'!H7)/H$17 | I7: ='6_组合权重'!$L$9*(1-'3_标准化'!I7)/I$17 | J7: ='6_组合权重'!$L$9*(1-'3_标准化'!J7)/J$17 | ... L7: ='6_组合权重'!$L$9*(1-'3_标准化'!L7)/L$17 | M7: =AVERAGE(C7:L7)
A8: D2 | B8: 农村居民人均收入相对全国水平（%） | C8: ='6_组合权重'!$L$10*(1-'3_标准化'!C8)/C$17 | D8: ='6_组合权重'!$L$10*(1-'3_标准化'!D8)/D$17 | E8: ='6_组合权重'!$L$10*(1-'3_标准化'!E8)/E$17 | F8: ='6_组合权重'!$L$10*(1-'3_标准化'!F8)/F$17 | G8: ='6_组合权重'!$L$10*(1-'3_标准化'!G8)/G$17 | H8: ='6_组合权重'!$L$10*(1-'3_标准化'!H8)/H$17 | I8: ='6_组合权重'!$L$10*(1-'3_标准化'!I8)/I$17 | J8: ='6_组合权重'!$L$10*(1-'3_标准化'!J8)/J$17 | ... L8: ='6_组合权重'!$L$10*(1-'3_标准化'!L8)/L$17 | M8: =AVERAGE(C8:L8)
A9: D3 | B9: 外向度（进出口总额/GDP，%） | C9: ='6_组合权重'!$L$11*(1-'3_标准化'!C9)/C$17 | D9: ='6_组合权重'!$L$11*(1-'3_标准化'!D9)/D$17 | E9: ='6_组合权重'!$L$11*(1-'3_标准化'!E9)/E$17 | F9: ='6_组合权重'!$L$11*(1-'3_标准化'!F9)/F$17 | G9: ='6_组合权重'!$L$11*(1-'3_标准化'!G9)/G$17 | H9: ='6_组合权重'!$L$11*(1-'3_标准化'!H9)/H$17 | I9: ='6_组合权重'!$L$11*(1-'3_标准化'!I9)/I$17 | J9: ='6_组合权重'!$L$11*(1-'3_标准化'!J9)/J$17 | ... L9: ='6_组合权重'!$L$11*(1-'3_标准化'!L9)/L$17 | M9: =AVERAGE(C9:L9) | N9: 0.3109
A10: D4 | B10: 人均接待游客（万人次/万人） | C10: ='6_组合权重'!$L$12*(1-'3_标准化'!C10)/C$17 | D10: ='6_组合权重'!$L$12*(1-'3_标准化'!D10)/D$17 | E10: ='6_组合权重'!$L$12*(1-'3_标准化'!E10)/E$17 | F10: ='6_组合权重'!$L$12*(1-'3_标准化'!F10)/F$17 | G10: ='6_组合权重'!$L$12*(1-'3_标准化'!G10)/G$17 | H10: ='6_组合权重'!$L$12*(1-'3_标准化'!H10)/H$17 | I10: ='6_组合权重'!$L$12*(1-'3_标准化'!I10)/I$17 | J10: ='6_组合权重'!$L$12*(1-'3_标准化'!J10)/J$17 | ... L10: ='6_组合权重'!$L$12*(1-'3_标准化'!L10)/L$17 | M10: =AVERAGE(C10:L10) | N10: 0.0513
A11: D5 | B11: 发电量（亿千瓦时） | C11: ='6_组合权重'!$L$13*(1-'3_标准化'!C11)/C$17 | D11: ='6_组合权重'!$L$13*(1-'3_标准化'!D11)/D$17 | E11: ='6_组合权重'!$L$13*(1-'3_标准化'!E11)/E$17 | F11: ='6_组合权重'!$L$13*(1-'3_标准化'!F11)/F$17 | G11: ='6_组合权重'!$L$13*(1-'3_标准化'!G11)/G$17 | H11: ='6_组合权重'!$L$13*(1-'3_标准化'!H11)/H$17 | I11: ='6_组合权重'!$L$13*(1-'3_标准化'!I11)/I$17 | J11: ='6_组合权重'!$L$13*(1-'3_标准化'!J11)/J$17 | ... L11: ='6_组合权重'!$L$13*(1-'3_标准化'!L11)/L$17 | M11: =AVERAGE(C11:L11) | N11: 0.0922
A12: E1 | B12: 单位GDP能耗指数 | C12: ='6_组合权重'!$L$14*(1-'3_标准化'!C12)/C$17 | D12: ='6_组合权重'!$L$14*(1-'3_标准化'!D12)/D$17 | E12: ='6_组合权重'!$L$14*(1-'3_标准化'!E12)/E$17 | F12: ='6_组合权重'!$L$14*(1-'3_标准化'!F12)/F$17 | G12: ='6_组合权重'!$L$14*(1-'3_标准化'!G12)/G$17 | H12: ='6_组合权重'!$L$14*(1-'3_标准化'!H12)/H$17 | I12: ='6_组合权重'!$L$14*(1-'3_标准化'!I12)/I$17 | J12: ='6_组合权重'!$L$14*(1-'3_标准化'!J12)/J$17 | ... L12: ='6_组合权重'!$L$14*(1-'3_标准化'!L12)/L$17 | M12: =AVERAGE(C12:L12) | N12: 0.1145
A13: E2 | B13: 森林覆盖率（%） | C13: ='6_组合权重'!$L$15*(1-'3_标准化'!C13)/C$17 | D13: ='6_组合权重'!$L$15*(1-'3_标准化'!D13)/D$17 | E13: ='6_组合权重'!$L$15*(1-'3_标准化'!E13)/E$17 | F13: ='6_组合权重'!$L$15*(1-'3_标准化'!F13)/F$17 | G13: ='6_组合权重'!$L$15*(1-'3_标准化'!G13)/G$17 | H13: ='6_组合权重'!$L$15*(1-'3_标准化'!H13)/H$17 | I13: ='6_组合权重'!$L$15*(1-'3_标准化'!I13)/I$17 | J13: ='6_组合权重'!$L$15*(1-'3_标准化'!J13)/J$17 | ... L13: ='6_组合权重'!$L$15*(1-'3_标准化'!L13)/L$17 | M13: =AVERAGE(C13:L13) | N13: 0.2556
A14: E3 | B14: 空气质量优良天数比例（%） | C14: ='6_组合权重'!$L$16*(1-'3_标准化'!C14)/C$17 | D14: ='6_组合权重'!$L$16*(1-'3_标准化'!D14)/D$17 | E14: ='6_组合权重'!$L$16*(1-'3_标准化'!E14)/E$17 | F14: ='6_组合权重'!$L$16*(1-'3_标准化'!F14)/F$17 | G14: ='6_组合权重'!$L$16*(1-'3_标准化'!G14)/G$17 | H14: ='6_组合权重'!$L$16*(1-'3_标准化'!H14)/H$17 | I14: ='6_组合权重'!$L$16*(1-'3_标准化'!I14)/I$17 | J14: ='6_组合权重'!$L$16*(1-'3_标准化'!J14)/J$17 | ... L14: ='6_组合权重'!$L$16*(1-'3_标准化'!L14)/L$17 | M14: =AVERAGE(C14:L14)
A15: E4 | B15: 草原综合植被盖度（%） | C15: ='6_组合权重'!$L$17*(1-'3_标准化'!C15)/C$17 | D15: ='6_组合权重'!$L$17*(1-'3_标准化'!D15)/D$17 | E15: ='6_组合权重'!$L$17*(1-'3_标准化'!E15)/E$17 | F15: ='6_组合权重'!$L$17*(1-'3_标准化'!F15)/F$17 | G15: ='6_组合权重'!$L$17*(1-'3_标准化'!G15)/G$17 | H15: ='6_组合权重'!$L$17*(1-'3_标准化'!H15)/H$17 | I15: ='6_组合权重'!$L$17*(1-'3_标准化'!I15)/I$17 | J15: ='6_组合权重'!$L$17*(1-'3_标准化'!J15)/J$17 | ... L15: ='6_组合权重'!$L$17*(1-'3_标准化'!L15)/L$17 | M15: =AVERAGE(C15:L15) | N15: 0.1582
B17: 分母 Σ w·I | C17: =SUMPRODUCT(('6_组合权重'!$L$5:$L$17),(1-'3_标准化'!C3:C15)) | D17: =SUMPRODUCT(('6_组合权重'!$L$5:$L$17),(1-'3_标准化'!D3:D15)) | E17: =SUMPRODUCT(('6_组合权重'!$L$5:$L$17),(1-'3_标准化'!E3:E15)) | F17: =SUMPRODUCT(('6_组合权重'!$L$5:$L$17),(1-'3_标准化'!F3:F15)) | G17: =SUMPRODUCT(('6_组合权重'!$L$5:$L$17),(1-'3_标准化'!G3:G15)) | H17: =SUMPRODUCT(('6_组合权重'!$L$5:$L$17),(1-'3_标准化'!H3:H15)) | I17: =SUMPRODUCT(('6_组合权重'!$L$5:$L$17),(1-'3_标准化'!I3:I15)) | J17: =SUMPRODUCT(('6_组合权重'!$L$5:$L$17),(1-'3_标准化'!J3:J15)) | ... L17: =SUMPRODUCT(('6_组合权重'!$L$5:$L$17),(1-'3_标准化'!L3:L15))

Sheet 8_局部敏感性
A1: 局部敏感性 ε = (D⁺−D⁻)/(0.02·D)，±1% 相对扰动双侧数值微分（论文表5）
A2: 年份 | B2: εS 安全 | C2: εD 发展 | D2: εE 生态 | F2: εS 论文 | G2: εD 论文 | H2: εE 论文 | J2: εS 差 | K2: εD 差 | L2: εE 差
A3: 2016 | B3: =((AVERAGE('4_子系统指数'!B3*1.01,'4_子系统指数'!C3,'4_子系统指数'!D3)-VAR.P('4_子系统指数'!B3*1.01,'4_子系统指数'!C3,'4_子系统指数'!D3)/AVERAGE('4_子系统指数'!B3*1.01,'4_子系统指数'!C3,'4_子系统指数'!D3))-(AVERAGE('4_子系统指数'!B3*0.99,'4_子系统指数'!C3,'4_子系统指数'!D3)-VAR.P('4_子系统指数'!B3*0.99,'4_子系统指数'!C3,'4_子系统指数'!D3)/AVERAGE('4_子系统指数'!B3*0.99,'4_子系统指数'!C3,'4_子系统指数'!D3)))/(0.02*'5_MPI协调指数'!I3) | C3: =((AVERAGE('4_子系统指数'!B3,'4_子系统指数'!C3*1.01,'4_子系统指数'!D3)-VAR.P('4_子系统指数'!B3,'4_子系统指数'!C3*1.01,'4_子系统指数'!D3)/AVERAGE('4_子系统指数'!B3,'4_子系统指数'!C3*1.01,'4_子系统指数'!D3))-(AVERAGE('4_子系统指数'!B3,'4_子系统指数'!C3*0.99,'4_子系统指数'!D3)-VAR.P('4_子系统指数'!B3,'4_子系统指数'!C3*0.99,'4_子系统指数'!D3)/AVERAGE('4_子系统指数'!B3,'4_子系统指数'!C3*0.99,'4_子系统指数'!D3)))/(0.02*'5_MPI协调指数'!I3) | D3: =((AVERAGE('4_子系统指数'!B3,'4_子系统指数'!C3,'4_子系统指数'!D3*1.01)-VAR.P('4_子系统指数'!B3,'4_子系统指数'!C3,'4_子系统指数'!D3*1.01)/AVERAGE('4_子系统指数'!B3,'4_子系统指数'!C3,'4_子系统指数'!D3*1.01))-(AVERAGE('4_子系统指数'!B3,'4_子系统指数'!C3,'4_子系统指数'!D3*0.99)-VAR.P('4_子系统指数'!B3,'4_子系统指数'!C3,'4_子系统指数'!D3*0.99)/AVERAGE('4_子系统指数'!B3,'4_子系统指数'!C3,'4_子系统指数'!D3*0.99)))/(0.02*'5_MPI协调指数'!I3)
A4: 2017 | B4: =((AVERAGE('4_子系统指数'!B4*1.01,'4_子系统指数'!C4,'4_子系统指数'!D4)-VAR.P('4_子系统指数'!B4*1.01,'4_子系统指数'!C4,'4_子系统指数'!D4)/AVERAGE('4_子系统指数'!B4*1.01,'4_子系统指数'!C4,'4_子系统指数'!D4))-(AVERAGE('4_子系统指数'!B4*0.99,'4_子系统指数'!C4,'4_子系统指数'!D4)-VAR.P('4_子系统指数'!B4*0.99,'4_子系统指数'!C4,'4_子系统指数'!D4)/AVERAGE('4_子系统指数'!B4*0.99,'4_子系统指数'!C4,'4_子系统指数'!D4)))/(0.02*'5_MPI协调指数'!I4) | C4: =((AVERAGE('4_子系统指数'!B4,'4_子系统指数'!C4*1.01,'4_子系统指数'!D4)-VAR.P('4_子系统指数'!B4,'4_子系统指数'!C4*1.01,'4_子系统指数'!D4)/AVERAGE('4_子系统指数'!B4,'4_子系统指数'!C4*1.01,'4_子系统指数'!D4))-(AVERAGE('4_子系统指数'!B4,'4_子系统指数'!C4*0.99,'4_子系统指数'!D4)-VAR.P('4_子系统指数'!B4,'4_子系统指数'!C4*0.99,'4_子系统指数'!D4)/AVERAGE('4_子系统指数'!B4,'4_子系统指数'!C4*0.99,'4_子系统指数'!D4)))/(0.02*'5_MPI协调指数'!I4) | D4: =((AVERAGE('4_子系统指数'!B4,'4_子系统指数'!C4,'4_子系统指数'!D4*1.01)-VAR.P('4_子系统指数'!B4,'4_子系统指数'!C4,'4_子系统指数'!D4*1.01)/AVERAGE('4_子系统指数'!B4,'4_子系统指数'!C4,'4_子系统指数'!D4*1.01))-(AVERAGE('4_子系统指数'!B4,'4_子系统指数'!C4,'4_子系统指数'!D4*0.99)-VAR.P('4_子系统指数'!B4,'4_子系统指数'!C4,'4_子系统指数'!D4*0.99)/AVERAGE('4_子系统指数'!B4,'4_子系统指数'!C4,'4_子系统指数'!D4*0.99)))/(0.02*'5_MPI协调指数'!I4) | F4: 0.271 | G4: 0.351 | H4: 0.378 | J4: =B4-F4 | K4: =C4-G4 | L4: =D4-H4
A5: 2018 | B5: =((AVERAGE('4_子系统指数'!B5*1.01,'4_子系统指数'!C5,'4_子系统指数'!D5)-VAR.P('4_子系统指数'!B5*1.01,'4_子系统指数'!C5,'4_子系统指数'!D5)/AVERAGE('4_子系统指数'!B5*1.01,'4_子系统指数'!C5,'4_子系统指数'!D5))-(AVERAGE('4_子系统指数'!B5*0.99,'4_子系统指数'!C5,'4_子系统指数'!D5)-VAR.P('4_子系统指数'!B5*0.99,'4_子系统指数'!C5,'4_子系统指数'!D5)/AVERAGE('4_子系统指数'!B5*0.99,'4_子系统指数'!C5,'4_子系统指数'!D5)))/(0.02*'5_MPI协调指数'!I5) | C5: =((AVERAGE('4_子系统指数'!B5,'4_子系统指数'!C5*1.01,'4_子系统指数'!D5)-VAR.P('4_子系统指数'!B5,'4_子系统指数'!C5*1.01,'4_子系统指数'!D5)/AVERAGE('4_子系统指数'!B5,'4_子系统指数'!C5*1.01,'4_子系统指数'!D5))-(AVERAGE('4_子系统指数'!B5,'4_子系统指数'!C5*0.99,'4_子系统指数'!D5)-VAR.P('4_子系统指数'!B5,'4_子系统指数'!C5*0.99,'4_子系统指数'!D5)/AVERAGE('4_子系统指数'!B5,'4_子系统指数'!C5*0.99,'4_子系统指数'!D5)))/(0.02*'5_MPI协调指数'!I5) | D5: =((AVERAGE('4_子系统指数'!B5,'4_子系统指数'!C5,'4_子系统指数'!D5*1.01)-VAR.P('4_子系统指数'!B5,'4_子系统指数'!C5,'4_子系统指数'!D5*1.01)/AVERAGE('4_子系统指数'!B5,'4_子系统指数'!C5,'4_子系统指数'!D5*1.01))-(AVERAGE('4_子系统指数'!B5,'4_子系统指数'!C5,'4_子系统指数'!D5*0.99)-VAR.P('4_子系统指数'!B5,'4_子系统指数'!C5,'4_子系统指数'!D5*0.99)/AVERAGE('4_子系统指数'!B5,'4_子系统指数'!C5,'4_子系统指数'!D5*0.99)))/(0.02*'5_MPI协调指数'!I5) | F5: 0.274 | G5: 0.365 | H5: 0.361 | J5: =B5-F5 | K5: =C5-G5 | L5: =D5-H5
A6: 2019 | B6: =((AVERAGE('4_子系统指数'!B6*1.01,'4_子系统指数'!C6,'4_子系统指数'!D6)-VAR.P('4_子系统指数'!B6*1.01,'4_子系统指数'!C6,'4_子系统指数'!D6)/AVERAGE('4_子系统指数'!B6*1.01,'4_子系统指数'!C6,'4_子系统指数'!D6))-(AVERAGE('4_子系统指数'!B6*0.99,'4_子系统指数'!C6,'4_子系统指数'!D6)-VAR.P('4_子系统指数'!B6*0.99,'4_子系统指数'!C6,'4_子系统指数'!D6)/AVERAGE('4_子系统指数'!B6*0.99,'4_子系统指数'!C6,'4_子系统指数'!D6)))/(0.02*'5_MPI协调指数'!I6) | C6: =((AVERAGE('4_子系统指数'!B6,'4_子系统指数'!C6*1.01,'4_子系统指数'!D6)-VAR.P('4_子系统指数'!B6,'4_子系统指数'!C6*1.01,'4_子系统指数'!D6)/AVERAGE('4_子系统指数'!B6,'4_子系统指数'!C6*1.01,'4_子系统指数'!D6))-(AVERAGE('4_子系统指数'!B6,'4_子系统指数'!C6*0.99,'4_子系统指数'!D6)-VAR.P('4_子系统指数'!B6,'4_子系统指数'!C6*0.99,'4_子系统指数'!D6)/AVERAGE('4_子系统指数'!B6,'4_子系统指数'!C6*0.99,'4_子系统指数'!D6)))/(0.02*'5_MPI协调指数'!I6) | D6: =((AVERAGE('4_子系统指数'!B6,'4_子系统指数'!C6,'4_子系统指数'!D6*1.01)-VAR.P('4_子系统指数'!B6,'4_子系统指数'!C6,'4_子系统指数'!D6*1.01)/AVERAGE('4_子系统指数'!B6,'4_子系统指数'!C6,'4_子系统指数'!D6*1.01))-(AVERAGE('4_子系统指数'!B6,'4_子系统指数'!C6,'4_子系统指数'!D6*0.99)-VAR.P('4_子系统指数'!B6,'4_子系统指数'!C6,'4_子系统指数'!D6*0.99)/AVERAGE('4_子系统指数'!B6,'4_子系统指数'!C6,'4_子系统指数'!D6*0.99)))/(0.02*'5_MPI协调指数'!I6) | F6: 0.297 | G6: 0.357 | H6: 0.346 | J6: =B6-F6 | K6: =C6-G6 | L6: =D6-H6
A7: 2020 | B7: =((AVERAGE('4_子系统指数'!B7*1.01,'4_子系统指数'!C7,'4_子系统指数'!D7)-VAR.P('4_子系统指数'!B7*1.01,'4_子系统指数'!C7,'4_子系统指数'!D7)/AVERAGE('4_子系统指数'!B7*1.01,'4_子系统指数'!C7,'4_子系统指数'!D7))-(AVERAGE('4_子系统指数'!B7*0.99,'4_子系统指数'!C7,'4_子系统指数'!D7)-VAR.P('4_子系统指数'!B7*0.99,'4_子系统指数'!C7,'4_子系统指数'!D7)/AVERAGE('4_子系统指数'!B7*0.99,'4_子系统指数'!C7,'4_子系统指数'!D7)))/(0.02*'5_MPI协调指数'!I7) | C7: =((AVERAGE('4_子系统指数'!B7,'4_子系统指数'!C7*1.01,'4_子系统指数'!D7)-VAR.P('4_子系统指数'!B7,'4_子系统指数'!C7*1.01,'4_子系统指数'!D7)/AVERAGE('4_子系统指数'!B7,'4_子系统指数'!C7*1.01,'4_子系统指数'!D7))-(AVERAGE('4_子系统指数'!B7,'4_子系统指数'!C7*0.99,'4_子系统指数'!D7)-VAR.P('4_子系统指数'!B7,'4_子系统指数'!C7*0.99,'4_子系统指数'!D7)/AVERAGE('4_子系统指数'!B7,'4_子系统指数'!C7*0.99,'4_子系统指数'!D7)))/(0.02*'5_MPI协调指数'!I7) | D7: =((AVERAGE('4_子系统指数'!B7,'4_子系统指数'!C7,'4_子系统指数'!D7*1.01)-VAR.P('4_子系统指数'!B7,'4_子系统指数'!C7,'4_子系统指数'!D7*1.01)/AVERAGE('4_子系统指数'!B7,'4_子系统指数'!C7,'4_子系统指数'!D7*1.01))-(AVERAGE('4_子系统指数'!B7,'4_子系统指数'!C7,'4_子系统指数'!D7*0.99)-VAR.P('4_子系统指数'!B7,'4_子系统指数'!C7,'4_子系统指数'!D7*0.99)/AVERAGE('4_子系统指数'!B7,'4_子系统指数'!C7,'4_子系统指数'!D7*0.99)))/(0.02*'5_MPI协调指数'!I7) | F7: 0.317 | G7: 0.379 | H7: 0.305 | J7: =B7-F7 | K7: =C7-G7 | L7: =D7-H7
A8: 2021 | B8: =((AVERAGE('4_子系统指数'!B8*1.01,'4_子系统指数'!C8,'4_子系统指数'!D8)-VAR.P('4_子系统指数'!B8*1.01,'4_子系统指数'!C8,'4_子系统指数'!D8)/AVERAGE('4_子系统指数'!B8*1.01,'4_子系统指数'!C8,'4_子系统指数'!D8))-(AVERAGE('4_子系统指数'!B8*0.99,'4_子系统指数'!C8,'4_子系统指数'!D8)-VAR.P('4_子系统指数'!B8*0.99,'4_子系统指数'!C8,'4_子系统指数'!D8)/AVERAGE('4_子系统指数'!B8*0.99,'4_子系统指数'!C8,'4_子系统指数'!D8)))/(0.02*'5_MPI协调指数'!I8) | C8: =((AVERAGE('4_子系统指数'!B8,'4_子系统指数'!C8*1.01,'4_子系统指数'!D8)-VAR.P('4_子系统指数'!B8,'4_子系统指数'!C8*1.01,'4_子系统指数'!D8)/AVERAGE('4_子系统指数'!B8,'4_子系统指数'!C8*1.01,'4_子系统指数'!D8))-(AVERAGE('4_子系统指数'!B8,'4_子系统指数'!C8*0.99,'4_子系统指数'!D8)-VAR.P('4_子系统指数'!B8,'4_子系统指数'!C8*0.99,'4_子系统指数'!D8)/AVERAGE('4_子系统指数'!B8,'4_子系统指数'!C8*0.99,'4_子系统指数'!D8)))/(0.02*'5_MPI协调指数'!I8) | D8: =((AVERAGE('4_子系统指数'!B8,'4_子系统指数'!C8,'4_子系统指数'!D8*1.01)-VAR.P('4_子系统指数'!B8,'4_子系统指数'!C8,'4_子系统指数'!D8*1.01)/AVERAGE('4_子系统指数'!B8,'4_子系统指数'!C8,'4_子系统指数'!D8*1.01))-(AVERAGE('4_子系统指数'!B8,'4_子系统指数'!C8,'4_子系统指数'!D8*0.99)-VAR.P('4_子系统指数'!B8,'4_子系统指数'!C8,'4_子系统指数'!D8*0.99)/AVERAGE('4_子系统指数'!B8,'4_子系统指数'!C8,'4_子系统指数'!D8*0.99)))/(0.02*'5_MPI协调指数'!I8) | F8: 0.326 | G8: 0.37 | H8: 0.304 | J8: =B8-F8 | K8: =C8-G8 | L8: =D8-H8
A9: 2022 | B9: =((AVERAGE('4_子系统指数'!B9*1.01,'4_子系统指数'!C9,'4_子系统指数'!D9)-VAR.P('4_子系统指数'!B9*1.01,'4_子系统指数'!C9,'4_子系统指数'!D9)/AVERAGE('4_子系统指数'!B9*1.01,'4_子系统指数'!C9,'4_子系统指数'!D9))-(AVERAGE('4_子系统指数'!B9*0.99,'4_子系统指数'!C9,'4_子系统指数'!D9)-VAR.P('4_子系统指数'!B9*0.99,'4_子系统指数'!C9,'4_子系统指数'!D9)/AVERAGE('4_子系统指数'!B9*0.99,'4_子系统指数'!C9,'4_子系统指数'!D9)))/(0.02*'5_MPI协调指数'!I9) | C9: =((AVERAGE('4_子系统指数'!B9,'4_子系统指数'!C9*1.01,'4_子系统指数'!D9)-VAR.P('4_子系统指数'!B9,'4_子系统指数'!C9*1.01,'4_子系统指数'!D9)/AVERAGE('4_子系统指数'!B9,'4_子系统指数'!C9*1.01,'4_子系统指数'!D9))-(AVERAGE('4_子系统指数'!B9,'4_子系统指数'!C9*0.99,'4_子系统指数'!D9)-VAR.P('4_子系统指数'!B9,'4_子系统指数'!C9*0.99,'4_子系统指数'!D9)/AVERAGE('4_子系统指数'!B9,'4_子系统指数'!C9*0.99,'4_子系统指数'!D9)))/(0.02*'5_MPI协调指数'!I9) | D9: =((AVERAGE('4_子系统指数'!B9,'4_子系统指数'!C9,'4_子系统指数'!D9*1.01)-VAR.P('4_子系统指数'!B9,'4_子系统指数'!C9,'4_子系统指数'!D9*1.01)/AVERAGE('4_子系统指数'!B9,'4_子系统指数'!C9,'4_子系统指数'!D9*1.01))-(AVERAGE('4_子系统指数'!B9,'4_子系统指数'!C9,'4_子系统指数'!D9*0.99)-VAR.P('4_子系统指数'!B9,'4_子系统指数'!C9,'4_子系统指数'!D9*0.99)/AVERAGE('4_子系统指数'!B9,'4_子系统指数'!C9,'4_子系统指数'!D9*0.99)))/(0.02*'5_MPI协调指数'!I9) | F9: 0.339 | G9: 0.37 | H9: 0.291 | J9: =B9-F9 | K9: =C9-G9 | L9: =D9-H9
A10: 2023 | B10: =((AVERAGE('4_子系统指数'!B10*1.01,'4_子系统指数'!C10,'4_子系统指数'!D10)-VAR.P('4_子系统指数'!B10*1.01,'4_子系统指数'!C10,'4_子系统指数'!D10)/AVERAGE('4_子系统指数'!B10*1.01,'4_子系统指数'!C10,'4_子系统指数'!D10))-(AVERAGE('4_子系统指数'!B10*0.99,'4_子系统指数'!C10,'4_子系统指数'!D10)-VAR.P('4_子系统指数'!B10*0.99,'4_子系统指数'!C10,'4_子系统指数'!D10)/AVERAGE('4_子系统指数'!B10*0.99,'4_子系统指数'!C10,'4_子系统指数'!D10)))/(0.02*'5_MPI协调指数'!I10) | C10: =((AVERAGE('4_子系统指数'!B10,'4_子系统指数'!C10*1.01,'4_子系统指数'!D10)-VAR.P('4_子系统指数'!B10,'4_子系统指数'!C10*1.01,'4_子系统指数'!D10)/AVERAGE('4_子系统指数'!B10,'4_子系统指数'!C10*1.01,'4_子系统指数'!D10))-(AVERAGE('4_子系统指数'!B10,'4_子系统指数'!C10*0.99,'4_子系统指数'!D10)-VAR.P('4_子系统指数'!B10,'4_子系统指数'!C10*0.99,'4_子系统指数'!D10)/AVERAGE('4_子系统指数'!B10,'4_子系统指数'!C10*0.99,'4_子系统指数'!D10)))/(0.02*'5_MPI协调指数'!I10) | D10: =((AVERAGE('4_子系统指数'!B10,'4_子系统指数'!C10,'4_子系统指数'!D10*1.01)-VAR.P('4_子系统指数'!B10,'4_子系统指数'!C10,'4_子系统指数'!D10*1.01)/AVERAGE('4_子系统指数'!B10,'4_子系统指数'!C10,'4_子系统指数'!D10*1.01))-(AVERAGE('4_子系统指数'!B10,'4_子系统指数'!C10,'4_子系统指数'!D10*0.99)-VAR.P('4_子系统指数'!B10,'4_子系统指数'!C10,'4_子系统指数'!D10*0.99)/AVERAGE('4_子系统指数'!B10,'4_子系统指数'!C10,'4_子系统指数'!D10*0.99)))/(0.02*'5_MPI协调指数'!I10) | F10: 0.343 | G10: 0.338 | H10: 0.319 | J10: =B10-F10 | K10: =C10-G10 | L10: =D10-H10
A11: 2024 | B11: =((AVERAGE('4_子系统指数'!B11*1.01,'4_子系统指数'!C11,'4_子系统指数'!D11)-VAR.P('4_子系统指数'!B11*1.01,'4_子系统指数'!C11,'4_子系统指数'!D11)/AVERAGE('4_子系统指数'!B11*1.01,'4_子系统指数'!C11,'4_子系统指数'!D11))-(AVERAGE('4_子系统指数'!B11*0.99,'4_子系统指数'!C11,'4_子系统指数'!D11)-VAR.P('4_子系统指数'!B11*0.99,'4_子系统指数'!C11,'4_子系统指数'!D11)/AVERAGE('4_子系统指数'!B11*0.99,'4_子系统指数'!C11,'4_子系统指数'!D11)))/(0.02*'5_MPI协调指数'!I11) | C11: =((AVERAGE('4_子系统指数'!B11,'4_子系统指数'!C11*1.01,'4_子系统指数'!D11)-VAR.P('4_子系统指数'!B11,'4_子系统指数'!C11*1.01,'4_子系统指数'!D11)/AVERAGE('4_子系统指数'!B11,'4_子系统指数'!C11*1.01,'4_子系统指数'!D11))-(AVERAGE('4_子系统指数'!B11,'4_子系统指数'!C11*0.99,'4_子系统指数'!D11)-VAR.P('4_子系统指数'!B11,'4_子系统指数'!C11*0.99,'4_子系统指数'!D11)/AVERAGE('4_子系统指数'!B11,'4_子系统指数'!C11*0.99,'4_子系统指数'!D11)))/(0.02*'5_MPI协调指数'!I11) | D11: =((AVERAGE('4_子系统指数'!B11,'4_子系统指数'!C11,'4_子系统指数'!D11*1.01)-VAR.P('4_子系统指数'!B11,'4_子系统指数'!C11,'4_子系统指数'!D11*1.01)/AVERAGE('4_子系统指数'!B11,'4_子系统指数'!C11,'4_子系统指数'!D11*1.01))-(AVERAGE('4_子系统指数'!B11,'4_子系统指数'!C11,'4_子系统指数'!D11*0.99)-VAR.P('4_子系统指数'!B11,'4_子系统指数'!C11,'4_子系统指数'!D11*0.99)/AVERAGE('4_子系统指数'!B11,'4_子系统指数'!C11,'4_子系统指数'!D11*0.99)))/(0.02*'5_MPI协调指数'!I11) | F11: 0.344 | G11: 0.333 | H11: 0.323 | J11: =B11-F11 | K11: =C11-G11 | L11: =D11-H11
