Workbook

Sheet 说明
A1: 西藏高质量发展三元均衡评价 · 全过程可复现计算底稿
A3: 数据来源：作者整理，2016—2025 年自治区级时序（原始数据见「1_原始数据」表，蓝色字为可修改的原始输入）。
A5: 计算链路（每一步均为活公式，修改原始数据后全部自动重算）：
A6: 1_原始数据 → 2_标准化（极差标准化并平移至[0.01,1]，逆向指标取反）
A7: → 3_权重（熵值法权重、CRITIC权重、二者乘积归一得组合权重）
A8: → 4_子系统指数（各子系统内以组合权重加权，得 US/UD/UE）
A9: → 5_耦合协调度（传统耦合度C、离散系数CV、修正耦合度C′=C(1−CV)、T、D=√(C′·T)、等级；并列传统D对照）
A10: → 6_障碍度（指标偏离度×权重归一，识别短板）
A11: → 7_偏弹性（协调度D对各子系统的弹性，数值微分）
A13: 一致性核验：本底稿由原始数据算得的 US/UD/UE 与论文表2逐年一致（各表内已列「论文表2值」与「差异」两列供核对）。
A15: 颜色约定：蓝色=原始输入（可改）；黑色=本表公式；绿色=引用其他表；黄底=关键假设/需注意。
A16: 说明：极差标准化平移常数取 0.01（避免熵值取对数时出现 0）；组合权重采用「熵值权重×CRITIC权重后归一」；
A17: T 权重取 α=β=γ=1/3（三系统同等重要）；CV 采用总体标准差；等级按耦合协调度十分法判定。

Sheet 1_原始数据
A1: 子系统 | B1: 指标 | C1: 方向 | D1: 单位 | E1: 2016 | F1: 2017 | G1: 2018 | H1: 2019 | I1: 2020 | J1: 2021 | K1: 2022 | L1: 2023 | M1: 2024 | N1: 2025
A2: 安全 S | B2: 地方一般公共预算收入 | C2: + | D2: 亿元 | E2: 155.99 | F2: 185.83 | G2: 230.35 | H2: 221.99 | I2: 220.99 | J2: 215.62 | K2: 179.63 | L2: 236.63 | M2: 277.19 | N2: 317.9
A3: 安全 S | B3: 城乡居民人均可支配收入比 | C3: - | D3: 倍 | E3: 3.0571806 | F3: 2.9691191 | G3: 2.9517031 | H3: 2.88858 | I3: 2.8192903 | J3: 2.7459699 | K3: 2.6774123 | L3: 2.6048986 | M3: 2.5694689 | N3: 2.5359731
A4: 安全 S | B4: 居民医保人均财政补助标准 | C4: + | D4: 元/人·年 | E4: 420 | F4: 450 | G4: 515 | H4: 515 | I4: 550 | J4: 580 | K4: 615 | L4: 675 | M4: 705 | N4: 735
A5: 安全 S | B5: 基本养老保险参保率 | C5: + | D5: % | E5: 0.855 | F5: 0.893 | G5: 0.9115 | H5: 0.926 | I5: 0.941 | J5: 0.952 | K5: 0.955 | L5: 0.958 | M5: 0.9631 | N5: 0.965
A6: 发展 D | B6: 人均GDP相对全国水平 | C6: + | D6: % | E6: 0.65418441 | F6: 0.65893073 | G6: 0.66222114 | H6: 0.69782243 | I6: 0.7287548 | J6: 0.6838046 | K6: 0.685 | L6: 0.7344 | M6: 0.7858 | N6: 0.8177
A7: 发展 D | B7: 第三产业增加值比重 | C7: + | D7: % | E7: 58.2 | F7: 57.4 | G7: 55.1 | H7: 55.6 | I7: 56.1 | J7: 57.4 | K7: 57.2 | L7: 57.5 | M7: 54.3 | N7: 52.5
A8: 发展 D | B8: 地区生产总值 | C8: + | D8: 亿元 | E8: 1197.38 | F8: 1380.97 | G8: 1583.48 | H8: 1750.34 | I8: 1956.54 | J8: 2145.08 | K8: 2235.39 | L8: 2532.86 | M8: 2789.07 | N8: 3031.89
A9: 发展 D | B9: 农村居民人均可支配收入 | C9: + | D9: 元 | E9: 9094 | F9: 10330 | G9: 11450 | H9: 12951 | I9: 14598 | J9: 16935 | K9: 18209 | L9: 19924 | M9: 21578 | N9: 23184
A10: 发展 D | B10: 货物进出口总额 | C10: + | D10: 亿元 | E10: 51.67 | F10: 59.19 | G10: 47.52 | H10: 48.76 | I10: 21.33 | J10: 40.16 | K10: 46.01 | L10: 109.78 | M10: 126.72 | N10: 84.79
A11: 发展 D | B11: 接待游客总人数 | C11: + | D11: 万人次 | E11: 2315.94 | F11: 2561.43 | G11: 3368.73 | H11: 4012.15 | I11: 3505.01 | J11: 4153.44 | K11: 3002.76 | L11: 5516.98 | M11: 6389.1 | N11: 7073.37
A12: 发展 D | B12: 清洁能源发电量 | C12: + | D12: 亿千瓦时 | E12: 50.78 | F12: 52.06 | G12: 63.14 | H12: 66.3 | I12: 67.1 | J12: 80.8 | K12: 111.1 | L12: 133.5 | M12: 140.41 | N12: 162.42
A13: 生态 E | B13: 单位GDP能耗指数 | C13: - | D13: 指数 | E13: 96.8 | F13: 93.41 | G13: 90.51 | H13: 87.98 | I13: 86.66 | J13: 84.06 | K13: 81.2 | L13: 78.85 | M13: 76.41 | N13: 73.89
... A16: 生态 E | B16: 草原综合植被盖度 | C16: + | D16: % | E16: 42.3 | F16: 44.2 | G16: 45.9 | H16: 46.7 | I16: 46.9 | J16: 47.14 | K16: 47.5 | L16: 47.78 | M16: 48.02 | N16: 48.07

Sheet 2_标准化
A1: 子系统 | B1: 指标 | C1: 方向 | D1: 2016 | E1: 2017 | F1: 2018 | G1: 2019 | H1: 2020 | I1: 2021 | J1: 2022 | K1: 2023 | L1: 2024 | M1: 2025 | O1: min | P1: max
A2: =1_原始数据!A2 -> 安全 S | B2: =1_原始数据!B2 -> 地方一般公共预算收入 | C2: =1_原始数据!C2 -> + | E2: =0.01+0.99*IF($C2="+",(1_原始数据!E2-$P2)/($Q2-$P2),($Q2-1_原始数据!E2)/($Q2-$P2)) -> 0.01 | F2: =0.01+0.99*IF($C2="+",(1_原始数据!F2-$P2)/($Q2-$P2),($Q2-1_原始数据!F2)/($Q2-$P2)) -> 0.19245692 | G2: =0.01+0.99*IF($C2="+",(1_原始数据!G2-$P2)/($Q2-$P2),($Q2-1_原始数据!G2)/($Q2-$P2)) -> 0.46467482 | H2: =0.01+0.99*IF($C2="+",(1_原始数据!H2-$P2)/($Q2-$P2),($Q2-1_原始数据!H2)/($Q2-$P2)) -> 0.41355753 | I2: =0.01+0.99*IF($C2="+",(1_原始数据!I2-$P2)/($Q2-$P2),($Q2-1_原始数据!I2)/($Q2-$P2)) -> 0.40744302 | J2: =0.01+0.99*IF($C2="+",(1_原始数据!J2-$P2)/($Q2-$P2),($Q2-1_原始数据!J2)/($Q2-$P2)) -> 0.37460812 | K2: =0.01+0.99*IF($C2="+",(1_原始数据!K2-$P2)/($Q2-$P2),($Q2-1_原始数据!K2)/($Q2-$P2)) -> 0.15454697 | L2: =0.01+0.99*IF($C2="+",(1_原始数据!L2-$P2)/($Q2-$P2),($Q2-1_原始数据!L2)/($Q2-$P2)) -> 0.50307393 | ... N2: =0.01+0.99*IF($C2="+",(1_原始数据!N2-$P2)/($Q2-$P2),($Q2-1_原始数据!N2)/($Q2-$P2)) -> 1 | P2: =MIN(1_原始数据!E2:N2) -> 155.99 | Q2: =MAX(1_原始数据!E2:N2) -> 317.9
A3: =1_原始数据!A3 -> 安全 S | B3: =1_原始数据!B3 -> 城乡居民人均可支配收入比 | C3: =1_原始数据!C3 -> - | E3: =0.01+0.99*IF($C3="+",(1_原始数据!E3-$P3)/($Q3-$P3),($Q3-1_原始数据!E3)/($Q3-$P3)) -> 0.01 | F3: =0.01+0.99*IF($C3="+",(1_原始数据!F3-$P3)/($Q3-$P3),($Q3-1_原始数据!F3)/($Q3-$P3)) -> 0.17726712 | G3: =0.01+0.99*IF($C3="+",(1_原始数据!G3-$P3)/($Q3-$P3),($Q3-1_原始数据!G3)/($Q3-$P3)) -> 0.21034772 | H3: =0.01+0.99*IF($C3="+",(1_原始数据!H3-$P3)/($Q3-$P3),($Q3-1_原始数据!H3)/($Q3-$P3)) -> 0.33024583 | I3: =0.01+0.99*IF($C3="+",(1_原始数据!I3-$P3)/($Q3-$P3),($Q3-1_原始数据!I3)/($Q3-$P3)) -> 0.46185719 | J3: =0.01+0.99*IF($C3="+",(1_原始数据!J3-$P3)/($Q3-$P3),($Q3-1_原始数据!J3)/($Q3-$P3)) -> 0.60112461 | K3: =0.01+0.99*IF($C3="+",(1_原始数据!K3-$P3)/($Q3-$P3),($Q3-1_原始数据!K3)/($Q3-$P3)) -> 0.73134539 | L3: =0.01+0.99*IF($C3="+",(1_原始数据!L3-$P3)/($Q3-$P3),($Q3-1_原始数据!L3)/($Q3-$P3)) -> 0.8690804 | ... N3: =0.01+0.99*IF($C3="+",(1_原始数据!N3-$P3)/($Q3-$P3),($Q3-1_原始数据!N3)/($Q3-$P3)) -> 1 | P3: =MIN(1_原始数据!E3:N3) -> 2.5359731 | Q3: =MAX(1_原始数据!E3:N3) -> 3.0571806
A4: =1_原始数据!A4 -> 安全 S | B4: =1_原始数据!B4 -> 居民医保人均财政补助标准 | C4: =1_原始数据!C4 -> + | E4: =0.01+0.99*IF($C4="+",(1_原始数据!E4-$P4)/($Q4-$P4),($Q4-1_原始数据!E4)/($Q4-$P4)) -> 0.01 | F4: =0.01+0.99*IF($C4="+",(1_原始数据!F4-$P4)/($Q4-$P4),($Q4-1_原始数据!F4)/($Q4-$P4)) -> 0.10428571 | G4: =0.01+0.99*IF($C4="+",(1_原始数据!G4-$P4)/($Q4-$P4),($Q4-1_原始数据!G4)/($Q4-$P4)) -> 0.30857143 | H4: =0.01+0.99*IF($C4="+",(1_原始数据!H4-$P4)/($Q4-$P4),($Q4-1_原始数据!H4)/($Q4-$P4)) -> 0.30857143 | I4: =0.01+0.99*IF($C4="+",(1_原始数据!I4-$P4)/($Q4-$P4),($Q4-1_原始数据!I4)/($Q4-$P4)) -> 0.41857143 | J4: =0.01+0.99*IF($C4="+",(1_原始数据!J4-$P4)/($Q4-$P4),($Q4-1_原始数据!J4)/($Q4-$P4)) -> 0.51285714 | K4: =0.01+0.99*IF($C4="+",(1_原始数据!K4-$P4)/($Q4-$P4),($Q4-1_原始数据!K4)/($Q4-$P4)) -> 0.62285714 | L4: =0.01+0.99*IF($C4="+",(1_原始数据!L4-$P4)/($Q4-$P4),($Q4-1_原始数据!L4)/($Q4-$P4)) -> 0.81142857 | ... N4: =0.01+0.99*IF($C4="+",(1_原始数据!N4-$P4)/($Q4-$P4),($Q4-1_原始数据!N4)/($Q4-$P4)) -> 1 | P4: =MIN(1_原始数据!E4:N4) -> 420 | Q4: =MAX(1_原始数据!E4:N4) -> 735
A5: =1_原始数据!A5 -> 安全 S | B5: =1_原始数据!B5 -> 基本养老保险参保率 | C5: =1_原始数据!C5 -> + | E5: =0.01+0.99*IF($C5="+",(1_原始数据!E5-$P5)/($Q5-$P5),($Q5-1_原始数据!E5)/($Q5-$P5)) -> 0.01 | F5: =0.01+0.99*IF($C5="+",(1_原始数据!F5-$P5)/($Q5-$P5),($Q5-1_原始数据!F5)/($Q5-$P5)) -> 0.352 | G5: =0.01+0.99*IF($C5="+",(1_原始数据!G5-$P5)/($Q5-$P5),($Q5-1_原始数据!G5)/($Q5-$P5)) -> 0.5185 | H5: =0.01+0.99*IF($C5="+",(1_原始数据!H5-$P5)/($Q5-$P5),($Q5-1_原始数据!H5)/($Q5-$P5)) -> 0.649 | I5: =0.01+0.99*IF($C5="+",(1_原始数据!I5-$P5)/($Q5-$P5),($Q5-1_原始数据!I5)/($Q5-$P5)) -> 0.784 | J5: =0.01+0.99*IF($C5="+",(1_原始数据!J5-$P5)/($Q5-$P5),($Q5-1_原始数据!J5)/($Q5-$P5)) -> 0.883 | K5: =0.01+0.99*IF($C5="+",(1_原始数据!K5-$P5)/($Q5-$P5),($Q5-1_原始数据!K5)/($Q5-$P5)) -> 0.91 | L5: =0.01+0.99*IF($C5="+",(1_原始数据!L5-$P5)/($Q5-$P5),($Q5-1_原始数据!L5)/($Q5-$P5)) -> 0.937 | ... N5: =0.01+0.99*IF($C5="+",(1_原始数据!N5-$P5)/($Q5-$P5),($Q5-1_原始数据!N5)/($Q5-$P5)) -> 1 | P5: =MIN(1_原始数据!E5:N5) -> 0.855 | Q5: =MAX(1_原始数据!E5:N5) -> 0.965
A6: =1_原始数据!A6 -> 发展 D | B6: =1_原始数据!B6 -> 人均GDP相对全国水平 | C6: =1_原始数据!C6 -> + | E6: =0.01+0.99*IF($C6="+",(1_原始数据!E6-$P6)/($Q6-$P6),($Q6-1_原始数据!E6)/($Q6-$P6)) -> 0.01 | F6: =0.01+0.99*IF($C6="+",(1_原始数据!F6-$P6)/($Q6-$P6),($Q6-1_原始数据!F6)/($Q6-$P6)) -> 0.038736453 | G6: =0.01+0.99*IF($C6="+",(1_原始数据!G6-$P6)/($Q6-$P6),($Q6-1_原始数据!G6)/($Q6-$P6)) -> 0.058658125 | H6: =0.01+0.99*IF($C6="+",(1_原始数据!H6-$P6)/($Q6-$P6),($Q6-1_原始数据!H6)/($Q6-$P6)) -> 0.27420501 | I6: =0.01+0.99*IF($C6="+",(1_原始数据!I6-$P6)/($Q6-$P6),($Q6-1_原始数据!I6)/($Q6-$P6)) -> 0.46148411 | J6: =0.01+0.99*IF($C6="+",(1_原始数据!J6-$P6)/($Q6-$P6),($Q6-1_原始数据!J6)/($Q6-$P6)) -> 0.1893345 | K6: =0.01+0.99*IF($C6="+",(1_原始数据!K6-$P6)/($Q6-$P6),($Q6-1_原始数据!K6)/($Q6-$P6)) -> 0.19657203 | L6: =0.01+0.99*IF($C6="+",(1_原始数据!L6-$P6)/($Q6-$P6),($Q6-1_原始数据!L6)/($Q6-$P6)) -> 0.49566278 | ... N6: =0.01+0.99*IF($C6="+",(1_原始数据!N6-$P6)/($Q6-$P6),($Q6-1_原始数据!N6)/($Q6-$P6)) -> 1 | P6: =MIN(1_原始数据!E6:N6) -> 0.65418441 | Q6: =MAX(1_原始数据!E6:N6) -> 0.8177
A7: =1_原始数据!A7 -> 发展 D | B7: =1_原始数据!B7 -> 第三产业增加值比重 | C7: =1_原始数据!C7 -> + | E7: =0.01+0.99*IF($C7="+",(1_原始数据!E7-$P7)/($Q7-$P7),($Q7-1_原始数据!E7)/($Q7-$P7)) -> 1 | F7: =0.01+0.99*IF($C7="+",(1_原始数据!F7-$P7)/($Q7-$P7),($Q7-1_原始数据!F7)/($Q7-$P7)) -> 0.86105263 | G7: =0.01+0.99*IF($C7="+",(1_原始数据!G7-$P7)/($Q7-$P7),($Q7-1_原始数据!G7)/($Q7-$P7)) -> 0.46157895 | H7: =0.01+0.99*IF($C7="+",(1_原始数据!H7-$P7)/($Q7-$P7),($Q7-1_原始数据!H7)/($Q7-$P7)) -> 0.54842105 | I7: =0.01+0.99*IF($C7="+",(1_原始数据!I7-$P7)/($Q7-$P7),($Q7-1_原始数据!I7)/($Q7-$P7)) -> 0.63526316 | J7: =0.01+0.99*IF($C7="+",(1_原始数据!J7-$P7)/($Q7-$P7),($Q7-1_原始数据!J7)/($Q7-$P7)) -> 0.86105263 | K7: =0.01+0.99*IF($C7="+",(1_原始数据!K7-$P7)/($Q7-$P7),($Q7-1_原始数据!K7)/($Q7-$P7)) -> 0.82631579 | L7: =0.01+0.99*IF($C7="+",(1_原始数据!L7-$P7)/($Q7-$P7),($Q7-1_原始数据!L7)/($Q7-$P7)) -> 0.87842105 | ... N7: =0.01+0.99*IF($C7="+",(1_原始数据!N7-$P7)/($Q7-$P7),($Q7-1_原始数据!N7)/($Q7-$P7)) -> 0.01 | P7: =MIN(1_原始数据!E7:N7) -> 52.5 | Q7: =MAX(1_原始数据!E7:N7) -> 58.2
A8: =1_原始数据!A8 -> 发展 D | B8: =1_原始数据!B8 -> 地区生产总值 | C8: =1_原始数据!C8 -> + | E8: =0.01+0.99*IF($C8="+",(1_原始数据!E8-$P8)/($Q8-$P8),($Q8-1_原始数据!E8)/($Q8-$P8)) -> 0.01 | F8: =0.01+0.99*IF($C8="+",(1_原始数据!F8-$P8)/($Q8-$P8),($Q8-1_原始数据!F8)/($Q8-$P8)) -> 0.10907501 | G8: =0.01+0.99*IF($C8="+",(1_原始数据!G8-$P8)/($Q8-$P8),($Q8-1_原始数据!G8)/($Q8-$P8)) -> 0.21836027 | H8: =0.01+0.99*IF($C8="+",(1_原始数据!H8-$P8)/($Q8-$P8),($Q8-1_原始数据!H8)/($Q8-$P8)) -> 0.30840688 | I8: =0.01+0.99*IF($C8="+",(1_原始数据!I8-$P8)/($Q8-$P8),($Q8-1_原始数据!I8)/($Q8-$P8)) -> 0.41968346 | J8: =0.01+0.99*IF($C8="+",(1_原始数据!J8-$P8)/($Q8-$P8),($Q8-1_原始数据!J8)/($Q8-$P8)) -> 0.52142976 | K8: =0.01+0.99*IF($C8="+",(1_原始数据!K8-$P8)/($Q8-$P8),($Q8-1_原始数据!K8)/($Q8-$P8)) -> 0.57016588 | L8: =0.01+0.99*IF($C8="+",(1_原始数据!L8-$P8)/($Q8-$P8),($Q8-1_原始数据!L8)/($Q8-$P8)) -> 0.73069664 | ... N8: =0.01+0.99*IF($C8="+",(1_原始数据!N8-$P8)/($Q8-$P8),($Q8-1_原始数据!N8)/($Q8-$P8)) -> 1 | P8: =MIN(1_原始数据!E8:N8) -> 1197.38 | Q8: =MAX(1_原始数据!E8:N8) -> 3031.89
A9: =1_原始数据!A9 -> 发展 D | B9: =1_原始数据!B9 -> 农村居民人均可支配收入 | C9: =1_原始数据!C9 -> + | E9: =0.01+0.99*IF($C9="+",(1_原始数据!E9-$P9)/($Q9-$P9),($Q9-1_原始数据!E9)/($Q9-$P9)) -> 0.01 | F9: =0.01+0.99*IF($C9="+",(1_原始数据!F9-$P9)/($Q9-$P9),($Q9-1_原始数据!F9)/($Q9-$P9)) -> 0.096844571 | G9: =0.01+0.99*IF($C9="+",(1_原始数据!G9-$P9)/($Q9-$P9),($Q9-1_原始数据!G9)/($Q9-$P9)) -> 0.17553868 | H9: =0.01+0.99*IF($C9="+",(1_原始数据!H9-$P9)/($Q9-$P9),($Q9-1_原始数据!H9)/($Q9-$P9)) -> 0.28100284 | I9: =0.01+0.99*IF($C9="+",(1_原始数据!I9-$P9)/($Q9-$P9),($Q9-1_原始数据!I9)/($Q9-$P9)) -> 0.39672534 | J9: =0.01+0.99*IF($C9="+",(1_原始数据!J9-$P9)/($Q9-$P9),($Q9-1_原始数据!J9)/($Q9-$P9)) -> 0.56092903 | K9: =0.01+0.99*IF($C9="+",(1_原始数据!K9-$P9)/($Q9-$P9),($Q9-1_原始数据!K9)/($Q9-$P9)) -> 0.65044358 | L9: =0.01+0.99*IF($C9="+",(1_原始数据!L9-$P9)/($Q9-$P9),($Q9-1_原始数据!L9)/($Q9-$P9)) -> 0.77094393 | ... N9: =0.01+0.99*IF($C9="+",(1_原始数据!N9-$P9)/($Q9-$P9),($Q9-1_原始数据!N9)/($Q9-$P9)) -> 1 | P9: =MIN(1_原始数据!E9:N9) -> 9094 | Q9: =MAX(1_原始数据!E9:N9) -> 23184
A10: =1_原始数据!A10 -> 发展 D | B10: =1_原始数据!B10 -> 货物进出口总额 | C10: =1_原始数据!C10 -> + | E10: =0.01+0.99*IF($C10="+",(1_原始数据!E10-$P10)/($Q10-$P10),($Q10-1_原始数据!E10)/($Q10-$P10)) -> 0.29500427 | F10: =0.01+0.99*IF($C10="+",(1_原始数据!F10-$P10)/($Q10-$P10),($Q10-1_原始数据!F10)/($Q10-$P10)) -> 0.36564475 | G10: =0.01+0.99*IF($C10="+",(1_原始数据!G10-$P10)/($Q10-$P10),($Q10-1_原始数据!G10)/($Q10-$P10)) -> 0.2560205 | H10: =0.01+0.99*IF($C10="+",(1_原始数据!H10-$P10)/($Q10-$P10),($Q10-1_原始数据!H10)/($Q10-$P10)) -> 0.26766866 | I10: =0.01+0.99*IF($C10="+",(1_原始数据!I10-$P10)/($Q10-$P10),($Q10-1_原始数据!I10)/($Q10-$P10)) -> 0.01 | J10: =0.01+0.99*IF($C10="+",(1_原始数据!J10-$P10)/($Q10-$P10),($Q10-1_原始数据!J10)/($Q10-$P10)) -> 0.18688301 | K10: =0.01+0.99*IF($C10="+",(1_原始数据!K10-$P10)/($Q10-$P10),($Q10-1_原始数据!K10)/($Q10-$P10)) -> 0.24183604 | L10: =0.01+0.99*IF($C10="+",(1_原始数据!L10-$P10)/($Q10-$P10),($Q10-1_原始数据!L10)/($Q10-$P10)) -> 0.84087105 | ... N10: =0.01+0.99*IF($C10="+",(1_原始数据!N10-$P10)/($Q10-$P10),($Q10-1_原始数据!N10)/($Q10-$P10)) -> 0.60612297 | P10: =MIN(1_原始数据!E10:N10) -> 21.33 | Q10: =MAX(1_原始数据!E10:N10) -> 126.72
A11: =1_原始数据!A11 -> 发展 D | B11: =1_原始数据!B11 -> 接待游客总人数 | C11: =1_原始数据!C11 -> + | E11: =0.01+0.99*IF($C11="+",(1_原始数据!E11-$P11)/($Q11-$P11),($Q11-1_原始数据!E11)/($Q11-$P11)) -> 0.01 | F11: =0.01+0.99*IF($C11="+",(1_原始数据!F11-$P11)/($Q11-$P11),($Q11-1_原始数据!F11)/($Q11-$P11)) -> 0.061085376 | G11: =0.01+0.99*IF($C11="+",(1_原始数据!G11-$P11)/($Q11-$P11),($Q11-1_原始数据!G11)/($Q11-$P11)) -> 0.22908091 | H11: =0.01+0.99*IF($C11="+",(1_原始数据!H11-$P11)/($Q11-$P11),($Q11-1_原始数据!H11)/($Q11-$P11)) -> 0.36297375 | I11: =0.01+0.99*IF($C11="+",(1_原始数据!I11-$P11)/($Q11-$P11),($Q11-1_原始数据!I11)/($Q11-$P11)) -> 0.25744017 | J11: =0.01+0.99*IF($C11="+",(1_原始数据!J11-$P11)/($Q11-$P11),($Q11-1_原始数据!J11)/($Q11-$P11)) -> 0.39237557 | K11: =0.01+0.99*IF($C11="+",(1_原始数据!K11-$P11)/($Q11-$P11),($Q11-1_原始数据!K11)/($Q11-$P11)) -> 0.15292418 | L11: =0.01+0.99*IF($C11="+",(1_原始数据!L11-$P11)/($Q11-$P11),($Q11-1_原始数据!L11)/($Q11-$P11)) -> 0.67612217 | ... N11: =0.01+0.99*IF($C11="+",(1_原始数据!N11-$P11)/($Q11-$P11),($Q11-1_原始数据!N11)/($Q11-$P11)) -> 1 | P11: =MIN(1_原始数据!E11:N11) -> 2315.94 | Q11: =MAX(1_原始数据!E11:N11) -> 7073.37
A12: =1_原始数据!A12 -> 发展 D | B12: =1_原始数据!B12 -> 清洁能源发电量 | C12: =1_原始数据!C12 -> + | E12: =0.01+0.99*IF($C12="+",(1_原始数据!E12-$P12)/($Q12-$P12),($Q12-1_原始数据!E12)/($Q12-$P12)) -> 0.01 | F12: =0.01+0.99*IF($C12="+",(1_原始数据!F12-$P12)/($Q12-$P12),($Q12-1_原始数据!F12)/($Q12-$P12)) -> 0.02135077 | G12: =0.01+0.99*IF($C12="+",(1_原始数据!G12-$P12)/($Q12-$P12),($Q12-1_原始数据!G12)/($Q12-$P12)) -> 0.11960588 | H12: =0.01+0.99*IF($C12="+",(1_原始数据!H12-$P12)/($Q12-$P12),($Q12-1_原始数据!H12)/($Q12-$P12)) -> 0.14762809 | I12: =0.01+0.99*IF($C12="+",(1_原始数据!I12-$P12)/($Q12-$P12),($Q12-1_原始数据!I12)/($Q12-$P12)) -> 0.15472232 | J12: =0.01+0.99*IF($C12="+",(1_原始数据!J12-$P12)/($Q12-$P12),($Q12-1_原始数据!J12)/($Q12-$P12)) -> 0.27621104 | K12: =0.01+0.99*IF($C12="+",(1_原始数据!K12-$P12)/($Q12-$P12),($Q12-1_原始数据!K12)/($Q12-$P12)) -> 0.54490505 | L12: =0.01+0.99*IF($C12="+",(1_原始数据!L12-$P12)/($Q12-$P12),($Q12-1_原始数据!L12)/($Q12-$P12)) -> 0.74354353 | ... N12: =0.01+0.99*IF($C12="+",(1_原始数据!N12-$P12)/($Q12-$P12),($Q12-1_原始数据!N12)/($Q12-$P12)) -> 1 | P12: =MIN(1_原始数据!E12:N12) -> 50.78 | Q12: =MAX(1_原始数据!E12:N12) -> 162.42
A13: =1_原始数据!A13 -> 生态 E | B13: =1_原始数据!B13 -> 单位GDP能耗指数 | C13: =1_原始数据!C13 -> - | E13: =0.01+0.99*IF($C13="+",(1_原始数据!E13-$P13)/($Q13-$P13),($Q13-1_原始数据!E13)/($Q13-$P13)) -> 0.01 | F13: =0.01+0.99*IF($C13="+",(1_原始数据!F13-$P13)/($Q13-$P13),($Q13-1_原始数据!F13)/($Q13-$P13)) -> 0.15649062 | G13: =0.01+0.99*IF($C13="+",(1_原始数据!G13-$P13)/($Q13-$P13),($Q13-1_原始数据!G13)/($Q13-$P13)) -> 0.28180707 | H13: =0.01+0.99*IF($C13="+",(1_原始数据!H13-$P13)/($Q13-$P13),($Q13-1_原始数据!H13)/($Q13-$P13)) -> 0.39113488 | I13: =0.01+0.99*IF($C13="+",(1_原始数据!I13-$P13)/($Q13-$P13),($Q13-1_原始数据!I13)/($Q13-$P13)) -> 0.44817547 | J13: =0.01+0.99*IF($C13="+",(1_原始数据!J13-$P13)/($Q13-$P13),($Q13-1_原始数据!J13)/($Q13-$P13)) -> 0.56052815 | K13: =0.01+0.99*IF($C13="+",(1_原始数据!K13-$P13)/($Q13-$P13),($Q13-1_原始数据!K13)/($Q13-$P13)) -> 0.68411611 | L13: =0.01+0.99*IF($C13="+",(1_原始数据!L13-$P13)/($Q13-$P13),($Q13-1_原始数据!L13)/($Q13-$P13)) -> 0.78566565 | ... N13: =0.01+0.99*IF($C13="+",(1_原始数据!N13-$P13)/($Q13-$P13),($Q13-1_原始数据!N13)/($Q13-$P13)) -> 1 | P13: =MIN(1_原始数据!E13:N13) -> 73.89 | Q13: =MAX(1_原始数据!E13:N13) -> 96.8
... A16: =1_原始数据!A16 -> 生态 E | B16: =1_原始数据!B16 -> 草原综合植被盖度 | C16: =1_原始数据!C16 -> + | E16: =0.01+0.99*IF($C16="+",(1_原始数据!E16-$P16)/($Q16-$P16),($Q16-1_原始数据!E16)/($Q16-$P16)) -> 0.01 | F16: =0.01+0.99*IF($C16="+",(1_原始数据!F16-$P16)/($Q16-$P16),($Q16-1_原始数据!F16)/($Q16-$P16)) -> 0.33599653 | G16: =0.01+0.99*IF($C16="+",(1_原始数据!G16-$P16)/($Q16-$P16),($Q16-1_原始数据!G16)/($Q16-$P16)) -> 0.62767764 | H16: =0.01+0.99*IF($C16="+",(1_原始数据!H16-$P16)/($Q16-$P16),($Q16-1_原始数据!H16)/($Q16-$P16)) -> 0.76493934 | I16: =0.01+0.99*IF($C16="+",(1_原始数据!I16-$P16)/($Q16-$P16),($Q16-1_原始数据!I16)/($Q16-$P16)) -> 0.79925477 | J16: =0.01+0.99*IF($C16="+",(1_原始数据!J16-$P16)/($Q16-$P16),($Q16-1_原始数据!J16)/($Q16-$P16)) -> 0.84043328 | K16: =0.01+0.99*IF($C16="+",(1_原始数据!K16-$P16)/($Q16-$P16),($Q16-1_原始数据!K16)/($Q16-$P16)) -> 0.90220104 | L16: =0.01+0.99*IF($C16="+",(1_原始数据!L16-$P16)/($Q16-$P16),($Q16-1_原始数据!L16)/($Q16-$P16)) -> 0.95024263 | ... N16: =0.01+0.99*IF($C16="+",(1_原始数据!N16-$P16)/($Q16-$P16),($Q16-1_原始数据!N16)/($Q16-$P16)) -> 1 | P16: =MIN(1_原始数据!E16:N16) -> 42.3 | Q16: =MAX(1_原始数据!E16:N16) -> 48.07

Sheet 3_权重
A1: 指标 | B1: 子系统 | C1: ΣZ | D1: 熵值 e | E1: 差异 d=1-e | F1: 熵值权重 | G1: 标准差σ | H1: r1 | I1: r2 | J1: r3 | K1: r4 | L1: r5 | M1: r6 | N1: r7 | O1: r8 | P1: r9 | Q1: r10 | R1: r11 | S1: r12 | T1: r13 | U1: r14 | V1: r15 | W1: 冲突性Σ(1-r) | X1: 信息量 σ·Σ | Y1: CRITIC权重 | Z1: 组合权重 | AA1: 子系统内权重
A2: =2_标准化!B2 -> 地方一般公共预算收入 | B2: =2_标准化!A2 -> 安全 S | C2: =SUM(2_标准化!E2:N2) -> 4.2714397 | D2: =-1/LN(10)*SUMPRODUCT((2_标准化!E2:N2/$C2),LN(2_标准化!E2:N2/$C2)) -> 0.9017717 | E2: =1-D2 -> 0.098228302 | F2: =E2/SUM($E$2:$E$16) -> 0.06251362 | G2: =STDEV(2_标准化!E2:N2) -> 0.28809729 | H2: =CORREL(2_标准化!$E2:$N2,2_标准化!$E2:$N2) -> 1 | I2: =CORREL(2_标准化!$E2:$N2,2_标准化!$E3:$N3) -> 0.73180545 | J2: =CORREL(2_标准化!$E2:$N2,2_标准化!$E4:$N4) -> 0.81038941 | K2: =CORREL(2_标准化!$E2:$N2,2_标准化!$E5:$N5) -> 0.68652644 | L2: =CORREL(2_标准化!$E2:$N2,2_标准化!$E6:$N6) -> 0.89990312 | M2: =CORREL(2_标准化!$E2:$N2,2_标准化!$E7:$N7) -> -0.89427199 | N2: =CORREL(2_标准化!$E2:$N2,2_标准化!$E8:$N8) -> 0.82078708 | O2: =CORREL(2_标准化!$E2:$N2,2_标准化!$E9:$N9) -> 0.76305891 | P2: =CORREL(2_标准化!$E2:$N2,2_标准化!$E10:$N10) -> 0.56606389 | Q2: =CORREL(2_标准化!$E2:$N2,2_标准化!$E11:$N11) -> 0.93704304 | R2: =CORREL(2_标准化!$E2:$N2,2_标准化!$E12:$N12) -> 0.76619613 | S2: =CORREL(2_标准化!$E2:$N2,2_标准化!$E13:$N13) -> 0.7893824 | T2: =CORREL(2_标准化!$E2:$N2,2_标准化!$E14:$N14) -> 0.76832058 | U2: =CORREL(2_标准化!$E2:$N2,2_标准化!$E15:$N15) -> 0.70676432 | V2: =CORREL(2_标准化!$E2:$N2,2_标准化!$E16:$N16) -> 0.71183167 | W2: =15-SUM(H2:V2) -> 4.9361995 | X2: =G2*W2 -> 1.4221057 | Y2: =X2/SUM($X$2:$X$16) -> 0.056482441 | Z2: =(F2*Y2)/SUMPRODUCT($F$2:$F$16,$Y$2:$Y$16) -> 0.057959966 | AA2: =Z2/SUMIF($B$2:$B$16,B2,$Z$2:$Z$16) -> 0.32746738
A3: =2_标准化!B3 -> 城乡居民人均可支配收入比 | B3: =2_标准化!A3 -> 安全 S | C3: =SUM(2_标准化!E3:N3) -> 5.3276451 | D3: =-1/LN(10)*SUMPRODUCT((2_标准化!E3:N3/$C3),LN(2_标准化!E3:N3/$C3)) -> 0.89948252 | E3: =1-D3 -> 0.10051748 | F3: =E3/SUM($E$2:$E$16) -> 0.063970482 | G3: =STDEV(2_标准化!E3:N3) -> 0.34770408 | H3: =CORREL(2_标准化!$E3:$N3,2_标准化!$E2:$N2) -> 0.73180545 | I3: =CORREL(2_标准化!$E3:$N3,2_标准化!$E3:$N3) -> 1 | J3: =CORREL(2_标准化!$E3:$N3,2_标准化!$E4:$N4) -> 0.98618019 | K3: =CORREL(2_标准化!$E3:$N3,2_标准化!$E5:$N5) -> 0.9233678 | L3: =CORREL(2_标准化!$E3:$N3,2_标准化!$E6:$N6) -> 0.8415926 | M3: =CORREL(2_标准化!$E3:$N3,2_标准化!$E7:$N7) -> -0.49769186 | N3: =CORREL(2_标准化!$E3:$N3,2_标准化!$E8:$N8) -> 0.98723472 | O3: =CORREL(2_标准化!$E3:$N3,2_标准化!$E9:$N9) -> 0.99553219 | P3: =CORREL(2_标准化!$E3:$N3,2_标准化!$E10:$N10) -> 0.62590655 | Q3: =CORREL(2_标准化!$E3:$N3,2_标准化!$E11:$N11) -> 0.85747852 | R3: =CORREL(2_标准化!$E3:$N3,2_标准化!$E12:$N12) -> 0.9532801 | S3: =CORREL(2_标准化!$E3:$N3,2_标准化!$E13:$N13) -> 0.99240497 | T3: =CORREL(2_标准化!$E3:$N3,2_标准化!$E14:$N14) -> 0.89607496 | U3: =CORREL(2_标准化!$E3:$N3,2_标准化!$E15:$N15) -> 0.7284975 | V3: =CORREL(2_标准化!$E3:$N3,2_标准化!$E16:$N16) -> 0.88394972 | W3: =15-SUM(H3:V3) -> 3.0943866 | X3: =G3*W3 -> 1.0759308 | Y3: =X3/SUM($X$2:$X$16) -> 0.042733252 | Z3: =(F3*Y3)/SUMPRODUCT($F$2:$F$16,$Y$2:$Y$16) -> 0.044873048 | AA3: =Z3/SUMIF($B$2:$B$16,B3,$Z$2:$Z$16) -> 0.25352775
A4: =2_标准化!B4 -> 居民医保人均财政补助标准 | B4: =2_标准化!A4 -> 安全 S | C4: =SUM(2_标准化!E4:N4) -> 5.0028571 | D4: =-1/LN(10)*SUMPRODUCT((2_标准化!E4:N4/$C4),LN(2_标准化!E4:N4/$C4)) -> 0.8961515 | E4: =1-D4 -> 0.1038485 | F4: =E4/SUM($E$2:$E$16) -> 0.066090379 | G4: =STDEV(2_标准化!E4:N4) -> 0.33390957 | H4: =CORREL(2_标准化!$E4:$N4,2_标准化!$E2:$N2) -> 0.81038941 | I4: =CORREL(2_标准化!$E4:$N4,2_标准化!$E3:$N3) -> 0.98618019 | J4: =CORREL(2_标准化!$E4:$N4,2_标准化!$E4:$N4) -> 1 | K4: =CORREL(2_标准化!$E4:$N4,2_标准化!$E5:$N5) -> 0.90460258 | L4: =CORREL(2_标准化!$E4:$N4,2_标准化!$E6:$N6) -> 0.87671775 | M4: =CORREL(2_标准化!$E4:$N4,2_标准化!$E7:$N7) -> -0.59919772 | N4: =CORREL(2_标准化!$E4:$N4,2_标准化!$E8:$N8) -> 0.9937632 | O4: =CORREL(2_标准化!$E4:$N4,2_标准化!$E9:$N9) -> 0.99023295 | P4: =CORREL(2_标准化!$E4:$N4,2_标准化!$E10:$N10) -> 0.65448955 | Q4: =CORREL(2_标准化!$E4:$N4,2_标准化!$E11:$N11) -> 0.90516552 | R4: =CORREL(2_标准化!$E4:$N4,2_标准化!$E12:$N12) -> 0.96815535 | S4: =CORREL(2_标准化!$E4:$N4,2_标准化!$E13:$N13) -> 0.99346356 | T4: =CORREL(2_标准化!$E4:$N4,2_标准化!$E14:$N14) -> 0.88874954 | U4: =CORREL(2_标准化!$E4:$N4,2_标准化!$E15:$N15) -> 0.75379476 | V4: =CORREL(2_标准化!$E4:$N4,2_标准化!$E16:$N16) -> 0.88227227 | W4: =15-SUM(H4:V4) -> 2.9912211 | X4: =G4*W4 -> 0.99879735 | Y4: =X4/SUM($X$2:$X$16) -> 0.039669704 | Z4: =(F4*Y4)/SUMPRODUCT($F$2:$F$16,$Y$2:$Y$16) -> 0.043036527 | AA4: =Z4/SUMIF($B$2:$B$16,B4,$Z$2:$Z$16) -> 0.24315161
A5: =2_标准化!B5 -> 基本养老保险参保率 | B5: =2_标准化!A5 -> 安全 S | C5: =SUM(2_标准化!E5:N5) -> 7.0264 | D5: =-1/LN(10)*SUMPRODUCT((2_标准化!E5:N5/$C5),LN(2_标准化!E5:N5/$C5)) -> 0.93939209 | E5: =1-D5 -> 0.060607908 | F5: =E5/SUM($E$2:$E$16) -> 0.038571569 | G5: =STDEV(2_标准化!E5:N5) -> 0.32378387 | H5: =CORREL(2_标准化!$E5:$N5,2_标准化!$E2:$N2) -> 0.68652644 | I5: =CORREL(2_标准化!$E5:$N5,2_标准化!$E3:$N3) -> 0.9233678 | J5: =CORREL(2_标准化!$E5:$N5,2_标准化!$E4:$N4) -> 0.90460258 | K5: =CORREL(2_标准化!$E5:$N5,2_标准化!$E5:$N5) -> 1 | L5: =CORREL(2_标准化!$E5:$N5,2_标准化!$E6:$N6) -> 0.72073311 | M5: =CORREL(2_标准化!$E5:$N5,2_标准化!$E7:$N7) -> -0.47979747 | N5: =CORREL(2_标准化!$E5:$N5,2_标准化!$E8:$N8) -> 0.90280844 | O5: =CORREL(2_标准化!$E5:$N5,2_标准化!$E9:$N9) -> 0.90525519 | P5: =CORREL(2_标准化!$E5:$N5,2_标准化!$E10:$N10) -> 0.3844508 | Q5: =CORREL(2_标准化!$E5:$N5,2_标准化!$E11:$N11) -> 0.74203349 | R5: =CORREL(2_标准化!$E5:$N5,2_标准化!$E12:$N12) -> 0.78725052 | S5: =CORREL(2_标准化!$E5:$N5,2_标准化!$E13:$N13) -> 0.93113769 | T5: =CORREL(2_标准化!$E5:$N5,2_标准化!$E14:$N14) -> 0.88913875 | U5: =CORREL(2_标准化!$E5:$N5,2_标准化!$E15:$N15) -> 0.89270082 | V5: =CORREL(2_标准化!$E5:$N5,2_标准化!$E16:$N16) -> 0.98712573 | W5: =15-SUM(H5:V5) -> 3.8226661 | X5: =G5*W5 -> 1.2377176 | Y5: =X5/SUM($X$2:$X$16) -> 0.049159014 | Z5: =(F5*Y5)/SUMPRODUCT($F$2:$F$16,$Y$2:$Y$16) -> 0.03112508 | AA5: =Z5/SUMIF($B$2:$B$16,B5,$Z$2:$Z$16) -> 0.17585326
A6: =2_标准化!B6 -> 人均GDP相对全国水平 | B6: =2_标准化!A6 -> 发展 D | C6: =SUM(2_标准化!E6:N6) -> 3.5315155 | D6: =-1/LN(10)*SUMPRODUCT((2_标准化!E6:N6/$C6),LN(2_标准化!E6:N6/$C6)) -> 0.81923605 | E6: =1-D6 -> 0.18076395 | F6: =E6/SUM($E$2:$E$16) -> 0.11504025 | G6: =STDEV(2_标准化!E6:N6) -> 0.33619337 | H6: =CORREL(2_标准化!$E6:$N6,2_标准化!$E2:$N2) -> 0.89990312 | I6: =CORREL(2_标准化!$E6:$N6,2_标准化!$E3:$N3) -> 0.8415926 | J6: =CORREL(2_标准化!$E6:$N6,2_标准化!$E4:$N4) -> 0.87671775 | K6: =CORREL(2_标准化!$E6:$N6,2_标准化!$E5:$N5) -> 0.72073311 | L6: =CORREL(2_标准化!$E6:$N6,2_标准化!$E6:$N6) -> 1 | M6: =CORREL(2_标准化!$E6:$N6,2_标准化!$E7:$N7) -> -0.76770624 | N6: =CORREL(2_标准化!$E6:$N6,2_标准化!$E8:$N8) -> 0.90297044 | O6: =CORREL(2_标准化!$E6:$N6,2_标准化!$E9:$N9) -> 0.86606836 | P6: =CORREL(2_标准化!$E6:$N6,2_标准化!$E10:$N10) -> 0.62260918 | Q6: =CORREL(2_标准化!$E6:$N6,2_标准化!$E11:$N11) -> 0.93368535 | R6: =CORREL(2_标准化!$E6:$N6,2_标准化!$E12:$N12) -> 0.86705741 | S6: =CORREL(2_标准化!$E6:$N6,2_标准化!$E13:$N13) -> 0.86630819 | T6: =CORREL(2_标准化!$E6:$N6,2_标准化!$E14:$N14) -> 0.81739623 | U6: =CORREL(2_标准化!$E6:$N6,2_标准化!$E15:$N15) -> 0.64939344 | V6: =CORREL(2_标准化!$E6:$N6,2_标准化!$E16:$N16) -> 0.70809003 | W6: =15-SUM(H6:V6) -> 4.195181 | X6: =G6*W6 -> 1.4103921 | Y6: =X6/SUM($X$2:$X$16) -> 0.056017205 | Z6: =(F6*Y6)/SUMPRODUCT($F$2:$F$16,$Y$2:$Y$16) -> 0.10578188 | AA6: =Z6/SUMIF($B$2:$B$16,B6,$Z$2:$Z$16) -> 0.15860183
A7: =2_标准化!B7 -> 第三产业增加值比重 | B7: =2_标准化!A7 -> 发展 D | C7: =SUM(2_标准化!E7:N7) -> 6.4047368 | D7: =-1/LN(10)*SUMPRODUCT((2_标准化!E7:N7/$C7),LN(2_标准化!E7:N7/$C7)) -> 0.93633288 | E7: =1-D7 -> 0.06366712 | F7: =E7/SUM($E$2:$E$16) -> 0.040518487 | G7: =STDEV(2_标准化!E7:N7) -> 0.30853604 | H7: =CORREL(2_标准化!$E7:$N7,2_标准化!$E2:$N2) -> -0.89427199 | I7: =CORREL(2_标准化!$E7:$N7,2_标准化!$E3:$N3) -> -0.49769186 | J7: =CORREL(2_标准化!$E7:$N7,2_标准化!$E4:$N4) -> -0.59919772 | K7: =CORREL(2_标准化!$E7:$N7,2_标准化!$E5:$N5) -> -0.47979747 | L7: =CORREL(2_标准化!$E7:$N7,2_标准化!$E6:$N6) -> -0.76770624 | M7: =CORREL(2_标准化!$E7:$N7,2_标准化!$E7:$N7) -> 1 | N7: =CORREL(2_标准化!$E7:$N7,2_标准化!$E8:$N8) -> -0.61250018 | O7: =CORREL(2_标准化!$E7:$N7,2_标准化!$E9:$N9) -> -0.54353808 | P7: =CORREL(2_标准化!$E7:$N7,2_标准化!$E10:$N10) -> -0.34473535 | Q7: =CORREL(2_标准化!$E7:$N7,2_标准化!$E11:$N11) -> -0.73203877 | R7: =CORREL(2_标准化!$E7:$N7,2_标准化!$E12:$N12) -> -0.57322055 | S7: =CORREL(2_标准化!$E7:$N7,2_标准化!$E13:$N13) -> -0.58744444 | T7: =CORREL(2_标准化!$E7:$N7,2_标准化!$E14:$N14) -> -0.59955193 | U7: =CORREL(2_标准化!$E7:$N7,2_标准化!$E15:$N15) -> -0.58058062 | V7: =CORREL(2_标准化!$E7:$N7,2_标准化!$E16:$N16) -> -0.53536401 | W7: =15-SUM(H7:V7) -> 22.347639 | X7: =G7*W7 -> 6.8950521 | Y7: =X7/SUM($X$2:$X$16) -> 0.27385403 | Z7: =(F7*Y7)/SUMPRODUCT($F$2:$F$16,$Y$2:$Y$16) -> 0.18214295 | AA7: =Z7/SUMIF($B$2:$B$16,B7,$Z$2:$Z$16) -> 0.2730922
A8: =2_标准化!B8 -> 地区生产总值 | B8: =2_标准化!A8 -> 发展 D | C8: =SUM(2_标准化!E8:N8) -> 4.7567792 | D8: =-1/LN(10)*SUMPRODUCT((2_标准化!E8:N8/$C8),LN(2_标准化!E8:N8/$C8)) -> 0.89263198 | E8: =1-D8 -> 0.10736802 | F8: =E8/SUM($E$2:$E$16) -> 0.068330245 | G8: =STDEV(2_标准化!E8:N8) -> 0.32561432 | H8: =CORREL(2_标准化!$E8:$N8,2_标准化!$E2:$N2) -> 0.82078708 | I8: =CORREL(2_标准化!$E8:$N8,2_标准化!$E3:$N3) -> 0.98723472 | J8: =CORREL(2_标准化!$E8:$N8,2_标准化!$E4:$N4) -> 0.9937632 | K8: =CORREL(2_标准化!$E8:$N8,2_标准化!$E5:$N5) -> 0.90280844 | L8: =CORREL(2_标准化!$E8:$N8,2_标准化!$E6:$N6) -> 0.90297044 | M8: =CORREL(2_标准化!$E8:$N8,2_标准化!$E7:$N7) -> -0.61250018 | N8: =CORREL(2_标准化!$E8:$N8,2_标准化!$E8:$N8) -> 1 | O8: =CORREL(2_标准化!$E8:$N8,2_标准化!$E9:$N9) -> 0.99516655 | P8: =CORREL(2_标准化!$E8:$N8,2_标准化!$E10:$N10) -> 0.63053777 | Q8: =CORREL(2_标准化!$E8:$N8,2_标准化!$E11:$N11) -> 0.91556 | R8: =CORREL(2_标准化!$E8:$N8,2_标准化!$E12:$N12) -> 0.9621761 | S8: =CORREL(2_标准化!$E8:$N8,2_标准化!$E13:$N13) -> 0.99395779 | T8: =CORREL(2_标准化!$E8:$N8,2_标准化!$E14:$N14) -> 0.91036421 | U8: =CORREL(2_标准化!$E8:$N8,2_标准化!$E15:$N15) -> 0.74564423 | V8: =CORREL(2_标准化!$E8:$N8,2_标准化!$E16:$N16) -> 0.87273265 | W8: =15-SUM(H8:V8) -> 2.978797 | X8: =G8*W8 -> 0.96993897 | Y8: =X8/SUM($X$2:$X$16) -> 0.038523523 | Z8: =(F8*Y8)/SUMPRODUCT($F$2:$F$16,$Y$2:$Y$16) -> 0.043209474 | AA8: =Z8/SUMIF($B$2:$B$16,B8,$Z$2:$Z$16) -> 0.064785216
A9: =2_标准化!B9 -> 农村居民人均可支配收入 | B9: =2_标准化!A9 -> 发展 D | C9: =SUM(2_标准化!E9:N9) -> 4.8295862 | D9: =-1/LN(10)*SUMPRODUCT((2_标准化!E9:N9/$C9),LN(2_标准化!E9:N9/$C9)) -> 0.88281097 | E9: =1-D9 -> 0.11718903 | F9: =E9/SUM($E$2:$E$16) -> 0.074580446 | G9: =STDEV(2_标准化!E9:N9) -> 0.34371799 | H9: =CORREL(2_标准化!$E9:$N9,2_标准化!$E2:$N2) -> 0.76305891 | I9: =CORREL(2_标准化!$E9:$N9,2_标准化!$E3:$N3) -> 0.99553219 | J9: =CORREL(2_标准化!$E9:$N9,2_标准化!$E4:$N4) -> 0.99023295 | K9: =CORREL(2_标准化!$E9:$N9,2_标准化!$E5:$N5) -> 0.90525519 | L9: =CORREL(2_标准化!$E9:$N9,2_标准化!$E6:$N6) -> 0.86606836 | M9: =CORREL(2_标准化!$E9:$N9,2_标准化!$E7:$N7) -> -0.54353808 | N9: =CORREL(2_标准化!$E9:$N9,2_标准化!$E8:$N8) -> 0.99516655 | O9: =CORREL(2_标准化!$E9:$N9,2_标准化!$E9:$N9) -> 1 | P9: =CORREL(2_标准化!$E9:$N9,2_标准化!$E10:$N10) -> 0.62458105 | Q9: =CORREL(2_标准化!$E9:$N9,2_标准化!$E11:$N11) -> 0.88176474 | R9: =CORREL(2_标准化!$E9:$N9,2_标准化!$E12:$N12) -> 0.96380046 | S9: =CORREL(2_标准化!$E9:$N9,2_标准化!$E13:$N13) -> 0.993656 | T9: =CORREL(2_标准化!$E9:$N9,2_标准化!$E14:$N14) -> 0.90135912 | U9: =CORREL(2_标准化!$E9:$N9,2_标准化!$E15:$N15) -> 0.72002675 | V9: =CORREL(2_标准化!$E9:$N9,2_标准化!$E16:$N16) -> 0.8662008 | W9: =15-SUM(H9:V9) -> 3.076835 | X9: =G9*W9 -> 1.0575636 | Y9: =X9/SUM($X$2:$X$16) -> 0.042003749 | Z9: =(F9*Y9)/SUMPRODUCT($F$2:$F$16,$Y$2:$Y$16) -> 0.051422483 | AA9: =Z9/SUMIF($B$2:$B$16,B9,$Z$2:$Z$16) -> 0.077099218
A10: =2_标准化!B10 -> 货物进出口总额 | B10: =2_标准化!A10 -> 发展 D | C10: =SUM(2_标准化!E10:N10) -> 4.0700512 | D10: =-1/LN(10)*SUMPRODUCT((2_标准化!E10:N10/$C10),LN(2_标准化!E10:N10/$C10)) -> 0.88507106 | E10: =1-D10 -> 0.11492894 | F10: =E10/SUM($E$2:$E$16) -> 0.073142099 | G10: =STDEV(2_标准化!E10:N10) -> 0.3107954 | H10: =CORREL(2_标准化!$E10:$N10,2_标准化!$E2:$N2) -> 0.56606389 | I10: =CORREL(2_标准化!$E10:$N10,2_标准化!$E3:$N3) -> 0.62590655 | J10: =CORREL(2_标准化!$E10:$N10,2_标准化!$E4:$N4) -> 0.65448955 | K10: =CORREL(2_标准化!$E10:$N10,2_标准化!$E5:$N5) -> 0.3844508 | L10: =CORREL(2_标准化!$E10:$N10,2_标准化!$E6:$N6) -> 0.62260918 | M10: =CORREL(2_标准化!$E10:$N10,2_标准化!$E7:$N7) -> -0.34473535 | N10: =CORREL(2_标准化!$E10:$N10,2_标准化!$E8:$N8) -> 0.63053777 | O10: =CORREL(2_标准化!$E10:$N10,2_标准化!$E9:$N9) -> 0.62458105 | P10: =CORREL(2_标准化!$E10:$N10,2_标准化!$E10:$N10) -> 1 | Q10: =CORREL(2_标准化!$E10:$N10,2_标准化!$E11:$N11) -> 0.73996648 | R10: =CORREL(2_标准化!$E10:$N10,2_标准化!$E12:$N12) -> 0.73884449 | S10: =CORREL(2_标准化!$E10:$N10,2_标准化!$E13:$N13) -> 0.60847215 | T10: =CORREL(2_标准化!$E10:$N10,2_标准化!$E14:$N14) -> 0.32465851 | U10: =CORREL(2_标准化!$E10:$N10,2_标准化!$E15:$N15) -> 0.22823882 | V10: =CORREL(2_标准化!$E10:$N10,2_标准化!$E16:$N16) -> 0.3705747 | W10: =15-SUM(H10:V10) -> 7.2253414 | X10: =G10*W10 -> 2.2456028 | Y10: =X10/SUM($X$2:$X$16) -> 0.089189665 | Z10: =(F10*Y10)/SUMPRODUCT($F$2:$F$16,$Y$2:$Y$16) -> 0.10708335 | AA10: =Z10/SUMIF($B$2:$B$16,B10,$Z$2:$Z$16) -> 0.16055317
A11: =2_标准化!B11 -> 接待游客总人数 | B11: =2_标准化!A11 -> 发展 D | C11: =SUM(2_标准化!E11:N11) -> 3.9996086 | D11: =-1/LN(10)*SUMPRODUCT((2_标准化!E11:N11/$C11),LN(2_标准化!E11:N11/$C11)) -> 0.85417122 | E11: =1-D11 -> 0.14582878 | F11: =E11/SUM($E$2:$E$16) -> 0.092807109 | G11: =STDEV(2_标准化!E11:N11) -> 0.33741211 | H11: =CORREL(2_标准化!$E11:$N11,2_标准化!$E2:$N2) -> 0.93704304 | I11: =CORREL(2_标准化!$E11:$N11,2_标准化!$E3:$N3) -> 0.85747852 | J11: =CORREL(2_标准化!$E11:$N11,2_标准化!$E4:$N4) -> 0.90516552 | K11: =CORREL(2_标准化!$E11:$N11,2_标准化!$E5:$N5) -> 0.74203349 | L11: =CORREL(2_标准化!$E11:$N11,2_标准化!$E6:$N6) -> 0.93368535 | M11: =CORREL(2_标准化!$E11:$N11,2_标准化!$E7:$N7) -> -0.73203877 | N11: =CORREL(2_标准化!$E11:$N11,2_标准化!$E8:$N8) -> 0.91556 | O11: =CORREL(2_标准化!$E11:$N11,2_标准化!$E9:$N9) -> 0.88176474 | P11: =CORREL(2_标准化!$E11:$N11,2_标准化!$E10:$N10) -> 0.73996648 | Q11: =CORREL(2_标准化!$E11:$N11,2_标准化!$E11:$N11) -> 1 | R11: =CORREL(2_标准化!$E11:$N11,2_标准化!$E12:$N12) -> 0.89199295 | S11: =CORREL(2_标准化!$E11:$N11,2_标准化!$E13:$N13) -> 0.88553319 | T11: =CORREL(2_标准化!$E11:$N11,2_标准化!$E14:$N14) -> 0.77294642 | U11: =CORREL(2_标准化!$E11:$N11,2_标准化!$E15:$N15) -> 0.6853345 | V11: =CORREL(2_标准化!$E11:$N11,2_标准化!$E16:$N16) -> 0.74082545 | W11: =15-SUM(H11:V11) -> 3.8427091 | X11: =G11*W11 -> 1.2965766 | Y11: =X11/SUM($X$2:$X$16) -> 0.051496743 | Z11: =(F11*Y11)/SUMPRODUCT($F$2:$F$16,$Y$2:$Y$16) -> 0.078451458 | AA11: =Z11/SUMIF($B$2:$B$16,B11,$Z$2:$Z$16) -> 0.11762454
A12: =2_标准化!B12 -> 清洁能源发电量 | B12: =2_标准化!A12 -> 发展 D | C12: =SUM(2_标准化!E12:N12) -> 3.8227866 | D12: =-1/LN(10)*SUMPRODUCT((2_标准化!E12:N12/$C12),LN(2_标准化!E12:N12/$C12)) -> 0.81352639 | E12: =1-D12 -> 0.18647361 | F12: =E12/SUM($E$2:$E$16) -> 0.11867395 | G12: =STDEV(2_标准化!E12:N12) -> 0.36102184 | H12: =CORREL(2_标准化!$E12:$N12,2_标准化!$E2:$N2) -> 0.76619613 | I12: =CORREL(2_标准化!$E12:$N12,2_标准化!$E3:$N3) -> 0.9532801 | J12: =CORREL(2_标准化!$E12:$N12,2_标准化!$E4:$N4) -> 0.96815535 | K12: =CORREL(2_标准化!$E12:$N12,2_标准化!$E5:$N5) -> 0.78725052 | L12: =CORREL(2_标准化!$E12:$N12,2_标准化!$E6:$N6) -> 0.86705741 | M12: =CORREL(2_标准化!$E12:$N12,2_标准化!$E7:$N7) -> -0.57322055 | N12: =CORREL(2_标准化!$E12:$N12,2_标准化!$E8:$N8) -> 0.9621761 | O12: =CORREL(2_标准化!$E12:$N12,2_标准化!$E9:$N9) -> 0.96380046 | P12: =CORREL(2_标准化!$E12:$N12,2_标准化!$E10:$N10) -> 0.73884449 | Q12: =CORREL(2_标准化!$E12:$N12,2_标准化!$E11:$N11) -> 0.89199295 | R12: =CORREL(2_标准化!$E12:$N12,2_标准化!$E12:$N12) -> 1 | S12: =CORREL(2_标准化!$E12:$N12,2_标准化!$E13:$N13) -> 0.95513213 | T12: =CORREL(2_标准化!$E12:$N12,2_标准化!$E14:$N14) -> 0.82521776 | U12: =CORREL(2_标准化!$E12:$N12,2_标准化!$E15:$N15) -> 0.59798062 | V12: =CORREL(2_标准化!$E12:$N12,2_标准化!$E16:$N16) -> 0.75641416 | W12: =15-SUM(H12:V12) -> 3.5397224 | X12: =G12*W12 -> 1.2779171 | Y12: =X12/SUM($X$2:$X$16) -> 0.050755634 | Z12: =(F12*Y12)/SUMPRODUCT($F$2:$F$16,$Y$2:$Y$16) -> 0.098873444 | AA12: =Z12/SUMIF($B$2:$B$16,B12,$Z$2:$Z$16) -> 0.14824382
A13: =2_标准化!B13 -> 单位GDP能耗指数 | B13: =2_标准化!A13 -> 生态 E | C13: =SUM(2_标准化!E13:N13) -> 5.2090223 | D13: =-1/LN(10)*SUMPRODUCT((2_标准化!E13:N13/$C13),LN(2_标准化!E13:N13/$C13)) -> 0.90822511 | E13: =1-D13 -> 0.091774891 | F13: =E13/SUM($E$2:$E$16) -> 0.058406596 | G13: =STDEV(2_标准化!E13:N13) -> 0.32283554 | H13: =CORREL(2_标准化!$E13:$N13,2_标准化!$E2:$N2) -> 0.7893824 | I13: =CORREL(2_标准化!$E13:$N13,2_标准化!$E3:$N3) -> 0.99240497 | J13: =CORREL(2_标准化!$E13:$N13,2_标准化!$E4:$N4) -> 0.99346356 | K13: =CORREL(2_标准化!$E13:$N13,2_标准化!$E5:$N5) -> 0.93113769 | L13: =CORREL(2_标准化!$E13:$N13,2_标准化!$E6:$N6) -> 0.86630819 | M13: =CORREL(2_标准化!$E13:$N13,2_标准化!$E7:$N7) -> -0.58744444 | N13: =CORREL(2_标准化!$E13:$N13,2_标准化!$E8:$N8) -> 0.99395779 | O13: =CORREL(2_标准化!$E13:$N13,2_标准化!$E9:$N9) -> 0.993656 | P13: =CORREL(2_标准化!$E13:$N13,2_标准化!$E10:$N10) -> 0.60847215 | Q13: =CORREL(2_标准化!$E13:$N13,2_标准化!$E11:$N11) -> 0.88553319 | R13: =CORREL(2_标准化!$E13:$N13,2_标准化!$E12:$N12) -> 0.95513213 | S13: =CORREL(2_标准化!$E13:$N13,2_标准化!$E13:$N13) -> 1 | T13: =CORREL(2_标准化!$E13:$N13,2_标准化!$E14:$N14) -> 0.9062421 | U13: =CORREL(2_标准化!$E13:$N13,2_标准化!$E15:$N15) -> 0.77758676 | V13: =CORREL(2_标准化!$E13:$N13,2_标准化!$E16:$N16) -> 0.90718856 | W13: =15-SUM(H13:V13) -> 2.9869789 | X13: =G13*W13 -> 0.96430295 | Y13: =X13/SUM($X$2:$X$16) -> 0.038299674 | Z13: =(F13*Y13)/SUMPRODUCT($F$2:$F$16,$Y$2:$Y$16) -> 0.036719519 | AA13: =Z13/SUMIF($B$2:$B$16,B13,$Z$2:$Z$16) -> 0.23532068
A14: =2_标准化!B14 -> 森林覆盖率 | B14: =2_标准化!A14 -> 生态 E | C14: =SUM(2_标准化!E14:N14) -> 4.8555357 | D14: =-1/LN(10)*SUMPRODUCT((2_标准化!E14:N14/$C14),LN(2_标准化!E14:N14/$C14)) -> 0.92535932 | E14: =1-D14 -> 0.074640681 | F14: =E14/SUM($E$2:$E$16) -> 0.047502188 | G14: =STDEV(2_标准化!E14:N14) -> 0.27087279 | H14: =CORREL(2_标准化!$E14:$N14,2_标准化!$E2:$N2) -> 0.76832058 | I14: =CORREL(2_标准化!$E14:$N14,2_标准化!$E3:$N3) -> 0.89607496 | J14: =CORREL(2_标准化!$E14:$N14,2_标准化!$E4:$N4) -> 0.88874954 | K14: =CORREL(2_标准化!$E14:$N14,2_标准化!$E5:$N5) -> 0.88913875 | L14: =CORREL(2_标准化!$E14:$N14,2_标准化!$E6:$N6) -> 0.81739623 | M14: =CORREL(2_标准化!$E14:$N14,2_标准化!$E7:$N7) -> -0.59955193 | N14: =CORREL(2_标准化!$E14:$N14,2_标准化!$E8:$N8) -> 0.91036421 | O14: =CORREL(2_标准化!$E14:$N14,2_标准化!$E9:$N9) -> 0.90135912 | P14: =CORREL(2_标准化!$E14:$N14,2_标准化!$E10:$N10) -> 0.32465851 | Q14: =CORREL(2_标准化!$E14:$N14,2_标准化!$E11:$N11) -> 0.77294642 | R14: =CORREL(2_标准化!$E14:$N14,2_标准化!$E12:$N12) -> 0.82521776 | S14: =CORREL(2_标准化!$E14:$N14,2_标准化!$E13:$N13) -> 0.9062421 | T14: =CORREL(2_标准化!$E14:$N14,2_标准化!$E14:$N14) -> 1 | U14: =CORREL(2_标准化!$E14:$N14,2_标准化!$E15:$N15) -> 0.72095086 | V14: =CORREL(2_标准化!$E14:$N14,2_标准化!$E16:$N16) -> 0.84637626 | W14: =15-SUM(H14:V14) -> 4.1317566 | X14: =G14*W14 -> 1.1191805 | Y14: =X14/SUM($X$2:$X$16) -> 0.044451017 | Z14: =(F14*Y14)/SUMPRODUCT($F$2:$F$16,$Y$2:$Y$16) -> 0.03466054 | AA14: =Z14/SUMIF($B$2:$B$16,B14,$Z$2:$Z$16) -> 0.22212551
A15: =2_标准化!B15 -> 空气质量优良天数比例 | B15: =2_标准化!A15 -> 生态 E | C15: =SUM(2_标准化!E15:N15) -> 7.4189286 | D15: =-1/LN(10)*SUMPRODUCT((2_标准化!E15:N15/$C15),LN(2_标准化!E15:N15/$C15)) -> 0.93258081 | E15: =1-D15 -> 0.067419193 | F15: =E15/SUM($E$2:$E$16) -> 0.042906349 | G15: =STDEV(2_标准化!E15:N15) -> 0.35162141 | H15: =CORREL(2_标准化!$E15:$N15,2_标准化!$E2:$N2) -> 0.70676432 | I15: =CORREL(2_标准化!$E15:$N15,2_标准化!$E3:$N3) -> 0.7284975 | J15: =CORREL(2_标准化!$E15:$N15,2_标准化!$E4:$N4) -> 0.75379476 | K15: =CORREL(2_标准化!$E15:$N15,2_标准化!$E5:$N5) -> 0.89270082 | L15: =CORREL(2_标准化!$E15:$N15,2_标准化!$E6:$N6) -> 0.64939344 | M15: =CORREL(2_标准化!$E15:$N15,2_标准化!$E7:$N7) -> -0.58058062 | N15: =CORREL(2_标准化!$E15:$N15,2_标准化!$E8:$N8) -> 0.74564423 | O15: =CORREL(2_标准化!$E15:$N15,2_标准化!$E9:$N9) -> 0.72002675 | P15: =CORREL(2_标准化!$E15:$N15,2_标准化!$E10:$N10) -> 0.22823882 | Q15: =CORREL(2_标准化!$E15:$N15,2_标准化!$E11:$N11) -> 0.6853345 | R15: =CORREL(2_标准化!$E15:$N15,2_标准化!$E12:$N12) -> 0.59798062 | S15: =CORREL(2_标准化!$E15:$N15,2_标准化!$E13:$N13) -> 0.77758676 | T15: =CORREL(2_标准化!$E15:$N15,2_标准化!$E14:$N14) -> 0.72095086 | U15: =CORREL(2_标准化!$E15:$N15,2_标准化!$E15:$N15) -> 1 | V15: =CORREL(2_标准化!$E15:$N15,2_标准化!$E16:$N16) -> 0.94486034 | W15: =15-SUM(H15:V15) -> 5.4288069 | X15: =G15*W15 -> 1.9088847 | Y15: =X15/SUM($X$2:$X$16) -> 0.075816073 | Z15: =(F15*Y15)/SUMPRODUCT($F$2:$F$16,$Y$2:$Y$16) -> 0.053397738 | AA15: =Z15/SUMIF($B$2:$B$16,B15,$Z$2:$Z$16) -> 0.3422047
A16: =2_标准化!B16 -> 草原综合植被盖度 | B16: =2_标准化!A16 -> 生态 E | C16: =SUM(2_标准化!E16:N16) -> 7.2221664 | D16: =-1/LN(10)*SUMPRODUCT((2_标准化!E16:N16/$C16),LN(2_标准化!E16:N16/$C16)) -> 0.94194601 | E16: =1-D16 -> 0.058053993 | F16: =E16/SUM($E$2:$E$16) -> 0.036946228 | G16: =STDEV(2_标准化!E16:N16) -> 0.31991601 | H16: =CORREL(2_标准化!$E16:$N16,2_标准化!$E2:$N2) -> 0.71183167 | I16: =CORREL(2_标准化!$E16:$N16,2_标准化!$E3:$N3) -> 0.88394972 | J16: =CORREL(2_标准化!$E16:$N16,2_标准化!$E4:$N4) -> 0.88227227 | K16: =CORREL(2_标准化!$E16:$N16,2_标准化!$E5:$N5) -> 0.98712573 | L16: =CORREL(2_标准化!$E16:$N16,2_标准化!$E6:$N6) -> 0.70809003 | M16: =CORREL(2_标准化!$E16:$N16,2_标准化!$E7:$N7) -> -0.53536401 | N16: =CORREL(2_标准化!$E16:$N16,2_标准化!$E8:$N8) -> 0.87273265 | O16: =CORREL(2_标准化!$E16:$N16,2_标准化!$E9:$N9) -> 0.8662008 | P16: =CORREL(2_标准化!$E16:$N16,2_标准化!$E10:$N10) -> 0.3705747 | Q16: =CORREL(2_标准化!$E16:$N16,2_标准化!$E11:$N11) -> 0.74082545 | R16: =CORREL(2_标准化!$E16:$N16,2_标准化!$E12:$N12) -> 0.75641416 | S16: =CORREL(2_标准化!$E16:$N16,2_标准化!$E13:$N13) -> 0.90718856 | T16: =CORREL(2_标准化!$E16:$N16,2_标准化!$E14:$N14) -> 0.84637626 | U16: =CORREL(2_标准化!$E16:$N16,2_标准化!$E15:$N15) -> 0.94486034 | V16: =CORREL(2_标准化!$E16:$N16,2_标准化!$E16:$N16) -> 1 | W16: =15-SUM(H16:V16) -> 4.0569217 | X16: =G16*W16 -> 1.2978742 | Y16: =X16/SUM($X$2:$X$16) -> 0.051548281 | Z16: =(F16*Y16)/SUMPRODUCT($F$2:$F$16,$Y$2:$Y$16) -> 0.031262543 | AA16: =Z16/SUMIF($B$2:$B$16,B16,$Z$2:$Z$16) -> 0.20034911

Sheet 4_子系统指数
A1: 年份 | B1: US 安全 | C1: UD 发展 | D1: UE 生态 | F1: US 论文 | G1: UD 论文 | H1: UE 论文 | J1: US差异 | K1: UD差异 | L1: UE差异
A2: 2016 | B2: =SUMPRODUCT(3_权重!$AA$2:$AA$5,2_标准化!E2:E5) -> 0.01 | C2: =SUMPRODUCT(3_权重!$AA$6:$AA$12,2_标准化!E6:E12) -> 0.32611961 | D2: =SUMPRODUCT(3_权重!$AA$13:$AA$16,2_标准化!E13:E16) -> 0.01 | F2: 0.01 | G2: 0.326 | H2: 0.01 | J2: =B2-F2 -> 0 | K2: =C2-G2 -> 0.00011961492 | L2: =D2-H2 -> 0
A3: 2017 | B3: =SUMPRODUCT(3_权重!$AA$2:$AA$5,2_标准化!F2:F5) -> 0.19522308 | C3: =SUMPRODUCT(3_权重!$AA$6:$AA$12,2_标准化!F6:F12) -> 0.3248792 | D3: =SUMPRODUCT(3_权重!$AA$13:$AA$16,2_标准化!F13:F16) -> 0.23311208 | F3: 0.195 | G3: 0.325 | H3: 0.233 | J3: =B3-F3 -> 0.00022308377 | K3: =C3-G3 -> -0.0001208001 | L3: =D3-H3 -> 0.00011207584
A4: 2018 | B4: =SUMPRODUCT(3_权重!$AA$2:$AA$5,2_标准化!G2:G5) -> 0.37170438 | C4: =SUMPRODUCT(3_权重!$AA$6:$AA$12,2_标准化!G6:G12) -> 0.24881858 | D4: =SUMPRODUCT(3_权重!$AA$13:$AA$16,2_标准化!G13:G16) -> 0.51462977 | F4: 0.372 | G4: 0.249 | H4: 0.515 | J4: =B4-F4 -> -0.00029561689 | K4: =C4-G4 -> -0.00018142062 | L4: =D4-H4 -> -0.00037023148
A5: 2019 | B5: =SUMPRODUCT(3_权重!$AA$2:$AA$5,2_标准化!H2:H5) -> 0.40831149 | C5: =SUMPRODUCT(3_权重!$AA$6:$AA$12,2_标准化!H6:H12) -> 0.34245886 | D5: =SUMPRODUCT(3_权重!$AA$13:$AA$16,2_标准化!H13:H16) -> 0.65255278 | F5: 0.408 | G5: 0.342 | H5: 0.653 | J5: =B5-F5 -> 0.00031148844 | K5: =C5-G5 -> 0.00045885847 | L5: =D5-H5 -> -0.00044721533
A6: 2020 | B6: =SUMPRODUCT(3_权重!$AA$2:$AA$5,2_标准化!I2:I5) -> 0.49016318 | C6: =SUMPRODUCT(3_权重!$AA$6:$AA$12,2_标准化!I6:I12) -> 0.35927758 | D6: =SUMPRODUCT(3_权重!$AA$13:$AA$16,2_标准化!I13:I16) -> 0.71540857 | F6: 0.49 | G6: 0.359 | H6: 0.715 | J6: =B6-F6 -> 0.00016318384 | K6: =C6-G6 -> 0.00027757648 | L6: =D6-H6 -> 0.00040856783
A7: 2021 | B7: =SUMPRODUCT(3_权重!$AA$2:$AA$5,2_标准化!J2:J5) -> 0.55505418 | C7: =SUMPRODUCT(3_权重!$AA$6:$AA$12,2_标准化!J6:J12) -> 0.45930792 | D7: =SUMPRODUCT(3_权重!$AA$13:$AA$16,2_标准化!J13:J16) -> 0.72589879 | F7: 0.555 | G7: 0.459 | H7: 0.726 | J7: =B7-F7 -> 5.4175856e-05 | K7: =C7-G7 -> 0.00030791724 | L7: =D7-H7 -> -0.00010120533
A8: 2022 | B8: =SUMPRODUCT(3_权重!$AA$2:$AA$5,2_标准化!K2:K5) -> 0.54750062 | C8: =SUMPRODUCT(3_权重!$AA$6:$AA$12,2_标准化!K6:K12) -> 0.48151808 | D8: =SUMPRODUCT(3_权重!$AA$13:$AA$16,2_标准化!K13:K16) -> 0.74315795 | F8: 0.548 | G8: 0.482 | H8: 0.743 | J8: =B8-F8 -> -0.0004993767 | K8: =C8-G8 -> -0.0004819243 | L8: =D8-H8 -> 0.0001579514
A9: 2023 | B9: =SUMPRODUCT(3_权重!$AA$2:$AA$5,2_标准化!L2:L5) -> 0.74715097 | C9: =SUMPRODUCT(3_权重!$AA$6:$AA$12,2_标准化!L6:L12) -> 0.75003928 | D9: =SUMPRODUCT(3_权重!$AA$13:$AA$16,2_标准化!L13:L16) -> 0.82507727 | F9: 0.747 | G9: 0.75 | H9: 0.825 | J9: =B9-F9 -> 0.00015096672 | K9: =C9-G9 -> 3.9283857e-05 | L9: =D9-H9 -> 7.7271455e-05
A10: 2024 | B10: =SUMPRODUCT(3_权重!$AA$2:$AA$5,2_标准化!M2:M5) -> 0.87642324 | C10: =SUMPRODUCT(3_权重!$AA$6:$AA$12,2_标准化!M6:M12) -> 0.72151141 | D10: =SUMPRODUCT(3_权重!$AA$13:$AA$16,2_标准化!M13:M16) -> 0.87023863 | F10: 0.876 | G10: 0.722 | H10: 0.87 | J10: =B10-F10 -> 0.00042323989 | K10: =C10-G10 -> -0.00048858863 | L10: =D10-H10 -> 0.00023863002
A11: 2025 | B11: =SUMPRODUCT(3_权重!$AA$2:$AA$5,2_标准化!N2:N5) -> 1 | C11: =SUMPRODUCT(3_权重!$AA$6:$AA$12,2_标准化!N6:N12) -> 0.66640052 | D11: =SUMPRODUCT(3_权重!$AA$13:$AA$16,2_标准化!N13:N16) -> 1 | F11: 1 | G11: 0.666 | H11: 1 | J11: =B11-F11 -> 0 | K11: =C11-G11 -> 0.00040051824 | L11: =D11-H11 -> 0

Sheet 5_耦合协调度
A1: 年份 | B1: US | C1: UD | D1: UE | E1: 传统C | F1: T | G1: 离散CV | H1: 修正C′ | I1: 协调度D | J1: 等级 | K1: 传统D | L1: D虚高% | N1: 论文D | O1: D差异
A2: 2016 | B2: =4_子系统指数!B2 -> 0.01 | C2: =4_子系统指数!C2 -> 0.32611961 | D2: =4_子系统指数!D2 -> 0.01 | E2: =3*((B2*C2*D2)/(B2+C2+D2)^3)^(1/3) -> 0.2769198 | F2: =(B2+C2+D2)/3 -> 0.1153732 | G2: =STDEVP(B2,C2,D2)/F2 -> 1.2916363 | H2: =MAX(0,E2*(1-G2)) -> 0 | I2: =SQRT(H2*F2) -> 0 | J2: =LOOKUP(I2,$R$2:$R$11,$S$2:$S$11) -> 极度失调 | K2: =SQRT(E2*F2) -> 0.17874318 | L2: =IF(I2=0,"—",(K2-I2)/I2) -> — | N2: 0 | O2: =I2-N2 -> 0 | R2: 0 | S2: 极度失调
A3: 2017 | B3: =4_子系统指数!B3 -> 0.19522308 | C3: =4_子系统指数!C3 -> 0.3248792 | D3: =4_子系统指数!D3 -> 0.23311208 | E3: =3*((B3*C3*D3)/(B3+C3+D3)^3)^(1/3) -> 0.97755668 | F3: =(B3+C3+D3)/3 -> 0.25107145 | G3: =STDEVP(B3,C3,D3)/F3 -> 0.21680659 | H3: =MAX(0,E3*(1-G3)) -> 0.76561595 | I3: =SQRT(H3*F3) -> 0.43843393 | J3: =LOOKUP(I3,$R$2:$R$11,$S$2:$S$11) -> 濒临失调 | K3: =SQRT(E3*F3) -> 0.49541556 | L3: =IF(I3=0,"—",(K3-I3)/I3) -> 0.12996629 | N3: 0.438 | O3: =I3-N3 -> 0.00043392781 | R3: 0.1 | S3: 严重失调
A4: 2018 | B4: =4_子系统指数!B4 -> 0.37170438 | C4: =4_子系统指数!C4 -> 0.24881858 | D4: =4_子系统指数!D4 -> 0.51462977 | E4: =3*((B4*C4*D4)/(B4+C4+D4)^3)^(1/3) -> 0.95776454 | F4: =(B4+C4+D4)/3 -> 0.37838424 | G4: =STDEVP(B4,C4,D4)/F4 -> 0.28706193 | H4: =MAX(0,E4*(1-G4)) -> 0.6828268 | I4: =SQRT(H4*F4) -> 0.50830198 | J4: =LOOKUP(I4,$R$2:$R$11,$S$2:$S$11) -> 勉强协调 | K4: =SQRT(E4*F4) -> 0.60199918 | L4: =IF(I4=0,"—",(K4-I4)/I4) -> 0.18433373 | N4: 0.508 | O4: =I4-N4 -> 0.0003019806 | R4: 0.2 | S4: 中度失调
A5: 2019 | B5: =4_子系统指数!B5 -> 0.40831149 | C5: =4_子系统指数!C5 -> 0.34245886 | D5: =4_子系统指数!D5 -> 0.65255278 | E5: =3*((B5*C5*D5)/(B5+C5+D5)^3)^(1/3) -> 0.96242919 | F5: =(B5+C5+D5)/3 -> 0.46777438 | G5: =STDEVP(B5,C5,D5)/F5 -> 0.28517006 | H5: =MAX(0,E5*(1-G5)) -> 0.68797321 | I5: =SQRT(H5*F5) -> 0.5672885 | J5: =LOOKUP(I5,$R$2:$R$11,$S$2:$S$11) -> 勉强协调 | K5: =SQRT(E5*F5) -> 0.67096924 | L5: =IF(I5=0,"—",(K5-I5)/I5) -> 0.18276545 | N5: 0.567 | O5: =I5-N5 -> 0.00028849661 | R5: 0.3 | S5: 轻度失调
A6: 2020 | B6: =4_子系统指数!B6 -> 0.49016318 | C6: =4_子系统指数!C6 -> 0.35927758 | D6: =4_子系统指数!D6 -> 0.71540857 | E6: =3*((B6*C6*D6)/(B6+C6+D6)^3)^(1/3) -> 0.96107447 | F6: =(B6+C6+D6)/3 -> 0.52161644 | G6: =STDEVP(B6,C6,D6)/F6 -> 0.28197186 | H6: =MAX(0,E6*(1-G6)) -> 0.69007851 | I6: =SQRT(H6*F6) -> 0.59996358 | J6: =LOOKUP(I6,$R$2:$R$11,$S$2:$S$11) -> 勉强协调 | K6: =SQRT(E6*F6) -> 0.70803407 | L6: =IF(I6=0,"—",(K6-I6)/I6) -> 0.18012842 | N6: 0.6 | O6: =I6-N6 -> -3.6419886e-05 | R6: 0.4 | S6: 濒临失调
A7: 2021 | B7: =4_子系统指数!B7 -> 0.55505418 | C7: =4_子系统指数!C7 -> 0.45930792 | D7: =4_子系统指数!D7 -> 0.72589879 | E7: =3*((B7*C7*D7)/(B7+C7+D7)^3)^(1/3) -> 0.98237814 | F7: =(B7+C7+D7)/3 -> 0.58008696 | G7: =STDEVP(B7,C7,D7)/F7 -> 0.19008408 | H7: =MAX(0,E7*(1-G7)) -> 0.79564369 | I7: =SQRT(H7*F7) -> 0.67936922 | J7: =LOOKUP(I7,$R$2:$R$11,$S$2:$S$11) -> 初级协调 | K7: =SQRT(E7*F7) -> 0.75489387 | L7: =IF(I7=0,"—",(K7-I7)/I7) -> 0.11116879 | N7: 0.679 | O7: =I7-N7 -> 0.00036921534 | R7: 0.5 | S7: 勉强协调
A8: 2022 | B8: =4_子系统指数!B8 -> 0.54750062 | C8: =4_子系统指数!C8 -> 0.48151808 | D8: =4_子系统指数!D8 -> 0.74315795 | E8: =3*((B8*C8*D8)/(B8+C8+D8)^3)^(1/3) -> 0.98319658 | F8: =(B8+C8+D8)/3 -> 0.59072555 | G8: =STDEVP(B8,C8,D8)/F8 -> 0.18807551 | H8: =MAX(0,E8*(1-G8)) -> 0.79828138 | I8: =SQRT(H8*F8) -> 0.68670606 | J8: =LOOKUP(I8,$R$2:$R$11,$S$2:$S$11) -> 初级协调 | K8: =SQRT(E8*F8) -> 0.76210192 | L8: =IF(I8=0,"—",(K8-I8)/I8) -> 0.10979351 | N8: 0.687 | O8: =I8-N8 -> -0.00029394497 | R8: 0.6 | S8: 初级协调
A9: 2023 | B9: =4_子系统指数!B9 -> 0.74715097 | C9: =4_子系统指数!C9 -> 0.75003928 | D9: =4_子系统指数!D9 -> 0.82507727 | E9: =3*((B9*C9*D9)/(B9+C9+D9)^3)^(1/3) -> 0.99893678 | F9: =(B9+C9+D9)/3 -> 0.77408917 | G9: =STDEVP(B9,C9,D9)/F9 -> 0.04660097 | H9: =MAX(0,E9*(1-G9)) -> 0.95238536 | I9: =SQRT(H9*F9) -> 0.85862168 | J9: =LOOKUP(I9,$R$2:$R$11,$S$2:$S$11) -> 良好协调 | K9: =SQRT(E9*F9) -> 0.87935553 | L9: =IF(I9=0,"—",(K9-I9)/I9) -> 0.024147825 | N9: 0.859 | O9: =I9-N9 -> -0.00037831562 | R9: 0.7 | S9: 中级协调
A10: 2024 | B10: =4_子系统指数!B10 -> 0.87642324 | C10: =4_子系统指数!C10 -> 0.72151141 | D10: =4_子系统指数!D10 -> 0.87023863 | E10: =3*((B10*C10*D10)/(B10+C10+D10)^3)^(1/3) -> 0.99604148 | F10: =(B10+C10+D10)/3 -> 0.82272443 | G10: =STDEVP(B10,C10,D10)/F10 -> 0.087043645 | H10: =MAX(0,E10*(1-G10)) -> 0.9093424 | I10: =SQRT(H10*F10) -> 0.86494983 | J10: =LOOKUP(I10,$R$2:$R$11,$S$2:$S$11) -> 良好协调 | K10: =SQRT(E10*F10) -> 0.90524453 | L10: =IF(I10=0,"—",(K10-I10)/I10) -> 0.046586171 | N10: 0.865 | O10: =I10-N10 -> -5.0173559e-05 | R10: 0.8 | S10: 良好协调
A11: 2025 | B11: =4_子系统指数!B11 -> 1 | C11: =4_子系统指数!C11 -> 0.66640052 | D11: =4_子系统指数!D11 -> 1 | E11: =3*((B11*C11*D11)/(B11+C11+D11)^3)^(1/3) -> 0.98274531 | F11: =(B11+C11+D11)/3 -> 0.88880017 | G11: =STDEVP(B11,C11,D11)/F11 -> 0.1769355 | H11: =MAX(0,E11*(1-G11)) -> 0.80886277 | I11: =SQRT(H11*F11) -> 0.84788995 | J11: =LOOKUP(I11,$R$2:$R$11,$S$2:$S$11) -> 良好协调 | K11: =SQRT(E11*F11) -> 0.93459307 | L11: =IF(I11=0,"—",(K11-I11)/I11) -> 0.10225751 | N11: 0.848 | O11: =I11-N11 -> -0.00011004681 | R11: 0.9 | S11: 优质协调

Sheet 6_障碍度
A1: 指标 | B1: 子系统 | C1: 2016 | D1: 2017 | E1: 2018 | F1: 2019 | G1: 2020 | H1: 2021 | I1: 2022 | J1: 2023 | K1: 2024 | L1: 2025 | M1: 均值 | N1: 排序
A2: =2_标准化!B2 -> 地方一般公共预算收入 | B2: =2_标准化!A2 -> 安全 S | C2: =3_权重!$AA2*(1-2_标准化!E2)/C$19 -> 0.122158 | D2: =3_权重!$AA2*(1-2_标准化!F2)/D$19 -> 0.11769882 | E2: =3_权重!$AA2*(1-2_标准化!G2)/E$19 -> 0.09400316 | F2: =3_权重!$AA2*(1-2_标准化!H2)/F$19 -> 0.12027529 | G2: =3_权重!$AA2*(1-2_标准化!I2)/G$19 -> 0.13520746 | H2: =3_权重!$AA2*(1-2_标准化!J2)/H$19 -> 0.16256973 | I2: =3_权重!$AA2*(1-2_标准化!K2)/I$19 -> 0.22548707 | J2: =3_权重!$AA2*(1-2_标准化!L2)/J$19 -> 0.24010518 | ... L2: =3_权重!$AA2*(1-2_标准化!N2)/L$19 -> 0 | M2: =AVERAGE(C2:L2) -> 0.13707759 | N2: =RANK(M2,$M$2:$M$16) -> 2
A3: =2_标准化!B3 -> 城乡居民人均可支配收入比 | B3: =2_标准化!A3 -> 安全 S | C3: =3_权重!$AA3*(1-2_标准化!E3)/C$19 -> 0.094575654 | D3: =3_权重!$AA3*(1-2_标准化!F3)/D$19 -> 0.092837347 | E3: =3_权重!$AA3*(1-2_标准化!G3)/E$19 -> 0.10735398 | F3: =3_权重!$AA3*(1-2_标准化!H3)/F$19 -> 0.10634667 | G3: =3_权重!$AA3*(1-2_标准化!I3)/G$19 -> 0.095066072 | H3: =3_权重!$AA3*(1-2_标准化!J3)/H$19 -> 0.080275335 | I3: =3_权重!$AA3*(1-2_标准化!K3)/I$19 -> 0.055473289 | J3: =3_权重!$AA3*(1-2_标准化!L3)/J$19 -> 0.048974711 | ... L3: =3_权重!$AA3*(1-2_标准化!N3)/L$19 -> 0 | M3: =AVERAGE(C3:L3) -> 0.071123292 | N3: =RANK(M3,$M$2:$M$16) -> 8
A4: =2_标准化!B4 -> 居民医保人均财政补助标准 | B4: =2_标准化!A4 -> 安全 S | C4: =3_权重!$AA4*(1-2_标准化!E4)/C$19 -> 0.090704952 | D4: =3_权重!$AA4*(1-2_标准化!F4)/D$19 -> 0.096935981 | E4: =3_权重!$AA4*(1-2_标准化!G4)/E$19 -> 0.090153211 | F4: =3_权重!$AA4*(1-2_标准化!H4)/F$19 -> 0.10529492 | G4: =3_权重!$AA4*(1-2_标准化!I4)/G$19 -> 0.098509025 | H4: =3_权重!$AA4*(1-2_标准化!J4)/H$19 -> 0.094027064 | I4: =3_权重!$AA4*(1-2_标准化!K4)/I$19 -> 0.074687367 | J4: =3_权重!$AA4*(1-2_标准化!L4)/J$19 -> 0.067654197 | ... L4: =3_权重!$AA4*(1-2_标准化!N4)/L$19 -> 0 | M4: =AVERAGE(C4:L4) -> 0.076107423 | N4: =RANK(M4,$M$2:$M$16) -> 5
A5: =2_标准化!B5 -> 基本养老保险参保率 | B5: =2_标准化!A5 -> 安全 S | C5: =3_权重!$AA5*(1-2_标准化!E5)/C$19 -> 0.065600064 | D5: =3_权重!$AA5*(1-2_标准化!F5)/D$19 -> 0.050718194 | E5: =3_权重!$AA5*(1-2_标准化!G5)/E$19 -> 0.045404974 | F5: =3_权重!$AA5*(1-2_标准化!H5)/F$19 -> 0.038658099 | G5: =3_权重!$AA5*(1-2_标准化!I5)/G$19 -> 0.026467119 | H5: =3_权重!$AA5*(1-2_标准化!J5)/H$19 -> 0.016332613 | I5: =3_权重!$AA5*(1-2_标准化!K5)/I$19 -> 0.012890122 | J5: =3_权重!$AA5*(1-2_标准化!L5)/J$19 -> 0.016346797 | ... L5: =3_权重!$AA5*(1-2_标准化!N5)/L$19 -> 0 | M5: =AVERAGE(C5:L5) -> 0.027807225 | N5: =RANK(M5,$M$2:$M$16) -> 13
A6: =2_标准化!B6 -> 人均GDP相对全国水平 | B6: =2_标准化!A6 -> 发展 D | C6: =3_权重!$AA6*(1-2_标准化!E6)/C$19 -> 0.059164617 | D6: =3_权重!$AA6*(1-2_标准化!F6)/D$19 -> 0.067856123 | E6: =3_权重!$AA6*(1-2_标准化!G6)/E$19 -> 0.080059397 | F6: =3_权重!$AA6*(1-2_标准化!H6)/F$19 -> 0.072094999 | G6: =3_权重!$AA6*(1-2_标准化!I6)/G$19 -> 0.059512642 | H6: =3_权重!$AA6*(1-2_标准化!J6)/H$19 -> 0.10206322 | I6: =3_权重!$AA6*(1-2_标准化!K6)/I$19 -> 0.10378134 | J6: =3_权重!$AA6*(1-2_标准化!L6)/J$19 -> 0.11802416 | ... L6: =3_权重!$AA6*(1-2_标准化!N6)/L$19 -> 0 | M6: =AVERAGE(C6:L6) -> 0.072015415 | N6: =RANK(M6,$M$2:$M$16) -> 6
A7: =2_标准化!B7 -> 第三产业增加值比重 | B7: =2_标准化!A7 -> 发展 D | C7: =3_权重!$AA7*(1-2_标准化!E7)/C$19 -> 0 | D7: =3_权重!$AA7*(1-2_标准化!F7)/D$19 -> 0.016888768 | E7: =3_权重!$AA7*(1-2_标准化!G7)/E$19 -> 0.078847523 | F7: =3_权重!$AA7*(1-2_标准化!H7)/F$19 -> 0.077237097 | G7: =3_权重!$AA7*(1-2_标准化!I7)/G$19 -> 0.069405107 | H7: =3_权重!$AA7*(1-2_标准化!J7)/H$19 -> 0.030121667 | I7: =3_权重!$AA7*(1-2_标准化!K7)/I$19 -> 0.038630804 | J7: =3_权重!$AA7*(1-2_标准化!L7)/J$19 -> 0.048990218 | ... L7: =3_权重!$AA7*(1-2_标准化!N7)/L$19 -> 0.81043674 | M7: =AVERAGE(C7:L7) -> 0.15183856 | N7: =RANK(M7,$M$2:$M$16) -> 1
A8: =2_标准化!B8 -> 地区生产总值 | B8: =2_标准化!A8 -> 发展 D | C8: =3_权重!$AA8*(1-2_标准化!E8)/C$19 -> 0.02416739 | D8: =3_权重!$AA8*(1-2_标准化!F8)/D$19 -> 0.025689486 | E8: =3_权重!$AA8*(1-2_标准化!G8)/E$19 -> 0.027154341 | F8: =3_权重!$AA8*(1-2_标准化!H8)/F$19 -> 0.028061413 | G8: =3_权重!$AA8*(1-2_标准化!I8)/G$19 -> 0.026196505 | H8: =3_权重!$AA8*(1-2_标准化!J8)/H$19 -> 0.024611665 | I8: =3_权重!$AA8*(1-2_标准化!K8)/I$19 -> 0.022679888 | J8: =3_权重!$AA8*(1-2_标准化!L8)/J$19 -> 0.025743013 | ... L8: =3_权重!$AA8*(1-2_标准化!N8)/L$19 -> 0 | M8: =AVERAGE(C8:L8) -> 0.022026636 | N8: =RANK(M8,$M$2:$M$16) -> 15
A9: =2_标准化!B9 -> 农村居民人均可支配收入 | B9: =2_标准化!A9 -> 发展 D | C9: =3_权重!$AA9*(1-2_标准化!E9)/C$19 -> 0.028760989 | D9: =3_权重!$AA9*(1-2_标准化!F9)/D$19 -> 0.030992088 | E9: =3_权重!$AA9*(1-2_标准化!G9)/E$19 -> 0.034086075 | F9: =3_权重!$AA9*(1-2_标准化!H9)/F$19 -> 0.034718433 | G9: =3_权重!$AA9*(1-2_标准化!I9)/G$19 -> 0.032409144 | H9: =3_权重!$AA9*(1-2_标准化!J9)/H$19 -> 0.026872253 | I9: =3_权重!$AA9*(1-2_标准化!K9)/I$19 -> 0.021949841 | J9: =3_权重!$AA9*(1-2_标准化!L9)/J$19 -> 0.026057544 | ... L9: =3_权重!$AA9*(1-2_标准化!N9)/L$19 -> 0 | M9: =AVERAGE(C9:L9) -> 0.02522051 | N9: =RANK(M9,$M$2:$M$16) -> 14
A10: =2_标准化!B10 -> 货物进出口总额 | B10: =2_标准化!A10 -> 发展 D | C10: =3_权重!$AA10*(1-2_标准化!E10)/C$19 -> 0.042650491 | D10: =3_权重!$AA10*(1-2_标准化!F10)/D$19 -> 0.045330425 | E10: =3_权重!$AA10*(1-2_标准化!G10)/E$19 -> 0.064052575 | F10: =3_权重!$AA10*(1-2_标准化!H10)/F$19 -> 0.073639271 | G10: =3_权重!$AA10*(1-2_标准化!I10)/G$19 -> 0.11075328 | H10: =3_权重!$AA10*(1-2_标准化!J10)/H$19 -> 0.10363139 | I10: =3_权重!$AA10*(1-2_标准化!K10)/I$19 -> 0.099139367 | J10: =3_权重!$AA10*(1-2_标准化!L10)/J$19 -> 0.037697261 | ... L10: =3_权重!$AA10*(1-2_标准化!N10)/L$19 -> 0.18956326 | M10: =AVERAGE(C10:L10) -> 0.076645732 | N10: =RANK(M10,$M$2:$M$16) -> 4
A11: =2_标准化!B11 -> 接待游客总人数 | B11: =2_标准化!A11 -> 发展 D | C11: =3_权重!$AA11*(1-2_标准化!E11)/C$19 -> 0.043878503 | D11: =3_权重!$AA11*(1-2_标准化!F11)/D$19 -> 0.049154401 | E11: =3_权重!$AA11*(1-2_标准化!G11)/E$19 -> 0.048625433 | F11: =3_权重!$AA11*(1-2_标准化!H11)/F$19 -> 0.04692867 | G11: =3_权重!$AA11*(1-2_标准化!I11)/G$19 -> 0.060859993 | H11: =3_权重!$AA11*(1-2_标准化!J11)/H$19 -> 0.056735196 | I11: =3_权重!$AA11*(1-2_标准化!K11)/I$19 -> 0.081149219 | J11: =3_权重!$AA11*(1-2_标准化!L11)/J$19 -> 0.056210943 | ... L11: =3_权重!$AA11*(1-2_标准化!N11)/L$19 -> 0 | M11: =AVERAGE(C11:L11) -> 0.047503565 | N11: =RANK(M11,$M$2:$M$16) -> 10
A12: =2_标准化!B12 -> 清洁能源发电量 | B12: =2_标准化!A12 -> 发展 D | C12: =3_权重!$AA12*(1-2_标准化!E12)/C$19 -> 0.055300676 | D12: =3_权重!$AA12*(1-2_标准化!F12)/D$19 -> 0.064571669 | E12: =3_权重!$AA12*(1-2_标准化!G12)/E$19 -> 0.069985885 | F12: =3_权重!$AA12*(1-2_标准化!H12)/F$19 -> 0.079138659 | G12: =3_权重!$AA12*(1-2_标准化!I12)/G$19 -> 0.087312916 | H12: =3_权重!$AA12*(1-2_标准化!J12)/H$19 -> 0.085174175 | I12: =3_权重!$AA12*(1-2_标准化!K12)/I$19 -> 0.05494684 | J12: =3_权重!$AA12*(1-2_标准化!L12)/J$19 -> 0.056096007 | ... L12: =3_权重!$AA12*(1-2_标准化!N12)/L$19 -> 0 | M12: =AVERAGE(C12:L12) -> 0.060693221 | N12: =RANK(M12,$M$2:$M$16) -> 9
A13: =2_标准化!B13 -> 单位GDP能耗指数 | B13: =2_标准化!A13 -> 生态 E | C13: =3_权重!$AA13*(1-2_标准化!E13)/C$19 -> 0.087783713 | D13: =3_权重!$AA13*(1-2_标准化!F13)/D$19 -> 0.088346302 | E13: =3_权重!$AA13*(1-2_标准化!G13)/E$19 -> 0.090627073 | F13: =3_权重!$AA13*(1-2_标准化!H13)/F$19 -> 0.089735474 | G13: =3_权重!$AA13*(1-2_标准化!I13)/G$19 -> 0.090482293 | H13: =3_权重!$AA13*(1-2_标准化!J13)/H$19 -> 0.082093834 | I13: =3_权重!$AA13*(1-2_标准化!K13)/I$19 -> 0.060541293 | J13: =3_权重!$AA13*(1-2_标准化!L13)/J$19 -> 0.074420671 | ... L13: =3_权重!$AA13*(1-2_标准化!N13)/L$19 -> 0 | M13: =AVERAGE(C13:L13) -> 0.07122144 | N13: =RANK(M13,$M$2:$M$16) -> 7
... A16: =2_标准化!B16 -> 草原综合植被盖度 | B16: =2_标准化!A16 -> 生态 E | C16: =3_权重!$AA16*(1-2_标准化!E16)/C$19 -> 0.074737965 | D16: =3_权重!$AA16*(1-2_标准化!F16)/D$19 -> 0.059210145 | E16: =3_权重!$AA16*(1-2_标准化!G16)/E$19 -> 0.040000301 | F16: =3_权重!$AA16*(1-2_标准化!H16)/F$19 -> 0.029495131 | G16: =3_权重!$AA16*(1-2_标准化!I16)/G$19 -> 0.028024325 | H16: =3_权重!$AA16*(1-2_标准化!J16)/H$19 -> 0.025377517 | I16: =3_权重!$AA16*(1-2_标准化!K16)/I$19 -> 0.015958268 | J16: =3_权重!$AA16*(1-2_标准化!L16)/J$19 -> 0.014709113 | ... L16: =3_权重!$AA16*(1-2_标准化!N16)/L$19 -> 0 | M16: =AVERAGE(C16:L16) -> 0.029074458 | N16: =RANK(M16,$M$2:$M$16) -> 12
A19: 分母Σ(w·偏离) | C19: =SUMPRODUCT(3_权重!$AA$2:$AA$16,(1-2_标准化!E$2:E$16)) -> 2.6538804 | D19: =SUMPRODUCT(3_权重!$AA$2:$AA$16,(1-2_标准化!F$2:F$16)) -> 2.2467856 | E19: =SUMPRODUCT(3_权重!$AA$2:$AA$16,(1-2_标准化!G$2:G$16)) -> 1.8648473 | F19: =SUMPRODUCT(3_权重!$AA$2:$AA$16,(1-2_标准化!H$2:H$16)) -> 1.5966769 | G19: =SUMPRODUCT(3_权重!$AA$2:$AA$16,(1-2_标准化!I$2:I$16)) -> 1.4351507 | H19: =SUMPRODUCT(3_权重!$AA$2:$AA$16,(1-2_标准化!J$2:J$16)) -> 1.2597391 | I19: =SUMPRODUCT(3_权重!$AA$2:$AA$16,(1-2_标准化!K$2:K$16)) -> 1.2278233 | J19: =SUMPRODUCT(3_权重!$AA$2:$AA$16,(1-2_标准化!L$2:L$16)) -> 0.67773248 | ... L19: =SUMPRODUCT(3_权重!$AA$2:$AA$16,(1-2_标准化!N$2:N$16)) -> 0.33359948
A21: 子系统障碍度合计
A22: 安全 S | C22: =SUM(C2:C5) -> 0.37303867 | D22: =SUM(D2:D5) -> 0.35819034 | E22: =SUM(E2:E5) -> 0.33691532 | F22: =SUM(F2:F5) -> 0.37057499 | G22: =SUM(G2:G5) -> 0.35524968 | H22: =SUM(H2:H5) -> 0.35320474 | I22: =SUM(I2:I5) -> 0.36853785 | J22: =SUM(J2:J5) -> 0.37308089 | ... L22: =SUM(L2:L5) -> 0
A23: 发展 D | C23: =SUM(C6:C12) -> 0.25392267 | D23: =SUM(D6:D12) -> 0.30048296 | E23: =SUM(E6:E12) -> 0.40281123 | F23: =SUM(F6:F12) -> 0.41181854 | G23: =SUM(G6:G12) -> 0.44644959 | H23: =SUM(H6:H12) -> 0.42920957 | I23: =SUM(I6:I12) -> 0.4222773 | J23: =SUM(J6:J12) -> 0.36881915 | ... L23: =SUM(L6:L12) -> 1
A24: 生态 E | C24: =SUM(C13:C16) -> 0.37303867 | D24: =SUM(D13:D16) -> 0.3413267 | E24: =SUM(E13:E16) -> 0.26027345 | F24: =SUM(F13:F16) -> 0.21760647 | G24: =SUM(G13:G16) -> 0.19830073 | H24: =SUM(H13:H16) -> 0.21758569 | I24: =SUM(I13:I16) -> 0.20918485 | J24: =SUM(J13:J16) -> 0.25809996 | ... L24: =SUM(L13:L16) -> 0

Sheet 7_偏弹性
A1: 扰动步长 h= | B1: 0.001
A2: 年份 | B2: US | C2: UD | D2: UE | E2: 基准D | F2: D(US+) | G2: D(UD+) | H2: D(UE+) | I2: 弹性·安全 | J2: 弹性·发展 | K2: 弹性·生态
A3: 2016 | B3: =5_耦合协调度!B2 -> 0.01 | C3: =5_耦合协调度!C2 -> 0.32611961 | D3: =5_耦合协调度!D2 -> 0.01 | E3: =5_耦合协调度!I2 -> 0 | F3: =SQRT(MAX(0,3*((B3*(1+$B$1)*C3*D3)/(B3*(1+$B$1)+C3+D3)^3)^(1/3)*(1-SQRT(((B3*(1+$B$1)-(B3*(1+$B$1)+C3+D3)/3)^2+(C3-(B3*(1+$B$1)+C3+D3)/3)^2+(D3-(B3*(1+$B$1)+C3+D3)/3)^2)/3)/((B3*(1+$B$1)+C3+D3)/3))*((B3*(1+$B$1)+C3+D3)/3))) -> 0 | G3: =SQRT(MAX(0,3*((B3*C3*(1+$B$1)*D3)/(B3+C3*(1+$B$1)+D3)^3)^(1/3)*(1-SQRT(((B3-(B3+C3*(1+$B$1)+D3)/3)^2+(C3*(1+$B$1)-(B3+C3*(1+$B$1)+D3)/3)^2+(D3-(B3+C3*(1+$B$1)+D3)/3)^2)/3)/((B3+C3*(1+$B$1)+D3)/3))*((B3+C3*(1+$B$1)+D3)/3))) -> 0 | H3: =SQRT(MAX(0,3*((B3*C3*D3*(1+$B$1))/(B3+C3+D3*(1+$B$1))^3)^(1/3)*(1-SQRT(((B3-(B3+C3+D3*(1+$B$1))/3)^2+(C3-(B3+C3+D3*(1+$B$1))/3)^2+(D3*(1+$B$1)-(B3+C3+D3*(1+$B$1))/3)^2)/3)/((B3+C3+D3*(1+$B$1))/3))*((B3+C3+D3*(1+$B$1))/3))) -> 0 | I3: =IF(E3=0,"—",(F3-E3)/E3/$B$1) -> — | J3: =IF(E3=0,"—",(G3-E3)/E3/$B$1) -> — | K3: =IF(E3=0,"—",(H3-E3)/E3/$B$1) -> —
A4: 2017 | B4: =5_耦合协调度!B3 -> 0.19522308 | C4: =5_耦合协调度!C3 -> 0.3248792 | D4: =5_耦合协调度!D3 -> 0.23311208 | E4: =5_耦合协调度!I3 -> 0.43843393 | F4: =SQRT(MAX(0,3*((B4*(1+$B$1)*C4*D4)/(B4*(1+$B$1)+C4+D4)^3)^(1/3)*(1-SQRT(((B4*(1+$B$1)-(B4*(1+$B$1)+C4+D4)/3)^2+(C4-(B4*(1+$B$1)+C4+D4)/3)^2+(D4-(B4*(1+$B$1)+C4+D4)/3)^2)/3)/((B4*(1+$B$1)+C4+D4)/3))*((B4*(1+$B$1)+C4+D4)/3))) -> 0.43859707 | G4: =SQRT(MAX(0,3*((B4*C4*(1+$B$1)*D4)/(B4+C4*(1+$B$1)+D4)^3)^(1/3)*(1-SQRT(((B4-(B4+C4*(1+$B$1)+D4)/3)^2+(C4*(1+$B$1)-(B4+C4*(1+$B$1)+D4)/3)^2+(D4-(B4+C4*(1+$B$1)+D4)/3)^2)/3)/((B4+C4*(1+$B$1)+D4)/3))*((B4+C4*(1+$B$1)+D4)/3))) -> 0.43836944 | H4: =SQRT(MAX(0,3*((B4*C4*D4*(1+$B$1))/(B4+C4+D4*(1+$B$1))^3)^(1/3)*(1-SQRT(((B4-(B4+C4+D4*(1+$B$1))/3)^2+(C4-(B4+C4+D4*(1+$B$1))/3)^2+(D4*(1+$B$1)-(B4+C4+D4*(1+$B$1))/3)^2)/3)/((B4+C4+D4*(1+$B$1))/3))*((B4+C4+D4*(1+$B$1))/3))) -> 0.43855421 | I4: =IF(E4=0,"—",(F4-E4)/E4/$B$1) -> 0.3721052 | J4: =IF(E4=0,"—",(G4-E4)/E4/$B$1) -> -0.14708012 | K4: =IF(E4=0,"—",(H4-E4)/E4/$B$1) -> 0.27433445
A5: 2018 | B5: =5_耦合协调度!B4 -> 0.37170438 | C5: =5_耦合协调度!C4 -> 0.24881858 | D5: =5_耦合协调度!D4 -> 0.51462977 | E5: =5_耦合协调度!I4 -> 0.50830198 | F5: =SQRT(MAX(0,3*((B5*(1+$B$1)*C5*D5)/(B5*(1+$B$1)+C5+D5)^3)^(1/3)*(1-SQRT(((B5*(1+$B$1)-(B5*(1+$B$1)+C5+D5)/3)^2+(C5-(B5*(1+$B$1)+C5+D5)/3)^2+(D5-(B5*(1+$B$1)+C5+D5)/3)^2)/3)/((B5*(1+$B$1)+C5+D5)/3))*((B5*(1+$B$1)+C5+D5)/3))) -> 0.50842721 | G5: =SQRT(MAX(0,3*((B5*C5*(1+$B$1)*D5)/(B5+C5*(1+$B$1)+D5)^3)^(1/3)*(1-SQRT(((B5-(B5+C5*(1+$B$1)+D5)/3)^2+(C5*(1+$B$1)-(B5+C5*(1+$B$1)+D5)/3)^2+(D5-(B5+C5*(1+$B$1)+D5)/3)^2)/3)/((B5+C5*(1+$B$1)+D5)/3))*((B5+C5*(1+$B$1)+D5)/3))) -> 0.50850226 | H5: =SQRT(MAX(0,3*((B5*C5*D5*(1+$B$1))/(B5+C5+D5*(1+$B$1))^3)^(1/3)*(1-SQRT(((B5-(B5+C5+D5*(1+$B$1))/3)^2+(C5-(B5+C5+D5*(1+$B$1))/3)^2+(D5*(1+$B$1)-(B5+C5+D5*(1+$B$1))/3)^2)/3)/((B5+C5+D5*(1+$B$1))/3))*((B5+C5+D5*(1+$B$1))/3))) -> 0.5082303 | I5: =IF(E5=0,"—",(F5-E5)/E5/$B$1) -> 0.24636559 | J5: =IF(E5=0,"—",(G5-E5)/E5/$B$1) -> 0.39402424 | K5: =IF(E5=0,"—",(H5-E5)/E5/$B$1) -> -0.14101327
A6: 2019 | B6: =5_耦合协调度!B5 -> 0.40831149 | C6: =5_耦合协调度!C5 -> 0.34245886 | D6: =5_耦合协调度!D5 -> 0.65255278 | E6: =5_耦合协调度!I5 -> 0.5672885 | F6: =SQRT(MAX(0,3*((B6*(1+$B$1)*C6*D6)/(B6*(1+$B$1)+C6+D6)^3)^(1/3)*(1-SQRT(((B6*(1+$B$1)-(B6*(1+$B$1)+C6+D6)/3)^2+(C6-(B6*(1+$B$1)+C6+D6)/3)^2+(D6-(B6*(1+$B$1)+C6+D6)/3)^2)/3)/((B6*(1+$B$1)+C6+D6)/3))*((B6*(1+$B$1)+C6+D6)/3))) -> 0.56746727 | G6: =SQRT(MAX(0,3*((B6*C6*(1+$B$1)*D6)/(B6+C6*(1+$B$1)+D6)^3)^(1/3)*(1-SQRT(((B6-(B6+C6*(1+$B$1)+D6)/3)^2+(C6*(1+$B$1)-(B6+C6*(1+$B$1)+D6)/3)^2+(D6-(B6+C6*(1+$B$1)+D6)/3)^2)/3)/((B6+C6*(1+$B$1)+D6)/3))*((B6+C6*(1+$B$1)+D6)/3))) -> 0.56750152 | H6: =SQRT(MAX(0,3*((B6*C6*D6*(1+$B$1))/(B6+C6+D6*(1+$B$1))^3)^(1/3)*(1-SQRT(((B6-(B6+C6+D6*(1+$B$1))/3)^2+(C6-(B6+C6+D6*(1+$B$1))/3)^2+(D6*(1+$B$1)-(B6+C6+D6*(1+$B$1))/3)^2)/3)/((B6+C6+D6*(1+$B$1))/3))*((B6+C6+D6*(1+$B$1))/3))) -> 0.56718005 | I6: =IF(E6=0,"—",(F6-E6)/E6/$B$1) -> 0.31513847 | J6: =IF(E6=0,"—",(G6-E6)/E6/$B$1) -> 0.37550937 | K6: =IF(E6=0,"—",(H6-E6)/E6/$B$1) -> -0.19117109
